2025-06-06 10:38:02,894 - DEBUG - Logging initialized. Writing to /Users/johnrush/repos/chuck-data/log/sessions/2025-06-06_10-38-02.log
2025-06-06 10:38:02,899 - DEBUG - HTTP error: HTTP 401, Response: {"status":401,"message":"Unauthorized"}
2025-06-06 10:38:02,901 - DEBUG - GET request to: https://test-workspace.cloud.databricks.com/test-endpoint
2025-06-06 10:38:02,901 - DEBUG - Connection error: Connection failed
2025-06-06 10:38:02,903 - DEBUG - GET request to: https://test-workspace.cloud.databricks.com/test-endpoint
2025-06-06 10:38:02,903 - DEBUG - HTTP error: HTTP 404, Response: Not Found
2025-06-06 10:38:02,905 - DEBUG - GET request to: https://test-workspace.cloud.databricks.com/test-endpoint
2025-06-06 10:38:02,907 - DEBUG - POST request to: https://test-workspace.cloud.databricks.com/test-endpoint
2025-06-06 10:38:02,907 - DEBUG - Connection error: Connection failed
2025-06-06 10:38:02,909 - DEBUG - POST request to: https://test-workspace.cloud.databricks.com/test-endpoint
2025-06-06 10:38:02,909 - DEBUG - HTTP error: HTTP 400, Response: Bad Request
2025-06-06 10:38:02,912 - DEBUG - POST request to: https://test-workspace.cloud.databricks.com/test-endpoint
2025-06-06 10:38:02,944 - ERROR - Error listing catalogs: Database connection failed
2025-06-06 10:38:02,950 - ERROR - Error listing schemas: Network error
2025-06-06 10:38:03,056 - DEBUG - Saved configuration to /var/folders/3f/2n5sjdw50vj9gfnrxjbptj4c0000gn/T/tmp0gupsy31/test_config.json
2025-06-06 10:38:03,057 - DEBUG - Loaded configuration from /var/folders/3f/2n5sjdw50vj9gfnrxjbptj4c0000gn/T/tmp0gupsy31/test_config.json
2025-06-06 10:38:03,057 - DEBUG - Loaded configuration from /var/folders/3f/2n5sjdw50vj9gfnrxjbptj4c0000gn/T/tmp0gupsy31/test_config.json
2025-06-06 10:38:03,057 - DEBUG - Saved configuration to /var/folders/3f/2n5sjdw50vj9gfnrxjbptj4c0000gn/T/tmp0gupsy31/test_config.json
2025-06-06 10:38:03,058 - DEBUG - Loaded configuration from /var/folders/3f/2n5sjdw50vj9gfnrxjbptj4c0000gn/T/tmp0gupsy31/test_config.json
2025-06-06 10:38:03,058 - DEBUG - Saved configuration to /var/folders/3f/2n5sjdw50vj9gfnrxjbptj4c0000gn/T/tmp0gupsy31/test_config.json
2025-06-06 10:38:03,058 - DEBUG - Loaded configuration from /var/folders/3f/2n5sjdw50vj9gfnrxjbptj4c0000gn/T/tmp0gupsy31/test_config.json
2025-06-06 10:38:03,059 - DEBUG - Saved configuration to /var/folders/3f/2n5sjdw50vj9gfnrxjbptj4c0000gn/T/tmp0gupsy31/test_config.json
2025-06-06 10:38:03,059 - DEBUG - Loaded configuration from /var/folders/3f/2n5sjdw50vj9gfnrxjbptj4c0000gn/T/tmp0gupsy31/test_config.json
2025-06-06 10:38:03,059 - DEBUG - Saved configuration to /var/folders/3f/2n5sjdw50vj9gfnrxjbptj4c0000gn/T/tmp0gupsy31/test_config.json
2025-06-06 10:38:03,059 - DEBUG - Loaded configuration from /var/folders/3f/2n5sjdw50vj9gfnrxjbptj4c0000gn/T/tmp0gupsy31/test_config.json
2025-06-06 10:38:03,060 - DEBUG - Loaded configuration from /var/folders/3f/2n5sjdw50vj9gfnrxjbptj4c0000gn/T/tmp0gupsy31/test_config.json
2025-06-06 10:38:03,060 - DEBUG - Loaded configuration from /var/folders/3f/2n5sjdw50vj9gfnrxjbptj4c0000gn/T/tmp0gupsy31/test_config.json
2025-06-06 10:38:03,060 - DEBUG - Loaded configuration from /var/folders/3f/2n5sjdw50vj9gfnrxjbptj4c0000gn/T/tmp0gupsy31/test_config.json
2025-06-06 10:38:03,060 - DEBUG - Loaded configuration from /var/folders/3f/2n5sjdw50vj9gfnrxjbptj4c0000gn/T/tmp0gupsy31/test_config.json
2025-06-06 10:38:03,063 - DEBUG - Saved configuration to /var/folders/3f/2n5sjdw50vj9gfnrxjbptj4c0000gn/T/tmpcnkxqabn/test_config.json
2025-06-06 10:38:03,063 - DEBUG - Loaded configuration from /var/folders/3f/2n5sjdw50vj9gfnrxjbptj4c0000gn/T/tmpcnkxqabn/test_config.json
2025-06-06 10:38:03,066 - DEBUG - Saved configuration to /var/folders/3f/2n5sjdw50vj9gfnrxjbptj4c0000gn/T/tmp8c9p76pi/test_config.json
2025-06-06 10:38:03,066 - DEBUG - Loaded configuration from /var/folders/3f/2n5sjdw50vj9gfnrxjbptj4c0000gn/T/tmp8c9p76pi/test_config.json
2025-06-06 10:38:03,069 - DEBUG - Saved configuration to /var/folders/3f/2n5sjdw50vj9gfnrxjbptj4c0000gn/T/tmpqh6yiaqb/test_config.json
2025-06-06 10:38:03,069 - DEBUG - Loaded configuration from /var/folders/3f/2n5sjdw50vj9gfnrxjbptj4c0000gn/T/tmpqh6yiaqb/test_config.json
2025-06-06 10:38:03,069 - DEBUG - Loaded configuration from /var/folders/3f/2n5sjdw50vj9gfnrxjbptj4c0000gn/T/tmpqh6yiaqb/test_config.json
2025-06-06 10:38:03,070 - DEBUG - Saved configuration to /var/folders/3f/2n5sjdw50vj9gfnrxjbptj4c0000gn/T/tmpqh6yiaqb/test_config.json
2025-06-06 10:38:03,070 - DEBUG - Loaded configuration from /var/folders/3f/2n5sjdw50vj9gfnrxjbptj4c0000gn/T/tmpqh6yiaqb/test_config.json
2025-06-06 10:38:03,070 - DEBUG - Loaded configuration from /var/folders/3f/2n5sjdw50vj9gfnrxjbptj4c0000gn/T/tmpqh6yiaqb/test_config.json
2025-06-06 10:38:03,074 - DEBUG - Saved configuration to /var/folders/3f/2n5sjdw50vj9gfnrxjbptj4c0000gn/T/tmpufbnfzkm/test_config.json
2025-06-06 10:38:03,074 - DEBUG - Loaded configuration from /var/folders/3f/2n5sjdw50vj9gfnrxjbptj4c0000gn/T/tmpufbnfzkm/test_config.json
2025-06-06 10:38:03,075 - DEBUG - Loaded configuration from /var/folders/3f/2n5sjdw50vj9gfnrxjbptj4c0000gn/T/tmpufbnfzkm/test_config.json
2025-06-06 10:38:03,075 - DEBUG - Saved configuration to /var/folders/3f/2n5sjdw50vj9gfnrxjbptj4c0000gn/T/tmpufbnfzkm/test_config.json
2025-06-06 10:38:03,075 - DEBUG - Loaded configuration from /var/folders/3f/2n5sjdw50vj9gfnrxjbptj4c0000gn/T/tmpufbnfzkm/test_config.json
2025-06-06 10:38:03,076 - DEBUG - Saved configuration to /var/folders/3f/2n5sjdw50vj9gfnrxjbptj4c0000gn/T/tmpufbnfzkm/test_config.json
2025-06-06 10:38:03,076 - DEBUG - Loaded configuration from /var/folders/3f/2n5sjdw50vj9gfnrxjbptj4c0000gn/T/tmpufbnfzkm/test_config.json
2025-06-06 10:38:03,076 - DEBUG - Saved configuration to /var/folders/3f/2n5sjdw50vj9gfnrxjbptj4c0000gn/T/tmpufbnfzkm/test_config.json
2025-06-06 10:38:03,076 - DEBUG - Loaded configuration from /var/folders/3f/2n5sjdw50vj9gfnrxjbptj4c0000gn/T/tmpufbnfzkm/test_config.json
2025-06-06 10:38:03,077 - DEBUG - Saved configuration to /var/folders/3f/2n5sjdw50vj9gfnrxjbptj4c0000gn/T/tmpufbnfzkm/test_config.json
2025-06-06 10:38:03,077 - DEBUG - Loaded configuration from /var/folders/3f/2n5sjdw50vj9gfnrxjbptj4c0000gn/T/tmpufbnfzkm/test_config.json
2025-06-06 10:38:03,077 - DEBUG - Using workspace_url from environment variable CHUCK_WORKSPACE_URL
2025-06-06 10:38:03,077 - DEBUG - Using active_model from environment variable CHUCK_ACTIVE_MODEL
2025-06-06 10:38:03,077 - DEBUG - Using warehouse_id from environment variable CHUCK_WAREHOUSE_ID
2025-06-06 10:38:03,077 - DEBUG - Using active_catalog from environment variable CHUCK_ACTIVE_CATALOG
2025-06-06 10:38:03,077 - DEBUG - Using active_schema from environment variable CHUCK_ACTIVE_SCHEMA
2025-06-06 10:38:03,077 - DEBUG - Using usage_tracking_consent from environment variable CHUCK_USAGE_TRACKING_CONSENT
2025-06-06 10:38:03,077 - DEBUG - Loaded configuration from /var/folders/3f/2n5sjdw50vj9gfnrxjbptj4c0000gn/T/tmpufbnfzkm/test_config.json
2025-06-06 10:38:03,080 - DEBUG - Saved configuration to /var/folders/3f/2n5sjdw50vj9gfnrxjbptj4c0000gn/T/tmpvw4mctd5/test_config.json
2025-06-06 10:38:03,080 - DEBUG - Loaded configuration from /var/folders/3f/2n5sjdw50vj9gfnrxjbptj4c0000gn/T/tmpvw4mctd5/test_config.json
2025-06-06 10:38:03,080 - DEBUG - Loaded configuration from /var/folders/3f/2n5sjdw50vj9gfnrxjbptj4c0000gn/T/tmpvw4mctd5/test_config.json
2025-06-06 10:38:03,080 - WARNING - Invalid workspace_url provided, using default instead
2025-06-06 10:38:03,081 - DEBUG - Saved configuration to /var/folders/3f/2n5sjdw50vj9gfnrxjbptj4c0000gn/T/tmpvw4mctd5/test_config.json
2025-06-06 10:38:03,081 - DEBUG - Loaded configuration from /var/folders/3f/2n5sjdw50vj9gfnrxjbptj4c0000gn/T/tmpvw4mctd5/test_config.json
2025-06-06 10:38:03,081 - DEBUG - Loaded configuration from /var/folders/3f/2n5sjdw50vj9gfnrxjbptj4c0000gn/T/tmpvw4mctd5/test_config.json
2025-06-06 10:38:03,081 - DEBUG - Saved configuration to /var/folders/3f/2n5sjdw50vj9gfnrxjbptj4c0000gn/T/tmpvw4mctd5/test_config.json
2025-06-06 10:38:03,081 - DEBUG - Loaded configuration from /var/folders/3f/2n5sjdw50vj9gfnrxjbptj4c0000gn/T/tmpvw4mctd5/test_config.json
2025-06-06 10:38:03,084 - DEBUG - Using workspace_url from environment variable CHUCK_WORKSPACE_URL
2025-06-06 10:38:03,084 - DEBUG - Using workspace_url from environment variable CHUCK_WORKSPACE_URL
2025-06-06 10:38:03,084 - DEBUG - Using active_model from environment variable CHUCK_ACTIVE_MODEL
2025-06-06 10:38:03,085 - DEBUG - Using amperity_token from environment variable CHUCK_AMPERITY_TOKEN
2025-06-06 10:38:03,085 - DEBUG - Using databricks_token from environment variable CHUCK_DATABRICKS_TOKEN
2025-06-06 10:38:03,085 - DEBUG - Saved configuration to /var/folders/3f/2n5sjdw50vj9gfnrxjbptj4c0000gn/T/tmpiez91_48/test_config.json
2025-06-06 10:38:03,086 - DEBUG - Loaded configuration from /var/folders/3f/2n5sjdw50vj9gfnrxjbptj4c0000gn/T/tmpiez91_48/test_config.json
2025-06-06 10:38:03,089 - DEBUG - Saved configuration to /var/folders/3f/2n5sjdw50vj9gfnrxjbptj4c0000gn/T/tmp5a_a80zi/test_config.json
2025-06-06 10:38:03,109 - DEBUG - GET request to: https://adb-3856707039489412.12.azuredatabricks.net/test-endpoint
2025-06-06 10:38:03,116 - DEBUG - GET request to: https://test-workspace.cloud.databricks.com/test-endpoint
2025-06-06 10:38:03,116 - DEBUG - Connection error: Connection failed
2025-06-06 10:38:03,118 - DEBUG - GET request to: https://test-workspace.cloud.databricks.com/test-endpoint
2025-06-06 10:38:03,118 - DEBUG - HTTP error: HTTP 404, Response: Not Found
2025-06-06 10:38:03,121 - WARNING - Model 'nonexistent-model' not found
2025-06-06 10:38:03,122 - DEBUG - GET request to: https://test-workspace.cloud.databricks.com/test-endpoint
2025-06-06 10:38:03,132 - DEBUG - POST request to: https://test-workspace.cloud.databricks.com/test-endpoint
2025-06-06 10:38:03,132 - DEBUG - Connection error: Connection failed
2025-06-06 10:38:03,134 - DEBUG - POST request to: https://test-workspace.cloud.databricks.com/test-endpoint
2025-06-06 10:38:03,134 - DEBUG - HTTP error: HTTP 400, Response: Bad Request
2025-06-06 10:38:03,136 - DEBUG - POST request to: https://test-workspace.cloud.databricks.com/test-endpoint
2025-06-06 10:38:03,139 - DEBUG - File upload request to: https://test-workspace.cloud.databricks.com/api/2.0/fs/files/test/path.txt
2025-06-06 10:38:03,143 - DEBUG - File upload request to: https://test-workspace.cloud.databricks.com/api/2.0/fs/files/test/path.txt
2025-06-06 10:38:03,145 - DEBUG - Token validation failed: Token validation failed
2025-06-06 10:38:03,157 - ERROR - Error listing catalogs: Random failure 3
2025-06-06 10:38:03,162 - ERROR - Error listing catalogs: Random failure 6
2025-06-06 10:38:03,168 - ERROR - Error listing catalogs: Random failure 9
2025-06-06 10:38:03,752 - ERROR - Error displaying table: Console error
2025-06-06 10:38:03,756 - ERROR - Error listing catalogs: 403 Forbidden: Insufficient permissions
2025-06-06 10:38:03,758 - ERROR - Error listing catalogs: 401 Unauthorized: Invalid token
2025-06-06 10:38:03,760 - ERROR - Error listing catalogs: Access denied to resource
2025-06-06 10:38:03,766 - ERROR - Error listing catalogs: 'NoneType' object has no attribute 'get'
2025-06-06 10:38:03,774 - ERROR - Error listing catalogs: 'str' object has no attribute 'get'
2025-06-06 10:38:03,951 - ERROR - Error listing catalogs: Connection failed
2025-06-06 10:38:03,953 - ERROR - Error listing catalogs: Request timed out
2025-06-06 10:38:03,955 - ERROR - Error listing catalogs: 404 Not Found
2025-06-06 10:38:04,014 - DEBUG - Saved configuration to /tmp/.test_chuck_integration_config.json
2025-06-06 10:38:04,014 - DEBUG - Saved configuration to /tmp/.test_chuck_integration_config.json
2025-06-06 10:38:04,016 - DEBUG - Saved configuration to /tmp/.test_chuck_integration_config.json
2025-06-06 10:38:04,016 - DEBUG - Saved configuration to /tmp/.test_chuck_integration_config.json
2025-06-06 10:38:04,019 - DEBUG - Saved configuration to /tmp/.test_chuck_integration_config.json
2025-06-06 10:38:04,019 - DEBUG - Saved configuration to /tmp/.test_chuck_integration_config.json
2025-06-06 10:38:04,045 - DEBUG - Sending metric: {"event": "USAGE", "prompt": "test prompt"}...
2025-06-06 10:38:04,045 - DEBUG - Error sending metrics: Test exception
Traceback (most recent call last):
  File "/Users/johnrush/repos/chuck-data/src/metrics_collector.py", line 123, in send_metric
    return self._client.submit_metrics(payload, token)
           ^^^^^^^^^^^^^^^^^^^^^^^^^^^^^^^^^^^^^^^^^^^
  File "/Users/johnrush/repos/chuck-data/tests/fixtures.py", line 60, in submit_metrics
    raise Exception("Test exception")
Exception: Test exception
2025-06-06 10:38:04,048 - DEBUG - Sending metric: {"event": "USAGE", "prompt": "test prompt"}...
2025-06-06 10:38:04,050 - DEBUG - Cannot send metrics - no authentication token available
2025-06-06 10:38:04,052 - DEBUG - Sending metric: {"event": "USAGE", "prompt": "test prompt"}...
2025-06-06 10:38:04,057 - DEBUG - Metrics tracking skipped - user has not provided consent
2025-06-06 10:38:04,061 - ERROR - Connection error when getting model: Connection failed
2025-06-06 10:38:04,062 - ERROR - Failed to get model: HTTP error occurred: 500 Internal Server Error
2025-06-06 10:38:04,065 - ERROR - Connection error when listing models: Connection failed
2025-06-06 10:38:04,067 - ERROR - Failed to list models: HTTP error occurred: 404 Not Found
2025-06-06 10:38:04,129 - ERROR - Error executing handler for command 'test_command': Command failed
Traceback (most recent call last):
  File "/Users/johnrush/repos/chuck-data/src/service.py", line 395, in execute_command
    result: CommandResult = command_def.handler(
                            ^^^^^^^^^^^^^^^^^^^^
  File "/usr/local/Cellar/python@3.11/3.11.4_1/Frameworks/Python.framework/Versions/3.11/lib/python3.11/unittest/mock.py", line 1124, in __call__
    return self._mock_call(*args, **kwargs)
           ^^^^^^^^^^^^^^^^^^^^^^^^^^^^^^^^
  File "/usr/local/Cellar/python@3.11/3.11.4_1/Frameworks/Python.framework/Versions/3.11/lib/python3.11/unittest/mock.py", line 1128, in _mock_call
    return self._execute_mock_call(*args, **kwargs)
           ^^^^^^^^^^^^^^^^^^^^^^^^^^^^^^^^^^^^^^^^
  File "/usr/local/Cellar/python@3.11/3.11.4_1/Frameworks/Python.framework/Versions/3.11/lib/python3.11/unittest/mock.py", line 1183, in _execute_mock_call
    raise effect
Exception: Command failed
2025-06-06 10:38:04,314 - DEBUG - Executing SQL: SELECT * INVALID SQL
2025-06-06 10:38:04,316 - DEBUG - Executing SQL: SELECT * INVALID SQL
2025-06-06 10:38:04,318 - DEBUG - Executing SQL: SELECT * FROM table
2025-06-06 10:38:04,321 - DEBUG - Executing SQL: SELECT * FROM table
2025-06-06 10:38:04,323 - DEBUG - Executing SQL: SELECT * FROM table
2025-06-06 10:38:04,326 - DEBUG - Executing SQL: SELECT * FROM table
2025-06-06 10:38:04,335 - ERROR - Authentication state polling received 401
2025-06-06 10:38:04,341 - ERROR - Error creating Stitch report: API Error
Traceback (most recent call last):
  File "/Users/johnrush/repos/chuck-data/src/commands/add_stitch_report.py", line 62, in handle_command
    result = client.create_stitch_notebook(table_path, custom_name)
             ^^^^^^^^^^^^^^^^^^^^^^^^^^^^^^^^^^^^^^^^^^^^^^^^^^^^^^
  File "/Users/johnrush/repos/chuck-data/tests/fixtures.py", line 509, in create_stitch_notebook
    raise self._create_stitch_notebook_error
ValueError: API Error
2025-06-06 10:38:04,348 - ERROR - Agent error: Agent error
Traceback (most recent call last):
  File "/Users/johnrush/repos/chuck-data/src/commands/agent.py", line 79, in handle_command
    agent = AgentManager(client, tool_output_callback=tool_output_callback)
            ^^^^^^^^^^^^^^^^^^^^^^^^^^^^^^^^^^^^^^^^^^^^^^^^^^^^^^^^^^^^^^^
  File "/usr/local/Cellar/python@3.11/3.11.4_1/Frameworks/Python.framework/Versions/3.11/lib/python3.11/unittest/mock.py", line 1124, in __call__
    return self._mock_call(*args, **kwargs)
           ^^^^^^^^^^^^^^^^^^^^^^^^^^^^^^^^
  File "/usr/local/Cellar/python@3.11/3.11.4_1/Frameworks/Python.framework/Versions/3.11/lib/python3.11/unittest/mock.py", line 1128, in _mock_call
    return self._execute_mock_call(*args, **kwargs)
           ^^^^^^^^^^^^^^^^^^^^^^^^^^^^^^^^^^^^^^^^
  File "/usr/local/Cellar/python@3.11/3.11.4_1/Frameworks/Python.framework/Versions/3.11/lib/python3.11/unittest/mock.py", line 1183, in _execute_mock_call
    raise effect
Exception: Agent error
2025-06-06 10:38:04,350 - DEBUG - Sending metric: {"event": "USAGE", "configuration": {"workspace_url": "https://dbc-df998298-4c7e.cloud.databricks.co...
2025-06-06 10:38:04,425 - DEBUG - Starting new HTTPS connection (1): chuck.amperity.com:443
2025-06-06 10:38:04,900 - DEBUG - https://chuck.amperity.com:443 "POST /api/usage HTTP/1.1" 204 0
2025-06-06 10:38:04,901 - DEBUG - Failed to send metrics: 204 - 
2025-06-06 10:38:04,909 - DEBUG - Sending metric: {"event": "USAGE", "configuration": {"workspace_url": "https://dbc-df998298-4c7e.cloud.databricks.co...
2025-06-06 10:38:04,913 - DEBUG - Starting new HTTPS connection (1): chuck.amperity.com:443
2025-06-06 10:38:05,034 - DEBUG - https://chuck.amperity.com:443 "POST /api/usage HTTP/1.1" 204 0
2025-06-06 10:38:05,034 - DEBUG - Failed to send metrics: 204 - 
2025-06-06 10:38:05,047 - DEBUG - Sending metric: {"event": "USAGE", "configuration": {"workspace_url": "https://dbc-df998298-4c7e.cloud.databricks.co...
2025-06-06 10:38:05,050 - DEBUG - Starting new HTTPS connection (1): chuck.amperity.com:443
2025-06-06 10:38:05,159 - DEBUG - https://chuck.amperity.com:443 "POST /api/usage HTTP/1.1" 204 0
2025-06-06 10:38:05,159 - DEBUG - Failed to send metrics: 204 - 
2025-06-06 10:38:05,162 - DEBUG - Sending metric: {"event": "USAGE", "configuration": {"workspace_url": "https://dbc-df998298-4c7e.cloud.databricks.co...
2025-06-06 10:38:05,165 - DEBUG - Starting new HTTPS connection (1): chuck.amperity.com:443
2025-06-06 10:38:05,272 - DEBUG - https://chuck.amperity.com:443 "POST /api/usage HTTP/1.1" 204 0
2025-06-06 10:38:05,272 - DEBUG - Failed to send metrics: 204 - 
2025-06-06 10:38:05,277 - DEBUG - Sending metric: {"event": "USAGE", "configuration": {"workspace_url": "https://dbc-df998298-4c7e.cloud.databricks.co...
2025-06-06 10:38:05,280 - DEBUG - Starting new HTTPS connection (1): chuck.amperity.com:443
2025-06-06 10:38:05,377 - DEBUG - https://chuck.amperity.com:443 "POST /api/usage HTTP/1.1" 204 0
2025-06-06 10:38:05,378 - DEBUG - Failed to send metrics: 204 - 
2025-06-06 10:38:05,387 - INFO - Databricks token set successfully
2025-06-06 10:38:05,390 - INFO - Databricks token cleared
2025-06-06 10:38:05,390 - INFO - Amperity token cleared
2025-06-06 10:38:05,392 - INFO - Amperity token cleared
2025-06-06 10:38:05,393 - INFO - Databricks token cleared
2025-06-06 10:38:05,395 - INFO - Amperity token cleared
2025-06-06 10:38:05,411 - DEBUG - Bug report submitted successfully
2025-06-06 10:38:05,470 - ERROR - Error submitting bug report: Network error
Traceback (most recent call last):
  File "/Users/johnrush/repos/chuck-data/src/commands/bug.py", line 72, in handle_command
    success, message = amperity_client.submit_bug_report(payload, amperity_token)
                       ^^^^^^^^^^^^^^^^^^^^^^^^^^^^^^^^^^^^^^^^^^^^^^^^^^^^^^^^^^
  File "/Users/johnrush/repos/chuck-data/tests/commands/test_bug.py", line 115, in submit_bug_report
    raise Exception("Network error")
Exception: Network error
2025-06-06 10:38:05,473 - DEBUG - Loaded configuration from /var/folders/3f/2n5sjdw50vj9gfnrxjbptj4c0000gn/T/tmpff1wzbah.json
2025-06-06 10:38:05,475 - DEBUG - Loaded configuration from /var/folders/3f/2n5sjdw50vj9gfnrxjbptj4c0000gn/T/tmpa6_e3djb.json
2025-06-06 10:38:05,486 - DEBUG - Bug report submitted successfully
2025-06-06 10:38:05,488 - ERROR - Error saving config: [Errno 30] Read-only file system: '/invalid'
2025-06-06 10:38:05,489 - DEBUG - Saved configuration to /var/folders/3f/2n5sjdw50vj9gfnrxjbptj4c0000gn/T/tmpwl9n45t7/test_config.json
2025-06-06 10:38:05,492 - DEBUG - Saved configuration to /var/folders/3f/2n5sjdw50vj9gfnrxjbptj4c0000gn/T/tmpu1g67t6w/test_config.json
2025-06-06 10:38:05,492 - DEBUG - Loaded configuration from /var/folders/3f/2n5sjdw50vj9gfnrxjbptj4c0000gn/T/tmpu1g67t6w/test_config.json
2025-06-06 10:38:05,495 - DEBUG - Saved configuration to /var/folders/3f/2n5sjdw50vj9gfnrxjbptj4c0000gn/T/tmp33x251iu/test_config.json
2025-06-06 10:38:05,496 - DEBUG - Loaded configuration from /var/folders/3f/2n5sjdw50vj9gfnrxjbptj4c0000gn/T/tmp33x251iu/test_config.json
2025-06-06 10:38:05,499 - INFO - Cluster init script uploaded successfully to /Volumes/main/default/chuck/cluster_init-2025-06-02_14-30.sh
2025-06-06 10:38:05,507 - DEBUG - Volume 'chuck' not found in main.default. Attempting to create.
2025-06-06 10:38:05,507 - DEBUG - Volume 'chuck' created successfully.
2025-06-06 10:38:05,507 - INFO - Cluster init script uploaded successfully to /Volumes/main/default/chuck/cluster_init-2025-06-02_14-30.sh
2025-06-06 10:38:05,510 - DEBUG - Volume 'chuck' not found in main.default. Attempting to create.
2025-06-06 10:38:05,510 - DEBUG - Volume 'chuck' created successfully.
2025-06-06 10:38:05,511 - INFO - Cluster init script uploaded successfully to /Volumes/main/default/chuck/cluster_init-2025-06-02_14-30.sh
2025-06-06 10:38:05,514 - DEBUG - Volume 'chuck' not found in main.default. Attempting to create.
2025-06-06 10:38:05,515 - DEBUG - Volume 'chuck' not found in main.default. Attempting to create.
2025-06-06 10:38:05,521 - INFO - Cluster init script uploaded successfully to /Volumes/test_catalog/test_schema/chuck/cluster_init-2025-12-31_23-59.sh
2025-06-06 10:38:05,524 - ERROR - Error generating help: Test error
Traceback (most recent call last):
  File "/Users/johnrush/repos/chuck-data/src/commands/help.py", line 27, in handle_command
    user_commands = get_user_commands()
                    ^^^^^^^^^^^^^^^^^^^
  File "/usr/local/Cellar/python@3.11/3.11.4_1/Frameworks/Python.framework/Versions/3.11/lib/python3.11/unittest/mock.py", line 1124, in __call__
    return self._mock_call(*args, **kwargs)
           ^^^^^^^^^^^^^^^^^^^^^^^^^^^^^^^^
  File "/usr/local/Cellar/python@3.11/3.11.4_1/Frameworks/Python.framework/Versions/3.11/lib/python3.11/unittest/mock.py", line 1128, in _mock_call
    return self._execute_mock_call(*args, **kwargs)
           ^^^^^^^^^^^^^^^^^^^^^^^^^^^^^^^^^^^^^^^^
  File "/usr/local/Cellar/python@3.11/3.11.4_1/Frameworks/Python.framework/Versions/3.11/lib/python3.11/unittest/mock.py", line 1183, in _execute_mock_call
    raise effect
Exception: Test error
2025-06-06 10:38:05,529 - ERROR - Failed to get job status for run '999999': Not Found
Traceback (most recent call last):
  File "/Users/johnrush/repos/chuck-data/src/commands/jobs.py", line 67, in handle_job_status
    data = client.get_job_run_status(run_id_str)
           ^^^^^^^^^^^^^^^^^^^^^^^^^^^^^^^^^^^^^
  File "/Users/johnrush/repos/chuck-data/tests/commands/test_jobs.py", line 119, in get_job_run_status
    raise Exception("Not Found")
Exception: Not Found
2025-06-06 10:38:05,535 - ERROR - Failed to submit job: Bad Request
Traceback (most recent call last):
  File "/Users/johnrush/repos/chuck-data/src/commands/jobs.py", line 32, in handle_launch_job
    run_data = client.submit_job_run(
               ^^^^^^^^^^^^^^^^^^^^^^
  File "/Users/johnrush/repos/chuck-data/tests/commands/test_jobs.py", line 70, in submit_job_run
    raise Exception("Bad Request")
Exception: Bad Request
2025-06-06 10:38:05,539 - ERROR - Failed to launch job, no run_id: {}
2025-06-06 10:38:05,545 - ERROR - Error listing catalogs: API error
2025-06-06 10:38:05,553 - DEBUG - Saved configuration to /var/folders/3f/2n5sjdw50vj9gfnrxjbptj4c0000gn/T/tmp524ynt39/test_config.json
2025-06-06 10:38:05,553 - DEBUG - Loaded configuration from /var/folders/3f/2n5sjdw50vj9gfnrxjbptj4c0000gn/T/tmp524ynt39/test_config.json
2025-06-06 10:38:05,556 - DEBUG - Saved configuration to /var/folders/3f/2n5sjdw50vj9gfnrxjbptj4c0000gn/T/tmp8vlzzyn2/test_config.json
2025-06-06 10:38:05,556 - DEBUG - Loaded configuration from /var/folders/3f/2n5sjdw50vj9gfnrxjbptj4c0000gn/T/tmp8vlzzyn2/test_config.json
2025-06-06 10:38:05,559 - DEBUG - Saved configuration to /var/folders/3f/2n5sjdw50vj9gfnrxjbptj4c0000gn/T/tmp5m062438/test_config.json
2025-06-06 10:38:05,560 - DEBUG - Loaded configuration from /var/folders/3f/2n5sjdw50vj9gfnrxjbptj4c0000gn/T/tmp5m062438/test_config.json
2025-06-06 10:38:05,561 - ERROR - Failed to list models: API error
Traceback (most recent call last):
  File "/Users/johnrush/repos/chuck-data/src/commands/list_models.py", line 31, in handle_command
    models_list = list_models_api(client)
                  ^^^^^^^^^^^^^^^^^^^^^^^
  File "/Users/johnrush/repos/chuck-data/src/models.py", line 19, in list_models
    return client.list_models()
           ^^^^^^^^^^^^^^^^^^^^
  File "/Users/johnrush/repos/chuck-data/tests/commands/test_list_models.py", line 112, in list_models
    raise Exception("API error")
Exception: API error
2025-06-06 10:38:05,566 - ERROR - Error listing tables: API error
2025-06-06 10:38:05,569 - DEBUG - Saved configuration to /var/folders/3f/2n5sjdw50vj9gfnrxjbptj4c0000gn/T/tmp09cfmwue/test_config.json
2025-06-06 10:38:05,569 - DEBUG - Loaded configuration from /var/folders/3f/2n5sjdw50vj9gfnrxjbptj4c0000gn/T/tmp09cfmwue/test_config.json
2025-06-06 10:38:05,569 - DEBUG - Loaded configuration from /var/folders/3f/2n5sjdw50vj9gfnrxjbptj4c0000gn/T/tmp09cfmwue/test_config.json
2025-06-06 10:38:05,573 - DEBUG - Saved configuration to /var/folders/3f/2n5sjdw50vj9gfnrxjbptj4c0000gn/T/tmpn4x9w7fs/test_config.json
2025-06-06 10:38:05,573 - DEBUG - Loaded configuration from /var/folders/3f/2n5sjdw50vj9gfnrxjbptj4c0000gn/T/tmpn4x9w7fs/test_config.json
2025-06-06 10:38:05,573 - DEBUG - Saved configuration to /var/folders/3f/2n5sjdw50vj9gfnrxjbptj4c0000gn/T/tmpn4x9w7fs/test_config.json
2025-06-06 10:38:05,574 - DEBUG - Loaded configuration from /var/folders/3f/2n5sjdw50vj9gfnrxjbptj4c0000gn/T/tmpn4x9w7fs/test_config.json
2025-06-06 10:38:05,574 - DEBUG - Loaded configuration from /var/folders/3f/2n5sjdw50vj9gfnrxjbptj4c0000gn/T/tmpn4x9w7fs/test_config.json
2025-06-06 10:38:05,580 - ERROR - Failed to set model 'claude-v1': API error
Traceback (most recent call last):
  File "/Users/johnrush/repos/chuck-data/src/commands/model_selection.py", line 28, in handle_command
    models_list = list_models_api(client)
                  ^^^^^^^^^^^^^^^^^^^^^^^
  File "/Users/johnrush/repos/chuck-data/src/models.py", line 19, in list_models
    return client.list_models()
           ^^^^^^^^^^^^^^^^^^^^
  File "/Users/johnrush/repos/chuck-data/tests/commands/test_model_selection.py", line 79, in list_models
    raise Exception("API error")
Exception: API error
2025-06-06 10:38:05,583 - DEBUG - Saved configuration to /var/folders/3f/2n5sjdw50vj9gfnrxjbptj4c0000gn/T/tmpl_fpaafn/test_config.json
2025-06-06 10:38:05,583 - DEBUG - Loaded configuration from /var/folders/3f/2n5sjdw50vj9gfnrxjbptj4c0000gn/T/tmpl_fpaafn/test_config.json
2025-06-06 10:38:05,585 - DEBUG - Saved configuration to /var/folders/3f/2n5sjdw50vj9gfnrxjbptj4c0000gn/T/tmphy0koa6j/test_config.json
2025-06-06 10:38:05,586 - DEBUG - Loaded configuration from /var/folders/3f/2n5sjdw50vj9gfnrxjbptj4c0000gn/T/tmphy0koa6j/test_config.json
2025-06-06 10:38:05,588 - DEBUG - Saved configuration to /var/folders/3f/2n5sjdw50vj9gfnrxjbptj4c0000gn/T/tmpx80a8gcj/test_config.json
2025-06-06 10:38:05,588 - DEBUG - Loaded configuration from /var/folders/3f/2n5sjdw50vj9gfnrxjbptj4c0000gn/T/tmpx80a8gcj/test_config.json
2025-06-06 10:38:05,593 - DEBUG - Saved configuration to /var/folders/3f/2n5sjdw50vj9gfnrxjbptj4c0000gn/T/tmp7xnhbbu2/test_config.json
2025-06-06 10:38:05,593 - DEBUG - Loaded configuration from /var/folders/3f/2n5sjdw50vj9gfnrxjbptj4c0000gn/T/tmp7xnhbbu2/test_config.json
2025-06-06 10:38:05,601 - INFO - Starting PII Scan for 2 tables in test_cat.test_schema.
2025-06-06 10:38:05,611 - ERROR - Bulk PII scan error: LLM client error
Traceback (most recent call last):
  File "/Users/johnrush/repos/chuck-data/src/commands/scan_pii.py", line 46, in handle_command
    llm_client = LLMClient()
                 ^^^^^^^^^^^
  File "/usr/local/Cellar/python@3.11/3.11.4_1/Frameworks/Python.framework/Versions/3.11/lib/python3.11/unittest/mock.py", line 1124, in __call__
    return self._mock_call(*args, **kwargs)
           ^^^^^^^^^^^^^^^^^^^^^^^^^^^^^^^^
  File "/usr/local/Cellar/python@3.11/3.11.4_1/Frameworks/Python.framework/Versions/3.11/lib/python3.11/unittest/mock.py", line 1128, in _mock_call
    return self._execute_mock_call(*args, **kwargs)
           ^^^^^^^^^^^^^^^^^^^^^^^^^^^^^^^^^^^^^^^^
  File "/usr/local/Cellar/python@3.11/3.11.4_1/Frameworks/Python.framework/Versions/3.11/lib/python3.11/unittest/mock.py", line 1183, in _execute_mock_call
    raise effect
Exception: LLM client error
2025-06-06 10:38:05,621 - DEBUG - Saved configuration to /var/folders/3f/2n5sjdw50vj9gfnrxjbptj4c0000gn/T/tmpgseh375i/test_config.json
2025-06-06 10:38:05,621 - DEBUG - Loaded configuration from /var/folders/3f/2n5sjdw50vj9gfnrxjbptj4c0000gn/T/tmpgseh375i/test_config.json
2025-06-06 10:38:05,622 - DEBUG - Loaded configuration from /var/folders/3f/2n5sjdw50vj9gfnrxjbptj4c0000gn/T/tmpgseh375i/test_config.json
2025-06-06 10:38:05,622 - DEBUG - Saved configuration to /var/folders/3f/2n5sjdw50vj9gfnrxjbptj4c0000gn/T/tmpgseh375i/test_config.json
2025-06-06 10:38:05,624 - DEBUG - Saved configuration to /var/folders/3f/2n5sjdw50vj9gfnrxjbptj4c0000gn/T/tmpn_wud6f6/test_config.json
2025-06-06 10:38:05,624 - DEBUG - Loaded configuration from /var/folders/3f/2n5sjdw50vj9gfnrxjbptj4c0000gn/T/tmpn_wud6f6/test_config.json
2025-06-06 10:38:05,624 - DEBUG - Loaded configuration from /var/folders/3f/2n5sjdw50vj9gfnrxjbptj4c0000gn/T/tmpn_wud6f6/test_config.json
2025-06-06 10:38:05,625 - DEBUG - Saved configuration to /var/folders/3f/2n5sjdw50vj9gfnrxjbptj4c0000gn/T/tmpn_wud6f6/test_config.json
2025-06-06 10:38:05,625 - DEBUG - Loaded configuration from /var/folders/3f/2n5sjdw50vj9gfnrxjbptj4c0000gn/T/tmpn_wud6f6/test_config.json
2025-06-06 10:38:05,627 - DEBUG - Saved configuration to /var/folders/3f/2n5sjdw50vj9gfnrxjbptj4c0000gn/T/tmpqt4b4l1u/test_config.json
2025-06-06 10:38:05,627 - DEBUG - Loaded configuration from /var/folders/3f/2n5sjdw50vj9gfnrxjbptj4c0000gn/T/tmpqt4b4l1u/test_config.json
2025-06-06 10:38:05,627 - DEBUG - Loaded configuration from /var/folders/3f/2n5sjdw50vj9gfnrxjbptj4c0000gn/T/tmpqt4b4l1u/test_config.json
2025-06-06 10:38:05,628 - DEBUG - Saved configuration to /var/folders/3f/2n5sjdw50vj9gfnrxjbptj4c0000gn/T/tmpqt4b4l1u/test_config.json
2025-06-06 10:38:05,628 - DEBUG - Loaded configuration from /var/folders/3f/2n5sjdw50vj9gfnrxjbptj4c0000gn/T/tmpqt4b4l1u/test_config.json
2025-06-06 10:38:05,634 - DEBUG - Sending metric: {"event": "USAGE", "configuration": {"workspace_url": "https://dbc-df998298-4c7e.cloud.databricks.co...
2025-06-06 10:38:05,637 - DEBUG - Starting new HTTPS connection (1): chuck.amperity.com:443
2025-06-06 10:38:05,742 - DEBUG - https://chuck.amperity.com:443 "POST /api/usage HTTP/1.1" 204 0
2025-06-06 10:38:05,742 - DEBUG - Failed to send metrics: 204 - 
2025-06-06 10:38:05,747 - ERROR - Stitch setup error: LLM client error
Traceback (most recent call last):
  File "/Users/johnrush/repos/chuck-data/src/commands/setup_stitch.py", line 111, in handle_command
    return _phase_1_prepare_config(
           ^^^^^^^^^^^^^^^^^^^^^^^^
  File "/Users/johnrush/repos/chuck-data/src/commands/setup_stitch.py", line 273, in _phase_1_prepare_config
    llm_client = LLMClient()
                 ^^^^^^^^^^^
  File "/usr/local/Cellar/python@3.11/3.11.4_1/Frameworks/Python.framework/Versions/3.11/lib/python3.11/unittest/mock.py", line 1124, in __call__
    return self._mock_call(*args, **kwargs)
           ^^^^^^^^^^^^^^^^^^^^^^^^^^^^^^^^
  File "/usr/local/Cellar/python@3.11/3.11.4_1/Frameworks/Python.framework/Versions/3.11/lib/python3.11/unittest/mock.py", line 1128, in _mock_call
    return self._execute_mock_call(*args, **kwargs)
           ^^^^^^^^^^^^^^^^^^^^^^^^^^^^^^^^^^^^^^^^
  File "/usr/local/Cellar/python@3.11/3.11.4_1/Frameworks/Python.framework/Versions/3.11/lib/python3.11/unittest/mock.py", line 1183, in _execute_mock_call
    raise effect
Exception: LLM client error
2025-06-06 10:38:05,761 - DEBUG - GET request to: https://.cloud.databricks.com/api/2.0/preview/scim/v2/Me
2025-06-06 10:38:05,761 - DEBUG - Connection error: URL has an invalid label.
2025-06-06 10:38:05,761 - DEBUG - Token validation failed: Connection error occurred: URL has an invalid label.
2025-06-06 10:38:05,765 - ERROR - Error validating token: Connection failed
2025-06-06 10:38:05,773 - DEBUG - GET request to: https://invalid-workspace.nonexistent.com.cloud.databricks.com/api/2.0/preview/scim/v2/Me
2025-06-06 10:38:05,865 - DEBUG - Starting new HTTPS connection (1): invalid-workspace.nonexistent.com.cloud.databricks.com:443
2025-06-06 10:38:05,867 - DEBUG - Connection error: HTTPSConnectionPool(host='invalid-workspace.nonexistent.com.cloud.databricks.com', port=443): Max retries exceeded with url: /api/2.0/preview/scim/v2/Me (Caused by NameResolutionError("<urllib3.connection.HTTPSConnection object at 0x1106fb150>: Failed to resolve 'invalid-workspace.nonexistent.com.cloud.databricks.com' ([Errno 8] nodename nor servname provided, or not known)"))
2025-06-06 10:38:05,867 - DEBUG - Token validation failed: Connection error occurred: HTTPSConnectionPool(host='invalid-workspace.nonexistent.com.cloud.databricks.com', port=443): Max retries exceeded with url: /api/2.0/preview/scim/v2/Me (Caused by NameResolutionError("<urllib3.connection.HTTPSConnection object at 0x1106fb150>: Failed to resolve 'invalid-workspace.nonexistent.com.cloud.databricks.com' ([Errno 8] nodename nor servname provided, or not known)"))
2025-06-06 10:38:05,993 - DEBUG - GET request to: https://invalid.nonexistent.com.cloud.databricks.com/api/2.0/preview/scim/v2/Me
2025-06-06 10:38:06,035 - DEBUG - Starting new HTTPS connection (1): invalid.nonexistent.com.cloud.databricks.com:443
2025-06-06 10:38:06,037 - DEBUG - Connection error: HTTPSConnectionPool(host='invalid.nonexistent.com.cloud.databricks.com', port=443): Max retries exceeded with url: /api/2.0/preview/scim/v2/Me (Caused by NameResolutionError("<urllib3.connection.HTTPSConnection object at 0x1107ded90>: Failed to resolve 'invalid.nonexistent.com.cloud.databricks.com' ([Errno 8] nodename nor servname provided, or not known)"))
2025-06-06 10:38:06,037 - DEBUG - Token validation failed: Connection error occurred: HTTPSConnectionPool(host='invalid.nonexistent.com.cloud.databricks.com', port=443): Max retries exceeded with url: /api/2.0/preview/scim/v2/Me (Caused by NameResolutionError("<urllib3.connection.HTTPSConnection object at 0x1107ded90>: Failed to resolve 'invalid.nonexistent.com.cloud.databricks.com' ([Errno 8] nodename nor servname provided, or not known)"))
2025-06-06 10:38:06,039 - ERROR - Error validating token: Validation failed
2025-06-06 10:38:06,182 - ERROR - Error validating token: Connection failed
2025-06-06 10:38:06,220 - ERROR - Error validating token: Network error with secret details
2025-06-06 10:38:06,262 - ERROR - Error validating token: Connection error: Failed to resolve 'workspace123.cloud.databricks.com'
2025-06-06 10:38:06,279 - ERROR - Error fetching Amperity init script: API Error
Traceback (most recent call last):
  File "/Users/johnrush/repos/chuck-data/src/commands/stitch_tools.py", line 179, in _helper_prepare_stitch_config
    init_script_data = client.fetch_amperity_job_init(amperity_token)
                       ^^^^^^^^^^^^^^^^^^^^^^^^^^^^^^^^^^^^^^^^^^^^^^
  File "/usr/local/Cellar/python@3.11/3.11.4_1/Frameworks/Python.framework/Versions/3.11/lib/python3.11/unittest/mock.py", line 1124, in __call__
    return self._mock_call(*args, **kwargs)
           ^^^^^^^^^^^^^^^^^^^^^^^^^^^^^^^^
  File "/usr/local/Cellar/python@3.11/3.11.4_1/Frameworks/Python.framework/Versions/3.11/lib/python3.11/unittest/mock.py", line 1128, in _mock_call
    return self._execute_mock_call(*args, **kwargs)
           ^^^^^^^^^^^^^^^^^^^^^^^^^^^^^^^^^^^^^^^^
  File "/usr/local/Cellar/python@3.11/3.11.4_1/Frameworks/Python.framework/Versions/3.11/lib/python3.11/unittest/mock.py", line 1183, in _execute_mock_call
    raise effect
Exception: API Error
2025-06-06 10:38:06,290 - DEBUG - Versioned cluster init script uploaded to /Volumes/test_catalog/test_schema/chuck/cluster_init-2025-06-02_14-30.sh
2025-06-06 10:38:06,293 - DEBUG - Versioned cluster init script uploaded to /Volumes/test_catalog/test_schema/chuck/cluster_init-2025-06-02_14-30.sh
2025-06-06 10:38:06,298 - DEBUG - Volume 'chuck' not found in test_catalog.test_schema. Attempting to create.
2025-06-06 10:38:06,311 - DEBUG - Saved configuration to /var/folders/3f/2n5sjdw50vj9gfnrxjbptj4c0000gn/T/tmpu8eephtp/test_config.json
2025-06-06 10:38:06,311 - DEBUG - Loaded configuration from /var/folders/3f/2n5sjdw50vj9gfnrxjbptj4c0000gn/T/tmpu8eephtp/test_config.json
2025-06-06 10:38:06,311 - DEBUG - Loaded configuration from /var/folders/3f/2n5sjdw50vj9gfnrxjbptj4c0000gn/T/tmpu8eephtp/test_config.json
2025-06-06 10:38:06,311 - DEBUG - Loaded configuration from /var/folders/3f/2n5sjdw50vj9gfnrxjbptj4c0000gn/T/tmpu8eephtp/test_config.json
2025-06-06 10:38:06,313 - DEBUG - Saved configuration to /var/folders/3f/2n5sjdw50vj9gfnrxjbptj4c0000gn/T/tmph8pataep/test_config.json
2025-06-06 10:38:06,314 - DEBUG - Loaded configuration from /var/folders/3f/2n5sjdw50vj9gfnrxjbptj4c0000gn/T/tmph8pataep/test_config.json
2025-06-06 10:38:06,314 - DEBUG - Saved configuration to /var/folders/3f/2n5sjdw50vj9gfnrxjbptj4c0000gn/T/tmph8pataep/test_config.json
2025-06-06 10:38:06,314 - DEBUG - Loaded configuration from /var/folders/3f/2n5sjdw50vj9gfnrxjbptj4c0000gn/T/tmph8pataep/test_config.json
2025-06-06 10:38:06,315 - DEBUG - Saved configuration to /var/folders/3f/2n5sjdw50vj9gfnrxjbptj4c0000gn/T/tmph8pataep/test_config.json
2025-06-06 10:38:06,315 - DEBUG - Loaded configuration from /var/folders/3f/2n5sjdw50vj9gfnrxjbptj4c0000gn/T/tmph8pataep/test_config.json
2025-06-06 10:38:06,315 - DEBUG - Loaded configuration from /var/folders/3f/2n5sjdw50vj9gfnrxjbptj4c0000gn/T/tmph8pataep/test_config.json
2025-06-06 10:38:06,315 - DEBUG - Loaded configuration from /var/folders/3f/2n5sjdw50vj9gfnrxjbptj4c0000gn/T/tmph8pataep/test_config.json
2025-06-06 10:38:06,317 - INFO - Applying tag 'email' to column 'email_col'
2025-06-06 10:38:06,317 - INFO - Applying tag 'given-name' to column 'name_col'
2025-06-06 10:38:06,319 - INFO - Applying tag 'phone' to column 'good_col'
2025-06-06 10:38:06,320 - INFO - Applying tag 'email' to column 'email_col'
2025-06-06 10:38:06,322 - INFO - Applying tag 'email' to column 'email_col'
2025-06-06 10:38:06,322 - ERROR - Error applying tag to email_col: Connection error
2025-06-06 10:38:06,326 - DEBUG - Saved configuration to /var/folders/3f/2n5sjdw50vj9gfnrxjbptj4c0000gn/T/tmpxql4m9j9/test_config.json
2025-06-06 10:38:06,326 - DEBUG - Loaded configuration from /var/folders/3f/2n5sjdw50vj9gfnrxjbptj4c0000gn/T/tmpxql4m9j9/test_config.json
2025-06-06 10:38:06,328 - DEBUG - Saved configuration to /var/folders/3f/2n5sjdw50vj9gfnrxjbptj4c0000gn/T/tmpoftuwc29/test_config.json
2025-06-06 10:38:06,330 - DEBUG - Saved configuration to /var/folders/3f/2n5sjdw50vj9gfnrxjbptj4c0000gn/T/tmp8vsywb1u/test_config.json
2025-06-06 10:38:06,331 - DEBUG - Loaded configuration from /var/folders/3f/2n5sjdw50vj9gfnrxjbptj4c0000gn/T/tmp8vsywb1u/test_config.json
2025-06-06 10:38:06,333 - DEBUG - Saved configuration to /var/folders/3f/2n5sjdw50vj9gfnrxjbptj4c0000gn/T/tmp19errci5/test_config.json
2025-06-06 10:38:06,333 - DEBUG - Loaded configuration from /var/folders/3f/2n5sjdw50vj9gfnrxjbptj4c0000gn/T/tmp19errci5/test_config.json
2025-06-06 10:38:06,340 - ERROR - Failed to set workspace URL: Validation error
Traceback (most recent call last):
  File "/Users/johnrush/repos/chuck-data/src/commands/workspace_selection.py", line 37, in handle_command
    is_valid, error_message = validate_workspace_url(workspace_url)
                              ^^^^^^^^^^^^^^^^^^^^^^^^^^^^^^^^^^^^^
  File "/usr/local/Cellar/python@3.11/3.11.4_1/Frameworks/Python.framework/Versions/3.11/lib/python3.11/unittest/mock.py", line 1124, in __call__
    return self._mock_call(*args, **kwargs)
           ^^^^^^^^^^^^^^^^^^^^^^^^^^^^^^^^
  File "/usr/local/Cellar/python@3.11/3.11.4_1/Frameworks/Python.framework/Versions/3.11/lib/python3.11/unittest/mock.py", line 1128, in _mock_call
    return self._execute_mock_call(*args, **kwargs)
           ^^^^^^^^^^^^^^^^^^^^^^^^^^^^^^^^^^^^^^^^
  File "/usr/local/Cellar/python@3.11/3.11.4_1/Frameworks/Python.framework/Versions/3.11/lib/python3.11/unittest/mock.py", line 1183, in _execute_mock_call
    raise effect
Exception: Validation error
