2025-05-27 11:27:01,662 - INFO - Starting PII Scan for 3 tables in chuck_integration_test_6617.bronze.
2025-05-27 11:27:08,327 - INFO - Stitch config written to /Volumes/chuck_integration_test_6617/bronze/chuck/stitch-2025-05-27_11-27.json
2025-05-27 11:28:23,338 - ERROR - Connection error: HTTPSConnectionPool(host='chuck-dev.amperity.top', port=443): Max retries exceeded with url: /api/job/launch (Caused by ConnectTimeoutError(<urllib3.connection.HTTPSConnection object at 0x1088e2d50>, 'Connection to chuck-dev.amperity.top timed out. (connect timeout=None)'))
2025-05-27 11:28:23,339 - ERROR - Error fetching Amperity init script: Connection error occurred: HTTPSConnectionPool(host='chuck-dev.amperity.top', port=443): Max retries exceeded with url: /api/job/launch (Caused by ConnectTimeoutError(<urllib3.connection.HTTPSConnection object at 0x1088e2d50>, 'Connection to chuck-dev.amperity.top timed out. (connect timeout=None)'))
Traceback (most recent call last):
  File "/Users/johnrush/repos/clamp-internal/.venv/lib/python3.13/site-packages/urllib3/connection.py", line 198, in _new_conn
    sock = connection.create_connection(
        (self._dns_host, self.port),
    ...<2 lines>...
        socket_options=self.socket_options,
    )
  File "/Users/johnrush/repos/clamp-internal/.venv/lib/python3.13/site-packages/urllib3/util/connection.py", line 85, in create_connection
    raise err
  File "/Users/johnrush/repos/clamp-internal/.venv/lib/python3.13/site-packages/urllib3/util/connection.py", line 73, in create_connection
    sock.connect(sa)
    ~~~~~~~~~~~~^^^^
TimeoutError: [Errno 60] Operation timed out

The above exception was the direct cause of the following exception:

Traceback (most recent call last):
  File "/Users/johnrush/repos/clamp-internal/.venv/lib/python3.13/site-packages/urllib3/connectionpool.py", line 787, in urlopen
    response = self._make_request(
        conn,
    ...<10 lines>...
        **response_kw,
    )
  File "/Users/johnrush/repos/clamp-internal/.venv/lib/python3.13/site-packages/urllib3/connectionpool.py", line 488, in _make_request
    raise new_e
  File "/Users/johnrush/repos/clamp-internal/.venv/lib/python3.13/site-packages/urllib3/connectionpool.py", line 464, in _make_request
    self._validate_conn(conn)
    ~~~~~~~~~~~~~~~~~~~^^^^^^
  File "/Users/johnrush/repos/clamp-internal/.venv/lib/python3.13/site-packages/urllib3/connectionpool.py", line 1093, in _validate_conn
    conn.connect()
    ~~~~~~~~~~~~^^
  File "/Users/johnrush/repos/clamp-internal/.venv/lib/python3.13/site-packages/urllib3/connection.py", line 704, in connect
    self.sock = sock = self._new_conn()
                       ~~~~~~~~~~~~~~^^
  File "/Users/johnrush/repos/clamp-internal/.venv/lib/python3.13/site-packages/urllib3/connection.py", line 207, in _new_conn
    raise ConnectTimeoutError(
    ...<2 lines>...
    ) from e
urllib3.exceptions.ConnectTimeoutError: (<urllib3.connection.HTTPSConnection object at 0x1088e2d50>, 'Connection to chuck-dev.amperity.top timed out. (connect timeout=None)')

The above exception was the direct cause of the following exception:

Traceback (most recent call last):
  File "/Users/johnrush/repos/clamp-internal/.venv/lib/python3.13/site-packages/requests/adapters.py", line 667, in send
    resp = conn.urlopen(
        method=request.method,
    ...<9 lines>...
        chunked=chunked,
    )
  File "/Users/johnrush/repos/clamp-internal/.venv/lib/python3.13/site-packages/urllib3/connectionpool.py", line 841, in urlopen
    retries = retries.increment(
        method, url, error=new_e, _pool=self, _stacktrace=sys.exc_info()[2]
    )
  File "/Users/johnrush/repos/clamp-internal/.venv/lib/python3.13/site-packages/urllib3/util/retry.py", line 519, in increment
    raise MaxRetryError(_pool, url, reason) from reason  # type: ignore[arg-type]
    ^^^^^^^^^^^^^^^^^^^^^^^^^^^^^^^^^^^^^^^^^^^^^^^^^^^
urllib3.exceptions.MaxRetryError: HTTPSConnectionPool(host='chuck-dev.amperity.top', port=443): Max retries exceeded with url: /api/job/launch (Caused by ConnectTimeoutError(<urllib3.connection.HTTPSConnection object at 0x1088e2d50>, 'Connection to chuck-dev.amperity.top timed out. (connect timeout=None)'))

During handling of the above exception, another exception occurred:

Traceback (most recent call last):
  File "/Users/johnrush/repos/clamp-internal/src/clients/databricks.py", line 710, in fetch_amperity_job_init
    response = requests.post(api_url, headers=headers, json={})
  File "/Users/johnrush/repos/clamp-internal/.venv/lib/python3.13/site-packages/requests/api.py", line 115, in post
    return request("post", url, data=data, json=json, **kwargs)
  File "/Users/johnrush/repos/clamp-internal/.venv/lib/python3.13/site-packages/requests/api.py", line 59, in request
    return session.request(method=method, url=url, **kwargs)
           ~~~~~~~~~~~~~~~^^^^^^^^^^^^^^^^^^^^^^^^^^^^^^^^^^
  File "/Users/johnrush/repos/clamp-internal/.venv/lib/python3.13/site-packages/requests/sessions.py", line 589, in request
    resp = self.send(prep, **send_kwargs)
  File "/Users/johnrush/repos/clamp-internal/.venv/lib/python3.13/site-packages/requests/sessions.py", line 703, in send
    r = adapter.send(request, **kwargs)
  File "/Users/johnrush/repos/clamp-internal/.venv/lib/python3.13/site-packages/requests/adapters.py", line 688, in send
    raise ConnectTimeout(e, request=request)
requests.exceptions.ConnectTimeout: HTTPSConnectionPool(host='chuck-dev.amperity.top', port=443): Max retries exceeded with url: /api/job/launch (Caused by ConnectTimeoutError(<urllib3.connection.HTTPSConnection object at 0x1088e2d50>, 'Connection to chuck-dev.amperity.top timed out. (connect timeout=None)'))

During handling of the above exception, another exception occurred:

Traceback (most recent call last):
  File "/Users/johnrush/repos/clamp-internal/src/commands/stitch_tools.py", line 130, in _helper_setup_stitch_logic
    init_script_data = client.fetch_amperity_job_init(
        "https://chuck-dev.amperity.top/api/job/launch", amperity_token
    )
  File "/Users/johnrush/repos/clamp-internal/src/clients/databricks.py", line 718, in fetch_amperity_job_init
    raise ConnectionError(f"Connection error occurred: {e}")
ConnectionError: Connection error occurred: HTTPSConnectionPool(host='chuck-dev.amperity.top', port=443): Max retries exceeded with url: /api/job/launch (Caused by ConnectTimeoutError(<urllib3.connection.HTTPSConnection object at 0x1088e2d50>, 'Connection to chuck-dev.amperity.top timed out. (connect timeout=None)'))
2025-05-27 11:30:44,778 - ERROR - HTTP error: 404 Client Error: Not Found for url: https://dbc-df998298-4c7e.cloud.databricks.com/api/2.1/unity-catalog/tables?catalog_name=chuck_integration_test_6617&schema_name=bronze&omit_columns=true, Response: {"error_code":"CATALOG_DOES_NOT_EXIST","message":"Catalog 'chuck_integration_test_6617' does not exist.","details":[{"@type":"type.googleapis.com/google.rpc.ErrorInfo","reason":"RESOURCE_DOES_NOT_EXIST","domain":"unity-catalog.databricks.com","metadata":{"resourceType":"Catalog","resourceIdentifier":"chuck_integration_test_6617"}},{"@type":"type.googleapis.com/google.rpc.RequestInfo","request_id":"2850e8fa-cd55-4ee5-9aaa-ab7fb26f241d","serving_data":""}]}
2025-05-27 11:31:07,534 - ERROR - HTTP error: 404 Client Error: Not Found for url: https://dbc-df998298-4c7e.cloud.databricks.com/api/2.1/unity-catalog/tables?catalog_name=chuck_integration_test_6617&schema_name=bronze&omit_columns=true, Response: {"error_code":"CATALOG_DOES_NOT_EXIST","message":"Catalog 'chuck_integration_test_6617' does not exist.","details":[{"@type":"type.googleapis.com/google.rpc.ErrorInfo","reason":"RESOURCE_DOES_NOT_EXIST","domain":"unity-catalog.databricks.com","metadata":{"resourceType":"Catalog","resourceIdentifier":"chuck_integration_test_6617"}},{"@type":"type.googleapis.com/google.rpc.RequestInfo","request_id":"772fe466-1726-44fc-8256-4a77c1ffb15e","serving_data":""}]}
2025-05-27 11:31:28,405 - INFO - Starting PII Scan for 8 tables in amperity_marketplace.bronze.
2025-05-27 11:31:47,080 - INFO - Stitch config written to /Volumes/amperity_marketplace/bronze/chuck/stitch-2025-05-27_11-31.json
2025-05-27 11:31:47,214 - ERROR - HTTP error: 401 Client Error: Unauthorized for url: https://chuck-dev.amperity.top/api/job/launch, Response: {"status":401,"message":"Invalid authentication: Failed to decode token string"}

2025-05-27 11:31:47,214 - ERROR - Error fetching Amperity init script: HTTP error occurred: 401 Client Error: Unauthorized for url: https://chuck-dev.amperity.top/api/job/launch, Response: {"status":401,"message":"Invalid authentication: Failed to decode token string"}
Traceback (most recent call last):
  File "/Users/johnrush/repos/clamp-internal/src/clients/databricks.py", line 711, in fetch_amperity_job_init
    response.raise_for_status()
    ~~~~~~~~~~~~~~~~~~~~~~~~~^^
  File "/Users/johnrush/repos/clamp-internal/.venv/lib/python3.13/site-packages/requests/models.py", line 1024, in raise_for_status
    raise HTTPError(http_error_msg, response=self)
requests.exceptions.HTTPError: 401 Client Error: Unauthorized for url: https://chuck-dev.amperity.top/api/job/launch

During handling of the above exception, another exception occurred:

Traceback (most recent call last):
  File "/Users/johnrush/repos/clamp-internal/src/commands/stitch_tools.py", line 130, in _helper_setup_stitch_logic
    init_script_data = client.fetch_amperity_job_init(
        "https://chuck-dev.amperity.top/api/job/launch", amperity_token
    )
  File "/Users/johnrush/repos/clamp-internal/src/clients/databricks.py", line 715, in fetch_amperity_job_init
    raise ValueError(f"HTTP error occurred: {e}, Response: {response.text}")
ValueError: HTTP error occurred: 401 Client Error: Unauthorized for url: https://chuck-dev.amperity.top/api/job/launch, Response: {"status":401,"message":"Invalid authentication: Failed to decode token string"}

2025-05-27 11:31:59,590 - INFO - setup_wizard: handle_command called with interactive_input='None', kwargs={}
2025-05-27 11:32:05,770 - INFO - Amperity token cleared
2025-05-27 11:32:18,900 - INFO - Starting PII Scan for 8 tables in amperity_marketplace.bronze.
2025-05-27 11:32:37,893 - INFO - Stitch config written to /Volumes/amperity_marketplace/bronze/chuck/stitch-2025-05-27_11-32.json
2025-05-27 11:32:38,795 - INFO - Cluster init script written to /Volumes/amperity_marketplace/bronze/chuck/cluster_init.sh
2025-05-27 11:34:52,786 - INFO - Amperity token cleared
