2025-06-05 14:16:17,697 - DEBUG - Logging initialized. Writing to /Users/johnrush/repos/chuck-data/log/sessions/2025-06-05_14-16-17.log
2025-06-05 14:16:17,701 - DEBUG - HTTP error: HTTP 401, Response: {"status":401,"message":"Unauthorized"}
2025-06-05 14:16:17,703 - DEBUG - GET request to: https://test-workspace.cloud.databricks.com/test-endpoint
2025-06-05 14:16:17,703 - DEBUG - Connection error: Connection failed
2025-06-05 14:16:17,704 - DEBUG - GET request to: https://test-workspace.cloud.databricks.com/test-endpoint
2025-06-05 14:16:17,704 - DEBUG - HTTP error: HTTP 404, Response: Not Found
2025-06-05 14:16:17,705 - DEBUG - GET request to: https://test-workspace.cloud.databricks.com/test-endpoint
2025-06-05 14:16:17,707 - DEBUG - POST request to: https://test-workspace.cloud.databricks.com/test-endpoint
2025-06-05 14:16:17,707 - DEBUG - Connection error: Connection failed
2025-06-05 14:16:17,708 - DEBUG - POST request to: https://test-workspace.cloud.databricks.com/test-endpoint
2025-06-05 14:16:17,708 - DEBUG - HTTP error: HTTP 400, Response: Bad Request
2025-06-05 14:16:17,710 - DEBUG - POST request to: https://test-workspace.cloud.databricks.com/test-endpoint
2025-06-05 14:16:17,714 - DEBUG - Saved configuration to /var/folders/3f/2n5sjdw50vj9gfnrxjbptj4c0000gn/T/tmpg8aprapm/test_config.json
2025-06-05 14:16:17,714 - DEBUG - Loaded configuration from /var/folders/3f/2n5sjdw50vj9gfnrxjbptj4c0000gn/T/tmpg8aprapm/test_config.json
2025-06-05 14:16:17,715 - DEBUG - Loaded configuration from /var/folders/3f/2n5sjdw50vj9gfnrxjbptj4c0000gn/T/tmpg8aprapm/test_config.json
2025-06-05 14:16:17,715 - DEBUG - Saved configuration to /var/folders/3f/2n5sjdw50vj9gfnrxjbptj4c0000gn/T/tmpg8aprapm/test_config.json
2025-06-05 14:16:17,715 - DEBUG - Loaded configuration from /var/folders/3f/2n5sjdw50vj9gfnrxjbptj4c0000gn/T/tmpg8aprapm/test_config.json
2025-06-05 14:16:17,716 - DEBUG - Saved configuration to /var/folders/3f/2n5sjdw50vj9gfnrxjbptj4c0000gn/T/tmpg8aprapm/test_config.json
2025-06-05 14:16:17,716 - DEBUG - Loaded configuration from /var/folders/3f/2n5sjdw50vj9gfnrxjbptj4c0000gn/T/tmpg8aprapm/test_config.json
2025-06-05 14:16:17,716 - DEBUG - Saved configuration to /var/folders/3f/2n5sjdw50vj9gfnrxjbptj4c0000gn/T/tmpg8aprapm/test_config.json
2025-06-05 14:16:17,716 - DEBUG - Loaded configuration from /var/folders/3f/2n5sjdw50vj9gfnrxjbptj4c0000gn/T/tmpg8aprapm/test_config.json
2025-06-05 14:16:17,717 - DEBUG - Saved configuration to /var/folders/3f/2n5sjdw50vj9gfnrxjbptj4c0000gn/T/tmpg8aprapm/test_config.json
2025-06-05 14:16:17,717 - DEBUG - Loaded configuration from /var/folders/3f/2n5sjdw50vj9gfnrxjbptj4c0000gn/T/tmpg8aprapm/test_config.json
2025-06-05 14:16:17,717 - DEBUG - Loaded configuration from /var/folders/3f/2n5sjdw50vj9gfnrxjbptj4c0000gn/T/tmpg8aprapm/test_config.json
2025-06-05 14:16:17,717 - DEBUG - Loaded configuration from /var/folders/3f/2n5sjdw50vj9gfnrxjbptj4c0000gn/T/tmpg8aprapm/test_config.json
2025-06-05 14:16:17,718 - DEBUG - Loaded configuration from /var/folders/3f/2n5sjdw50vj9gfnrxjbptj4c0000gn/T/tmpg8aprapm/test_config.json
2025-06-05 14:16:17,718 - DEBUG - Loaded configuration from /var/folders/3f/2n5sjdw50vj9gfnrxjbptj4c0000gn/T/tmpg8aprapm/test_config.json
2025-06-05 14:16:17,720 - DEBUG - Saved configuration to /var/folders/3f/2n5sjdw50vj9gfnrxjbptj4c0000gn/T/tmp0ghhy9hq/test_config.json
2025-06-05 14:16:17,720 - DEBUG - Loaded configuration from /var/folders/3f/2n5sjdw50vj9gfnrxjbptj4c0000gn/T/tmp0ghhy9hq/test_config.json
2025-06-05 14:16:17,722 - DEBUG - Saved configuration to /var/folders/3f/2n5sjdw50vj9gfnrxjbptj4c0000gn/T/tmpgdfh75o_/test_config.json
2025-06-05 14:16:17,722 - DEBUG - Loaded configuration from /var/folders/3f/2n5sjdw50vj9gfnrxjbptj4c0000gn/T/tmpgdfh75o_/test_config.json
2025-06-05 14:16:17,724 - DEBUG - Saved configuration to /var/folders/3f/2n5sjdw50vj9gfnrxjbptj4c0000gn/T/tmp6i7d059q/test_config.json
2025-06-05 14:16:17,724 - DEBUG - Loaded configuration from /var/folders/3f/2n5sjdw50vj9gfnrxjbptj4c0000gn/T/tmp6i7d059q/test_config.json
2025-06-05 14:16:17,724 - DEBUG - Loaded configuration from /var/folders/3f/2n5sjdw50vj9gfnrxjbptj4c0000gn/T/tmp6i7d059q/test_config.json
2025-06-05 14:16:17,725 - DEBUG - Saved configuration to /var/folders/3f/2n5sjdw50vj9gfnrxjbptj4c0000gn/T/tmp6i7d059q/test_config.json
2025-06-05 14:16:17,725 - DEBUG - Loaded configuration from /var/folders/3f/2n5sjdw50vj9gfnrxjbptj4c0000gn/T/tmp6i7d059q/test_config.json
2025-06-05 14:16:17,725 - DEBUG - Loaded configuration from /var/folders/3f/2n5sjdw50vj9gfnrxjbptj4c0000gn/T/tmp6i7d059q/test_config.json
2025-06-05 14:16:17,728 - DEBUG - Saved configuration to /var/folders/3f/2n5sjdw50vj9gfnrxjbptj4c0000gn/T/tmp9920oqhr/test_config.json
2025-06-05 14:16:17,728 - DEBUG - Loaded configuration from /var/folders/3f/2n5sjdw50vj9gfnrxjbptj4c0000gn/T/tmp9920oqhr/test_config.json
2025-06-05 14:16:17,729 - DEBUG - Loaded configuration from /var/folders/3f/2n5sjdw50vj9gfnrxjbptj4c0000gn/T/tmp9920oqhr/test_config.json
2025-06-05 14:16:17,729 - DEBUG - Saved configuration to /var/folders/3f/2n5sjdw50vj9gfnrxjbptj4c0000gn/T/tmp9920oqhr/test_config.json
2025-06-05 14:16:17,729 - DEBUG - Loaded configuration from /var/folders/3f/2n5sjdw50vj9gfnrxjbptj4c0000gn/T/tmp9920oqhr/test_config.json
2025-06-05 14:16:17,729 - DEBUG - Saved configuration to /var/folders/3f/2n5sjdw50vj9gfnrxjbptj4c0000gn/T/tmp9920oqhr/test_config.json
2025-06-05 14:16:17,730 - DEBUG - Loaded configuration from /var/folders/3f/2n5sjdw50vj9gfnrxjbptj4c0000gn/T/tmp9920oqhr/test_config.json
2025-06-05 14:16:17,730 - DEBUG - Saved configuration to /var/folders/3f/2n5sjdw50vj9gfnrxjbptj4c0000gn/T/tmp9920oqhr/test_config.json
2025-06-05 14:16:17,730 - DEBUG - Loaded configuration from /var/folders/3f/2n5sjdw50vj9gfnrxjbptj4c0000gn/T/tmp9920oqhr/test_config.json
2025-06-05 14:16:17,730 - DEBUG - Saved configuration to /var/folders/3f/2n5sjdw50vj9gfnrxjbptj4c0000gn/T/tmp9920oqhr/test_config.json
2025-06-05 14:16:17,731 - DEBUG - Loaded configuration from /var/folders/3f/2n5sjdw50vj9gfnrxjbptj4c0000gn/T/tmp9920oqhr/test_config.json
2025-06-05 14:16:17,731 - DEBUG - Using workspace_url from environment variable CHUCK_WORKSPACE_URL
2025-06-05 14:16:17,731 - DEBUG - Using active_model from environment variable CHUCK_ACTIVE_MODEL
2025-06-05 14:16:17,731 - DEBUG - Using warehouse_id from environment variable CHUCK_WAREHOUSE_ID
2025-06-05 14:16:17,731 - DEBUG - Using active_catalog from environment variable CHUCK_ACTIVE_CATALOG
2025-06-05 14:16:17,731 - DEBUG - Using active_schema from environment variable CHUCK_ACTIVE_SCHEMA
2025-06-05 14:16:17,731 - DEBUG - Using usage_tracking_consent from environment variable CHUCK_USAGE_TRACKING_CONSENT
2025-06-05 14:16:17,731 - DEBUG - Loaded configuration from /var/folders/3f/2n5sjdw50vj9gfnrxjbptj4c0000gn/T/tmp9920oqhr/test_config.json
2025-06-05 14:16:17,733 - DEBUG - Saved configuration to /var/folders/3f/2n5sjdw50vj9gfnrxjbptj4c0000gn/T/tmppzdf686c/test_config.json
2025-06-05 14:16:17,733 - DEBUG - Loaded configuration from /var/folders/3f/2n5sjdw50vj9gfnrxjbptj4c0000gn/T/tmppzdf686c/test_config.json
2025-06-05 14:16:17,733 - DEBUG - Loaded configuration from /var/folders/3f/2n5sjdw50vj9gfnrxjbptj4c0000gn/T/tmppzdf686c/test_config.json
2025-06-05 14:16:17,733 - WARNING - Invalid workspace_url provided, using default instead
2025-06-05 14:16:17,734 - DEBUG - Saved configuration to /var/folders/3f/2n5sjdw50vj9gfnrxjbptj4c0000gn/T/tmppzdf686c/test_config.json
2025-06-05 14:16:17,734 - DEBUG - Loaded configuration from /var/folders/3f/2n5sjdw50vj9gfnrxjbptj4c0000gn/T/tmppzdf686c/test_config.json
2025-06-05 14:16:17,734 - DEBUG - Loaded configuration from /var/folders/3f/2n5sjdw50vj9gfnrxjbptj4c0000gn/T/tmppzdf686c/test_config.json
2025-06-05 14:16:17,734 - DEBUG - Saved configuration to /var/folders/3f/2n5sjdw50vj9gfnrxjbptj4c0000gn/T/tmppzdf686c/test_config.json
2025-06-05 14:16:17,735 - DEBUG - Loaded configuration from /var/folders/3f/2n5sjdw50vj9gfnrxjbptj4c0000gn/T/tmppzdf686c/test_config.json
2025-06-05 14:16:17,736 - DEBUG - Using workspace_url from environment variable CHUCK_WORKSPACE_URL
2025-06-05 14:16:17,736 - DEBUG - Using workspace_url from environment variable CHUCK_WORKSPACE_URL
2025-06-05 14:16:17,736 - DEBUG - Using active_model from environment variable CHUCK_ACTIVE_MODEL
2025-06-05 14:16:17,736 - DEBUG - Using amperity_token from environment variable CHUCK_AMPERITY_TOKEN
2025-06-05 14:16:17,736 - DEBUG - Using databricks_token from environment variable CHUCK_DATABRICKS_TOKEN
2025-06-05 14:16:17,737 - DEBUG - Saved configuration to /var/folders/3f/2n5sjdw50vj9gfnrxjbptj4c0000gn/T/tmpk1ps7u5j/test_config.json
2025-06-05 14:16:17,737 - DEBUG - Loaded configuration from /var/folders/3f/2n5sjdw50vj9gfnrxjbptj4c0000gn/T/tmpk1ps7u5j/test_config.json
2025-06-05 14:16:17,739 - DEBUG - Saved configuration to /var/folders/3f/2n5sjdw50vj9gfnrxjbptj4c0000gn/T/tmpz2bma2h4/test_config.json
2025-06-05 14:16:17,752 - DEBUG - GET request to: https://adb-3856707039489412.12.azuredatabricks.net/test-endpoint
2025-06-05 14:16:17,757 - DEBUG - GET request to: https://test-workspace.cloud.databricks.com/test-endpoint
2025-06-05 14:16:17,757 - DEBUG - Connection error: Connection failed
2025-06-05 14:16:17,758 - DEBUG - GET request to: https://test-workspace.cloud.databricks.com/test-endpoint
2025-06-05 14:16:17,758 - DEBUG - HTTP error: HTTP 404, Response: Not Found
2025-06-05 14:16:17,760 - WARNING - Model 'nonexistent-model' not found
2025-06-05 14:16:17,761 - DEBUG - GET request to: https://test-workspace.cloud.databricks.com/test-endpoint
2025-06-05 14:16:17,765 - CRITICAL - Warehouses response: {'warehouses': [{'id': '123'}, {'id': '456'}]}
2025-06-05 14:16:17,767 - DEBUG - POST request to: https://test-workspace.cloud.databricks.com/test-endpoint
2025-06-05 14:16:17,767 - DEBUG - Connection error: Connection failed
2025-06-05 14:16:17,768 - DEBUG - POST request to: https://test-workspace.cloud.databricks.com/test-endpoint
2025-06-05 14:16:17,768 - DEBUG - HTTP error: HTTP 400, Response: Bad Request
2025-06-05 14:16:17,769 - DEBUG - POST request to: https://test-workspace.cloud.databricks.com/test-endpoint
2025-06-05 14:16:17,771 - DEBUG - File upload request to: https://test-workspace.cloud.databricks.com/api/2.0/fs/files/test/path.txt
2025-06-05 14:16:17,773 - DEBUG - File upload request to: https://test-workspace.cloud.databricks.com/api/2.0/fs/files/test/path.txt
2025-06-05 14:16:17,775 - DEBUG - Token validation failed: Token validation failed
2025-06-05 14:16:17,777 - DEBUG - Saved configuration to /tmp/.test_chuck_integration_config.json
2025-06-05 14:16:17,778 - DEBUG - Saved configuration to /tmp/.test_chuck_integration_config.json
2025-06-05 14:16:17,780 - DEBUG - Saved configuration to /tmp/.test_chuck_integration_config.json
2025-06-05 14:16:17,780 - DEBUG - Saved configuration to /tmp/.test_chuck_integration_config.json
2025-06-05 14:16:17,782 - DEBUG - Saved configuration to /tmp/.test_chuck_integration_config.json
2025-06-05 14:16:17,782 - DEBUG - Saved configuration to /tmp/.test_chuck_integration_config.json
2025-06-05 14:16:17,787 - DEBUG - Sending metric: {"event": "USAGE", "prompt": "test prompt"}...
2025-06-05 14:16:17,787 - DEBUG - Error sending metrics: Test exception
Traceback (most recent call last):
  File "/Users/johnrush/repos/chuck-data/src/metrics_collector.py", line 123, in send_metric
    return self._client.submit_metrics(payload, token)
           ^^^^^^^^^^^^^^^^^^^^^^^^^^^^^^^^^^^^^^^^^^^
  File "/Users/johnrush/repos/chuck-data/tests/fixtures.py", line 60, in submit_metrics
    raise Exception("Test exception")
Exception: Test exception
2025-06-05 14:16:17,790 - DEBUG - Sending metric: {"event": "USAGE", "prompt": "test prompt"}...
2025-06-05 14:16:17,792 - DEBUG - Cannot send metrics - no authentication token available
2025-06-05 14:16:17,793 - DEBUG - Sending metric: {"event": "USAGE", "prompt": "test prompt"}...
2025-06-05 14:16:17,797 - DEBUG - Metrics tracking skipped - user has not provided consent
2025-06-05 14:16:17,800 - ERROR - Connection error when getting model: Connection failed
2025-06-05 14:16:17,801 - ERROR - Failed to get model: HTTP error occurred: 500 Internal Server Error
2025-06-05 14:16:17,805 - ERROR - Connection error when listing models: Connection failed
2025-06-05 14:16:17,807 - ERROR - Failed to list models: HTTP error occurred: 404 Not Found
2025-06-05 14:16:17,860 - ERROR - Error executing handler for command 'test_command': Command failed
Traceback (most recent call last):
  File "/Users/johnrush/repos/chuck-data/src/service.py", line 395, in execute_command
    result: CommandResult = command_def.handler(
                            ^^^^^^^^^^^^^^^^^^^^
  File "/usr/local/Cellar/python@3.11/3.11.4_1/Frameworks/Python.framework/Versions/3.11/lib/python3.11/unittest/mock.py", line 1124, in __call__
    return self._mock_call(*args, **kwargs)
           ^^^^^^^^^^^^^^^^^^^^^^^^^^^^^^^^
  File "/usr/local/Cellar/python@3.11/3.11.4_1/Frameworks/Python.framework/Versions/3.11/lib/python3.11/unittest/mock.py", line 1128, in _mock_call
    return self._execute_mock_call(*args, **kwargs)
           ^^^^^^^^^^^^^^^^^^^^^^^^^^^^^^^^^^^^^^^^
  File "/usr/local/Cellar/python@3.11/3.11.4_1/Frameworks/Python.framework/Versions/3.11/lib/python3.11/unittest/mock.py", line 1183, in _execute_mock_call
    raise effect
Exception: Command failed
2025-06-05 14:16:17,901 - DEBUG - Executing SQL: SELECT * INVALID SQL
2025-06-05 14:16:17,902 - DEBUG - Executing SQL: SELECT * INVALID SQL
2025-06-05 14:16:17,904 - DEBUG - Executing SQL: SELECT * FROM table
2025-06-05 14:16:17,905 - DEBUG - Executing SQL: SELECT * FROM table
2025-06-05 14:16:17,906 - DEBUG - Executing SQL: SELECT * FROM table
2025-06-05 14:16:17,907 - DEBUG - Executing SQL: SELECT * FROM table
2025-06-05 14:16:17,913 - ERROR - Authentication state polling received 401
2025-06-05 14:16:17,916 - ERROR - Error creating Stitch report: API Error
Traceback (most recent call last):
  File "/Users/johnrush/repos/chuck-data/src/commands/add_stitch_report.py", line 62, in handle_command
    result = client.create_stitch_notebook(table_path, custom_name)
             ^^^^^^^^^^^^^^^^^^^^^^^^^^^^^^^^^^^^^^^^^^^^^^^^^^^^^^
  File "/Users/johnrush/repos/chuck-data/tests/fixtures.py", line 526, in create_stitch_notebook
    raise self._create_stitch_notebook_error
ValueError: API Error
2025-06-05 14:16:17,920 - ERROR - Agent error: Agent error
Traceback (most recent call last):
  File "/Users/johnrush/repos/chuck-data/src/commands/agent.py", line 79, in handle_command
    agent = AgentManager(client, tool_output_callback=tool_output_callback)
            ^^^^^^^^^^^^^^^^^^^^^^^^^^^^^^^^^^^^^^^^^^^^^^^^^^^^^^^^^^^^^^^
  File "/usr/local/Cellar/python@3.11/3.11.4_1/Frameworks/Python.framework/Versions/3.11/lib/python3.11/unittest/mock.py", line 1124, in __call__
    return self._mock_call(*args, **kwargs)
           ^^^^^^^^^^^^^^^^^^^^^^^^^^^^^^^^
  File "/usr/local/Cellar/python@3.11/3.11.4_1/Frameworks/Python.framework/Versions/3.11/lib/python3.11/unittest/mock.py", line 1128, in _mock_call
    return self._execute_mock_call(*args, **kwargs)
           ^^^^^^^^^^^^^^^^^^^^^^^^^^^^^^^^^^^^^^^^
  File "/usr/local/Cellar/python@3.11/3.11.4_1/Frameworks/Python.framework/Versions/3.11/lib/python3.11/unittest/mock.py", line 1183, in _execute_mock_call
    raise effect
Exception: Agent error
2025-06-05 14:16:17,922 - DEBUG - Sending metric: {"event": "USAGE", "configuration": {"workspace_url": "https://dbc-df998298-4c7e.cloud.databricks.co...
2025-06-05 14:16:17,955 - DEBUG - Starting new HTTPS connection (1): chuck.amperity.com:443
2025-06-05 14:16:18,033 - DEBUG - https://chuck.amperity.com:443 "POST /api/usage HTTP/1.1" 204 0
2025-06-05 14:16:18,033 - DEBUG - Failed to send metrics: 204 - 
2025-06-05 14:16:18,036 - DEBUG - Sending metric: {"event": "USAGE", "configuration": {"workspace_url": "https://dbc-df998298-4c7e.cloud.databricks.co...
2025-06-05 14:16:18,038 - DEBUG - Starting new HTTPS connection (1): chuck.amperity.com:443
2025-06-05 14:16:18,104 - DEBUG - https://chuck.amperity.com:443 "POST /api/usage HTTP/1.1" 204 0
2025-06-05 14:16:18,104 - DEBUG - Failed to send metrics: 204 - 
2025-06-05 14:16:18,111 - DEBUG - Sending metric: {"event": "USAGE", "configuration": {"workspace_url": "https://dbc-df998298-4c7e.cloud.databricks.co...
2025-06-05 14:16:18,113 - DEBUG - Starting new HTTPS connection (1): chuck.amperity.com:443
2025-06-05 14:16:18,190 - DEBUG - https://chuck.amperity.com:443 "POST /api/usage HTTP/1.1" 204 0
2025-06-05 14:16:18,190 - DEBUG - Failed to send metrics: 204 - 
2025-06-05 14:16:18,193 - DEBUG - Sending metric: {"event": "USAGE", "configuration": {"workspace_url": "https://dbc-df998298-4c7e.cloud.databricks.co...
2025-06-05 14:16:18,195 - DEBUG - Starting new HTTPS connection (1): chuck.amperity.com:443
2025-06-05 14:16:18,268 - DEBUG - https://chuck.amperity.com:443 "POST /api/usage HTTP/1.1" 204 0
2025-06-05 14:16:18,269 - DEBUG - Failed to send metrics: 204 - 
2025-06-05 14:16:18,271 - DEBUG - Sending metric: {"event": "USAGE", "configuration": {"workspace_url": "https://dbc-df998298-4c7e.cloud.databricks.co...
2025-06-05 14:16:18,274 - DEBUG - Starting new HTTPS connection (1): chuck.amperity.com:443
2025-06-05 14:16:18,336 - DEBUG - https://chuck.amperity.com:443 "POST /api/usage HTTP/1.1" 204 0
2025-06-05 14:16:18,336 - DEBUG - Failed to send metrics: 204 - 
2025-06-05 14:16:18,342 - INFO - Databricks token set successfully
2025-06-05 14:16:18,343 - INFO - Databricks token cleared
2025-06-05 14:16:18,343 - INFO - Amperity token cleared
2025-06-05 14:16:18,344 - INFO - Amperity token cleared
2025-06-05 14:16:18,345 - INFO - Databricks token cleared
2025-06-05 14:16:18,346 - INFO - Amperity token cleared
2025-06-05 14:16:18,355 - DEBUG - Bug report submitted successfully
2025-06-05 14:16:18,404 - ERROR - Error submitting bug report: Network error
Traceback (most recent call last):
  File "/Users/johnrush/repos/chuck-data/src/commands/bug.py", line 72, in handle_command
    success, message = amperity_client.submit_bug_report(payload, amperity_token)
                       ^^^^^^^^^^^^^^^^^^^^^^^^^^^^^^^^^^^^^^^^^^^^^^^^^^^^^^^^^^
  File "/Users/johnrush/repos/chuck-data/tests/commands/test_bug.py", line 115, in submit_bug_report
    raise Exception("Network error")
Exception: Network error
2025-06-05 14:16:18,406 - DEBUG - Loaded configuration from /var/folders/3f/2n5sjdw50vj9gfnrxjbptj4c0000gn/T/tmp6rh5fo5n.json
2025-06-05 14:16:18,408 - DEBUG - Loaded configuration from /var/folders/3f/2n5sjdw50vj9gfnrxjbptj4c0000gn/T/tmpypaaav8y.json
2025-06-05 14:16:18,415 - DEBUG - Bug report submitted successfully
2025-06-05 14:16:18,416 - ERROR - Error saving config: [Errno 30] Read-only file system: '/invalid'
2025-06-05 14:16:18,417 - DEBUG - Saved configuration to /var/folders/3f/2n5sjdw50vj9gfnrxjbptj4c0000gn/T/tmp51l39awr/test_config.json
2025-06-05 14:16:18,419 - DEBUG - Saved configuration to /var/folders/3f/2n5sjdw50vj9gfnrxjbptj4c0000gn/T/tmp_vzg0qjp/test_config.json
2025-06-05 14:16:18,419 - DEBUG - Loaded configuration from /var/folders/3f/2n5sjdw50vj9gfnrxjbptj4c0000gn/T/tmp_vzg0qjp/test_config.json
2025-06-05 14:16:18,422 - DEBUG - Saved configuration to /var/folders/3f/2n5sjdw50vj9gfnrxjbptj4c0000gn/T/tmpahb3r0lz/test_config.json
2025-06-05 14:16:18,422 - DEBUG - Loaded configuration from /var/folders/3f/2n5sjdw50vj9gfnrxjbptj4c0000gn/T/tmpahb3r0lz/test_config.json
2025-06-05 14:16:18,424 - INFO - Cluster init script uploaded successfully to /Volumes/main/default/chuck/cluster_init-2025-06-02_14-30.sh
2025-06-05 14:16:18,429 - DEBUG - Volume 'chuck' not found in main.default. Attempting to create.
2025-06-05 14:16:18,429 - DEBUG - Volume 'chuck' created successfully.
2025-06-05 14:16:18,429 - INFO - Cluster init script uploaded successfully to /Volumes/main/default/chuck/cluster_init-2025-06-02_14-30.sh
2025-06-05 14:16:18,432 - DEBUG - Volume 'chuck' not found in main.default. Attempting to create.
2025-06-05 14:16:18,432 - DEBUG - Volume 'chuck' created successfully.
2025-06-05 14:16:18,432 - INFO - Cluster init script uploaded successfully to /Volumes/main/default/chuck/cluster_init-2025-06-02_14-30.sh
2025-06-05 14:16:18,434 - DEBUG - Volume 'chuck' not found in main.default. Attempting to create.
2025-06-05 14:16:18,435 - DEBUG - Volume 'chuck' not found in main.default. Attempting to create.
2025-06-05 14:16:18,439 - INFO - Cluster init script uploaded successfully to /Volumes/test_catalog/test_schema/chuck/cluster_init-2025-12-31_23-59.sh
2025-06-05 14:16:18,441 - ERROR - Error generating help: Test error
Traceback (most recent call last):
  File "/Users/johnrush/repos/chuck-data/src/commands/help.py", line 27, in handle_command
    user_commands = get_user_commands()
                    ^^^^^^^^^^^^^^^^^^^
  File "/usr/local/Cellar/python@3.11/3.11.4_1/Frameworks/Python.framework/Versions/3.11/lib/python3.11/unittest/mock.py", line 1124, in __call__
    return self._mock_call(*args, **kwargs)
           ^^^^^^^^^^^^^^^^^^^^^^^^^^^^^^^^
  File "/usr/local/Cellar/python@3.11/3.11.4_1/Frameworks/Python.framework/Versions/3.11/lib/python3.11/unittest/mock.py", line 1128, in _mock_call
    return self._execute_mock_call(*args, **kwargs)
           ^^^^^^^^^^^^^^^^^^^^^^^^^^^^^^^^^^^^^^^^
  File "/usr/local/Cellar/python@3.11/3.11.4_1/Frameworks/Python.framework/Versions/3.11/lib/python3.11/unittest/mock.py", line 1183, in _execute_mock_call
    raise effect
Exception: Test error
2025-06-05 14:16:18,447 - ERROR - Failed to get job status for run '999999': Not Found
Traceback (most recent call last):
  File "/Users/johnrush/repos/chuck-data/src/commands/jobs.py", line 67, in handle_job_status
    data = client.get_job_run_status(run_id_str)
           ^^^^^^^^^^^^^^^^^^^^^^^^^^^^^^^^^^^^^
  File "/Users/johnrush/repos/chuck-data/tests/commands/test_jobs.py", line 119, in get_job_run_status
    raise Exception("Not Found")
Exception: Not Found
2025-06-05 14:16:18,452 - ERROR - Failed to submit job: Bad Request
Traceback (most recent call last):
  File "/Users/johnrush/repos/chuck-data/src/commands/jobs.py", line 32, in handle_launch_job
    run_data = client.submit_job_run(
               ^^^^^^^^^^^^^^^^^^^^^^
  File "/Users/johnrush/repos/chuck-data/tests/commands/test_jobs.py", line 70, in submit_job_run
    raise Exception("Bad Request")
Exception: Bad Request
2025-06-05 14:16:18,456 - ERROR - Failed to launch job, no run_id: {}
2025-06-05 14:16:18,461 - ERROR - Error listing catalogs: API error
2025-06-05 14:16:18,467 - DEBUG - Saved configuration to /var/folders/3f/2n5sjdw50vj9gfnrxjbptj4c0000gn/T/tmp426n_gaj/test_config.json
2025-06-05 14:16:18,467 - DEBUG - Loaded configuration from /var/folders/3f/2n5sjdw50vj9gfnrxjbptj4c0000gn/T/tmp426n_gaj/test_config.json
2025-06-05 14:16:18,469 - DEBUG - Saved configuration to /var/folders/3f/2n5sjdw50vj9gfnrxjbptj4c0000gn/T/tmpg6wxom9u/test_config.json
2025-06-05 14:16:18,469 - DEBUG - Loaded configuration from /var/folders/3f/2n5sjdw50vj9gfnrxjbptj4c0000gn/T/tmpg6wxom9u/test_config.json
2025-06-05 14:16:18,472 - DEBUG - Saved configuration to /var/folders/3f/2n5sjdw50vj9gfnrxjbptj4c0000gn/T/tmp5g03qzx8/test_config.json
2025-06-05 14:16:18,472 - DEBUG - Loaded configuration from /var/folders/3f/2n5sjdw50vj9gfnrxjbptj4c0000gn/T/tmp5g03qzx8/test_config.json
2025-06-05 14:16:18,473 - ERROR - Failed to list models: API error
Traceback (most recent call last):
  File "/Users/johnrush/repos/chuck-data/src/commands/list_models.py", line 31, in handle_command
    models_list = list_models_api(client)
                  ^^^^^^^^^^^^^^^^^^^^^^^
  File "/Users/johnrush/repos/chuck-data/src/models.py", line 19, in list_models
    return client.list_models()
           ^^^^^^^^^^^^^^^^^^^^
  File "/Users/johnrush/repos/chuck-data/tests/commands/test_list_models.py", line 112, in list_models
    raise Exception("API error")
Exception: API error
2025-06-05 14:16:18,476 - ERROR - Error listing tables: API error
2025-06-05 14:16:18,479 - DEBUG - Saved configuration to /var/folders/3f/2n5sjdw50vj9gfnrxjbptj4c0000gn/T/tmpxt50smvp/test_config.json
2025-06-05 14:16:18,479 - DEBUG - Loaded configuration from /var/folders/3f/2n5sjdw50vj9gfnrxjbptj4c0000gn/T/tmpxt50smvp/test_config.json
2025-06-05 14:16:18,479 - DEBUG - Loaded configuration from /var/folders/3f/2n5sjdw50vj9gfnrxjbptj4c0000gn/T/tmpxt50smvp/test_config.json
2025-06-05 14:16:18,482 - DEBUG - Saved configuration to /var/folders/3f/2n5sjdw50vj9gfnrxjbptj4c0000gn/T/tmppdccec3q/test_config.json
2025-06-05 14:16:18,482 - DEBUG - Loaded configuration from /var/folders/3f/2n5sjdw50vj9gfnrxjbptj4c0000gn/T/tmppdccec3q/test_config.json
2025-06-05 14:16:18,482 - DEBUG - Saved configuration to /var/folders/3f/2n5sjdw50vj9gfnrxjbptj4c0000gn/T/tmppdccec3q/test_config.json
2025-06-05 14:16:18,482 - DEBUG - Loaded configuration from /var/folders/3f/2n5sjdw50vj9gfnrxjbptj4c0000gn/T/tmppdccec3q/test_config.json
2025-06-05 14:16:18,482 - DEBUG - Loaded configuration from /var/folders/3f/2n5sjdw50vj9gfnrxjbptj4c0000gn/T/tmppdccec3q/test_config.json
2025-06-05 14:16:18,485 - ERROR - Error fetching warehouses: API connection error
2025-06-05 14:16:18,491 - ERROR - Failed to set model 'claude-v1': API error
Traceback (most recent call last):
  File "/Users/johnrush/repos/chuck-data/src/commands/model_selection.py", line 28, in handle_command
    models_list = list_models_api(client)
                  ^^^^^^^^^^^^^^^^^^^^^^^
  File "/Users/johnrush/repos/chuck-data/src/models.py", line 19, in list_models
    return client.list_models()
           ^^^^^^^^^^^^^^^^^^^^
  File "/Users/johnrush/repos/chuck-data/tests/commands/test_model_selection.py", line 79, in list_models
    raise Exception("API error")
Exception: API error
2025-06-05 14:16:18,493 - DEBUG - Saved configuration to /var/folders/3f/2n5sjdw50vj9gfnrxjbptj4c0000gn/T/tmpehyxzrws/test_config.json
2025-06-05 14:16:18,493 - DEBUG - Loaded configuration from /var/folders/3f/2n5sjdw50vj9gfnrxjbptj4c0000gn/T/tmpehyxzrws/test_config.json
2025-06-05 14:16:18,494 - DEBUG - Saved configuration to /var/folders/3f/2n5sjdw50vj9gfnrxjbptj4c0000gn/T/tmpajy_hj_j/test_config.json
2025-06-05 14:16:18,495 - DEBUG - Loaded configuration from /var/folders/3f/2n5sjdw50vj9gfnrxjbptj4c0000gn/T/tmpajy_hj_j/test_config.json
2025-06-05 14:16:18,496 - DEBUG - Saved configuration to /var/folders/3f/2n5sjdw50vj9gfnrxjbptj4c0000gn/T/tmp0yo0ewl_/test_config.json
2025-06-05 14:16:18,496 - DEBUG - Loaded configuration from /var/folders/3f/2n5sjdw50vj9gfnrxjbptj4c0000gn/T/tmp0yo0ewl_/test_config.json
2025-06-05 14:16:18,499 - DEBUG - Saved configuration to /var/folders/3f/2n5sjdw50vj9gfnrxjbptj4c0000gn/T/tmpg84i5ep_/test_config.json
2025-06-05 14:16:18,499 - DEBUG - Loaded configuration from /var/folders/3f/2n5sjdw50vj9gfnrxjbptj4c0000gn/T/tmpg84i5ep_/test_config.json
2025-06-05 14:16:18,504 - INFO - Starting PII Scan for 2 tables in test_cat.test_schema.
2025-06-05 14:16:18,510 - ERROR - Bulk PII scan error: LLM client error
Traceback (most recent call last):
  File "/Users/johnrush/repos/chuck-data/src/commands/scan_pii.py", line 46, in handle_command
    llm_client = LLMClient()
                 ^^^^^^^^^^^
  File "/usr/local/Cellar/python@3.11/3.11.4_1/Frameworks/Python.framework/Versions/3.11/lib/python3.11/unittest/mock.py", line 1124, in __call__
    return self._mock_call(*args, **kwargs)
           ^^^^^^^^^^^^^^^^^^^^^^^^^^^^^^^^
  File "/usr/local/Cellar/python@3.11/3.11.4_1/Frameworks/Python.framework/Versions/3.11/lib/python3.11/unittest/mock.py", line 1128, in _mock_call
    return self._execute_mock_call(*args, **kwargs)
           ^^^^^^^^^^^^^^^^^^^^^^^^^^^^^^^^^^^^^^^^
  File "/usr/local/Cellar/python@3.11/3.11.4_1/Frameworks/Python.framework/Versions/3.11/lib/python3.11/unittest/mock.py", line 1183, in _execute_mock_call
    raise effect
Exception: LLM client error
2025-06-05 14:16:18,516 - DEBUG - Saved configuration to /var/folders/3f/2n5sjdw50vj9gfnrxjbptj4c0000gn/T/tmppwsx57vm/test_config.json
2025-06-05 14:16:18,516 - DEBUG - Loaded configuration from /var/folders/3f/2n5sjdw50vj9gfnrxjbptj4c0000gn/T/tmppwsx57vm/test_config.json
2025-06-05 14:16:18,517 - DEBUG - Loaded configuration from /var/folders/3f/2n5sjdw50vj9gfnrxjbptj4c0000gn/T/tmppwsx57vm/test_config.json
2025-06-05 14:16:18,517 - DEBUG - Saved configuration to /var/folders/3f/2n5sjdw50vj9gfnrxjbptj4c0000gn/T/tmppwsx57vm/test_config.json
2025-06-05 14:16:18,518 - DEBUG - Saved configuration to /var/folders/3f/2n5sjdw50vj9gfnrxjbptj4c0000gn/T/tmpj3ii084o/test_config.json
2025-06-05 14:16:18,518 - DEBUG - Loaded configuration from /var/folders/3f/2n5sjdw50vj9gfnrxjbptj4c0000gn/T/tmpj3ii084o/test_config.json
2025-06-05 14:16:18,519 - DEBUG - Loaded configuration from /var/folders/3f/2n5sjdw50vj9gfnrxjbptj4c0000gn/T/tmpj3ii084o/test_config.json
2025-06-05 14:16:18,519 - DEBUG - Saved configuration to /var/folders/3f/2n5sjdw50vj9gfnrxjbptj4c0000gn/T/tmpj3ii084o/test_config.json
2025-06-05 14:16:18,519 - DEBUG - Loaded configuration from /var/folders/3f/2n5sjdw50vj9gfnrxjbptj4c0000gn/T/tmpj3ii084o/test_config.json
2025-06-05 14:16:18,520 - DEBUG - Saved configuration to /var/folders/3f/2n5sjdw50vj9gfnrxjbptj4c0000gn/T/tmpiuth6u1y/test_config.json
2025-06-05 14:16:18,520 - DEBUG - Loaded configuration from /var/folders/3f/2n5sjdw50vj9gfnrxjbptj4c0000gn/T/tmpiuth6u1y/test_config.json
2025-06-05 14:16:18,520 - DEBUG - Loaded configuration from /var/folders/3f/2n5sjdw50vj9gfnrxjbptj4c0000gn/T/tmpiuth6u1y/test_config.json
2025-06-05 14:16:18,521 - DEBUG - Saved configuration to /var/folders/3f/2n5sjdw50vj9gfnrxjbptj4c0000gn/T/tmpiuth6u1y/test_config.json
2025-06-05 14:16:18,521 - DEBUG - Loaded configuration from /var/folders/3f/2n5sjdw50vj9gfnrxjbptj4c0000gn/T/tmpiuth6u1y/test_config.json
2025-06-05 14:16:18,525 - DEBUG - Sending metric: {"event": "USAGE", "configuration": {"workspace_url": "https://dbc-df998298-4c7e.cloud.databricks.co...
2025-06-05 14:16:18,528 - DEBUG - Starting new HTTPS connection (1): chuck.amperity.com:443
2025-06-05 14:16:18,602 - DEBUG - https://chuck.amperity.com:443 "POST /api/usage HTTP/1.1" 204 0
2025-06-05 14:16:18,603 - DEBUG - Failed to send metrics: 204 - 
2025-06-05 14:16:18,605 - ERROR - Stitch setup error: LLM client error
Traceback (most recent call last):
  File "/Users/johnrush/repos/chuck-data/src/commands/setup_stitch.py", line 111, in handle_command
    return _phase_1_prepare_config(
           ^^^^^^^^^^^^^^^^^^^^^^^^
  File "/Users/johnrush/repos/chuck-data/src/commands/setup_stitch.py", line 273, in _phase_1_prepare_config
    llm_client = LLMClient()
                 ^^^^^^^^^^^
  File "/usr/local/Cellar/python@3.11/3.11.4_1/Frameworks/Python.framework/Versions/3.11/lib/python3.11/unittest/mock.py", line 1124, in __call__
    return self._mock_call(*args, **kwargs)
           ^^^^^^^^^^^^^^^^^^^^^^^^^^^^^^^^
  File "/usr/local/Cellar/python@3.11/3.11.4_1/Frameworks/Python.framework/Versions/3.11/lib/python3.11/unittest/mock.py", line 1128, in _mock_call
    return self._execute_mock_call(*args, **kwargs)
           ^^^^^^^^^^^^^^^^^^^^^^^^^^^^^^^^^^^^^^^^
  File "/usr/local/Cellar/python@3.11/3.11.4_1/Frameworks/Python.framework/Versions/3.11/lib/python3.11/unittest/mock.py", line 1183, in _execute_mock_call
    raise effect
Exception: LLM client error
2025-06-05 14:16:18,613 - DEBUG - GET request to: https://.cloud.databricks.com/api/2.0/preview/scim/v2/Me
2025-06-05 14:16:18,614 - DEBUG - Connection error: URL has an invalid label.
2025-06-05 14:16:18,614 - DEBUG - Token validation failed: Connection error occurred: URL has an invalid label.
2025-06-05 14:16:18,617 - ERROR - Error validating token: Connection failed
2025-06-05 14:16:18,622 - DEBUG - GET request to: https://invalid-workspace.nonexistent.com.cloud.databricks.com/api/2.0/preview/scim/v2/Me
2025-06-05 14:16:18,624 - DEBUG - Starting new HTTPS connection (1): invalid-workspace.nonexistent.com.cloud.databricks.com:443
2025-06-05 14:16:18,625 - DEBUG - Connection error: HTTPSConnectionPool(host='invalid-workspace.nonexistent.com.cloud.databricks.com', port=443): Max retries exceeded with url: /api/2.0/preview/scim/v2/Me (Caused by NameResolutionError("<urllib3.connection.HTTPSConnection object at 0x111ef5350>: Failed to resolve 'invalid-workspace.nonexistent.com.cloud.databricks.com' ([Errno 8] nodename nor servname provided, or not known)"))
2025-06-05 14:16:18,625 - DEBUG - Token validation failed: Connection error occurred: HTTPSConnectionPool(host='invalid-workspace.nonexistent.com.cloud.databricks.com', port=443): Max retries exceeded with url: /api/2.0/preview/scim/v2/Me (Caused by NameResolutionError("<urllib3.connection.HTTPSConnection object at 0x111ef5350>: Failed to resolve 'invalid-workspace.nonexistent.com.cloud.databricks.com' ([Errno 8] nodename nor servname provided, or not known)"))
2025-06-05 14:16:18,720 - DEBUG - GET request to: https://invalid.nonexistent.com.cloud.databricks.com/api/2.0/preview/scim/v2/Me
2025-06-05 14:16:18,723 - DEBUG - Starting new HTTPS connection (1): invalid.nonexistent.com.cloud.databricks.com:443
2025-06-05 14:16:18,724 - DEBUG - Connection error: HTTPSConnectionPool(host='invalid.nonexistent.com.cloud.databricks.com', port=443): Max retries exceeded with url: /api/2.0/preview/scim/v2/Me (Caused by NameResolutionError("<urllib3.connection.HTTPSConnection object at 0x112147fd0>: Failed to resolve 'invalid.nonexistent.com.cloud.databricks.com' ([Errno 8] nodename nor servname provided, or not known)"))
2025-06-05 14:16:18,724 - DEBUG - Token validation failed: Connection error occurred: HTTPSConnectionPool(host='invalid.nonexistent.com.cloud.databricks.com', port=443): Max retries exceeded with url: /api/2.0/preview/scim/v2/Me (Caused by NameResolutionError("<urllib3.connection.HTTPSConnection object at 0x112147fd0>: Failed to resolve 'invalid.nonexistent.com.cloud.databricks.com' ([Errno 8] nodename nor servname provided, or not known)"))
2025-06-05 14:16:18,725 - ERROR - Error validating token: Validation failed
2025-06-05 14:16:18,844 - ERROR - Error validating token: Connection failed
2025-06-05 14:16:18,879 - ERROR - Error validating token: Network error with secret details
2025-06-05 14:16:18,921 - ERROR - Error validating token: Connection error: Failed to resolve 'workspace123.cloud.databricks.com'
2025-06-05 14:16:18,930 - ERROR - Error fetching Amperity init script: API Error
Traceback (most recent call last):
  File "/Users/johnrush/repos/chuck-data/src/commands/stitch_tools.py", line 179, in _helper_prepare_stitch_config
    init_script_data = client.fetch_amperity_job_init(amperity_token)
                       ^^^^^^^^^^^^^^^^^^^^^^^^^^^^^^^^^^^^^^^^^^^^^^
  File "/usr/local/Cellar/python@3.11/3.11.4_1/Frameworks/Python.framework/Versions/3.11/lib/python3.11/unittest/mock.py", line 1124, in __call__
    return self._mock_call(*args, **kwargs)
           ^^^^^^^^^^^^^^^^^^^^^^^^^^^^^^^^
  File "/usr/local/Cellar/python@3.11/3.11.4_1/Frameworks/Python.framework/Versions/3.11/lib/python3.11/unittest/mock.py", line 1128, in _mock_call
    return self._execute_mock_call(*args, **kwargs)
           ^^^^^^^^^^^^^^^^^^^^^^^^^^^^^^^^^^^^^^^^
  File "/usr/local/Cellar/python@3.11/3.11.4_1/Frameworks/Python.framework/Versions/3.11/lib/python3.11/unittest/mock.py", line 1183, in _execute_mock_call
    raise effect
Exception: API Error
2025-06-05 14:16:18,937 - DEBUG - Versioned cluster init script uploaded to /Volumes/test_catalog/test_schema/chuck/cluster_init-2025-06-02_14-30.sh
2025-06-05 14:16:18,938 - DEBUG - Versioned cluster init script uploaded to /Volumes/test_catalog/test_schema/chuck/cluster_init-2025-06-02_14-30.sh
2025-06-05 14:16:18,942 - DEBUG - Volume 'chuck' not found in test_catalog.test_schema. Attempting to create.
2025-06-05 14:16:18,951 - DEBUG - Saved configuration to /var/folders/3f/2n5sjdw50vj9gfnrxjbptj4c0000gn/T/tmpio77ewpv/test_config.json
2025-06-05 14:16:18,951 - DEBUG - Loaded configuration from /var/folders/3f/2n5sjdw50vj9gfnrxjbptj4c0000gn/T/tmpio77ewpv/test_config.json
2025-06-05 14:16:18,952 - DEBUG - Loaded configuration from /var/folders/3f/2n5sjdw50vj9gfnrxjbptj4c0000gn/T/tmpio77ewpv/test_config.json
2025-06-05 14:16:18,952 - DEBUG - Loaded configuration from /var/folders/3f/2n5sjdw50vj9gfnrxjbptj4c0000gn/T/tmpio77ewpv/test_config.json
2025-06-05 14:16:18,953 - DEBUG - Saved configuration to /var/folders/3f/2n5sjdw50vj9gfnrxjbptj4c0000gn/T/tmp6c8xf9h8/test_config.json
2025-06-05 14:16:18,954 - DEBUG - Loaded configuration from /var/folders/3f/2n5sjdw50vj9gfnrxjbptj4c0000gn/T/tmp6c8xf9h8/test_config.json
2025-06-05 14:16:18,954 - DEBUG - Saved configuration to /var/folders/3f/2n5sjdw50vj9gfnrxjbptj4c0000gn/T/tmp6c8xf9h8/test_config.json
2025-06-05 14:16:18,954 - DEBUG - Loaded configuration from /var/folders/3f/2n5sjdw50vj9gfnrxjbptj4c0000gn/T/tmp6c8xf9h8/test_config.json
2025-06-05 14:16:18,955 - DEBUG - Saved configuration to /var/folders/3f/2n5sjdw50vj9gfnrxjbptj4c0000gn/T/tmp6c8xf9h8/test_config.json
2025-06-05 14:16:18,955 - DEBUG - Loaded configuration from /var/folders/3f/2n5sjdw50vj9gfnrxjbptj4c0000gn/T/tmp6c8xf9h8/test_config.json
2025-06-05 14:16:18,955 - DEBUG - Loaded configuration from /var/folders/3f/2n5sjdw50vj9gfnrxjbptj4c0000gn/T/tmp6c8xf9h8/test_config.json
2025-06-05 14:16:18,956 - DEBUG - Loaded configuration from /var/folders/3f/2n5sjdw50vj9gfnrxjbptj4c0000gn/T/tmp6c8xf9h8/test_config.json
2025-06-05 14:16:18,957 - INFO - Applying tag 'email' to column 'email_col'
2025-06-05 14:16:18,957 - INFO - Applying tag 'given-name' to column 'name_col'
2025-06-05 14:16:18,958 - INFO - Applying tag 'phone' to column 'good_col'
2025-06-05 14:16:18,959 - INFO - Applying tag 'email' to column 'email_col'
2025-06-05 14:16:18,961 - INFO - Applying tag 'email' to column 'email_col'
2025-06-05 14:16:18,961 - ERROR - Error applying tag to email_col: Connection error
2025-06-05 14:16:18,963 - DEBUG - Saved configuration to /var/folders/3f/2n5sjdw50vj9gfnrxjbptj4c0000gn/T/tmpmo1r079z/test_config.json
2025-06-05 14:16:18,997 - DEBUG - Saved configuration to /var/folders/3f/2n5sjdw50vj9gfnrxjbptj4c0000gn/T/tmpxvxcatgv/test_config.json
2025-06-05 14:16:18,999 - DEBUG - Saved configuration to /var/folders/3f/2n5sjdw50vj9gfnrxjbptj4c0000gn/T/tmpis383cgn/test_config.json
2025-06-05 14:16:19,000 - DEBUG - Loaded configuration from /var/folders/3f/2n5sjdw50vj9gfnrxjbptj4c0000gn/T/tmpis383cgn/test_config.json
2025-06-05 14:16:19,001 - DEBUG - Saved configuration to /var/folders/3f/2n5sjdw50vj9gfnrxjbptj4c0000gn/T/tmptwzs3z6f/test_config.json
2025-06-05 14:16:19,002 - DEBUG - Loaded configuration from /var/folders/3f/2n5sjdw50vj9gfnrxjbptj4c0000gn/T/tmptwzs3z6f/test_config.json
2025-06-05 14:16:19,007 - ERROR - Failed to set workspace URL: Validation error
Traceback (most recent call last):
  File "/Users/johnrush/repos/chuck-data/src/commands/workspace_selection.py", line 37, in handle_command
    is_valid, error_message = validate_workspace_url(workspace_url)
                              ^^^^^^^^^^^^^^^^^^^^^^^^^^^^^^^^^^^^^
  File "/usr/local/Cellar/python@3.11/3.11.4_1/Frameworks/Python.framework/Versions/3.11/lib/python3.11/unittest/mock.py", line 1124, in __call__
    return self._mock_call(*args, **kwargs)
           ^^^^^^^^^^^^^^^^^^^^^^^^^^^^^^^^
  File "/usr/local/Cellar/python@3.11/3.11.4_1/Frameworks/Python.framework/Versions/3.11/lib/python3.11/unittest/mock.py", line 1128, in _mock_call
    return self._execute_mock_call(*args, **kwargs)
           ^^^^^^^^^^^^^^^^^^^^^^^^^^^^^^^^^^^^^^^^
  File "/usr/local/Cellar/python@3.11/3.11.4_1/Frameworks/Python.framework/Versions/3.11/lib/python3.11/unittest/mock.py", line 1183, in _execute_mock_call
    raise effect
Exception: Validation error
