2025-05-14 12:58:04,025 - ERROR - HTTP error: 403 Client Error: Forbidden for url: https://dbc-df998298-4c7e.cloud.databricks.com/api/2.0/preview/scim/v2/Me, Response: {"error_code":403,"message":"Invalid access to Org: 3416276235813320 [ReqId: f3d8acba-a5d9-435d-859b-2a9a43da20fb]"}
2025-05-14 12:58:04,026 - ERROR - Token validation failed: HTTP error occurred: 403 Client Error: Forbidden for url: https://dbc-df998298-4c7e.cloud.databricks.com/api/2.0/preview/scim/v2/Me, Response: {"error_code":403,"message":"Invalid access to Org: 3416276235813320 [ReqId: f3d8acba-a5d9-435d-859b-2a9a43da20fb]"}
2025-05-14 12:58:10,922 - ERROR - HTTP error: 403 Client Error: Forbidden for url: https://dbc-df998298-4c7e.cloud.databricks.com/api/2.0/preview/scim/v2/Me, Response: {"error_code":403,"message":"Invalid access to Org: 3416276235813320 [ReqId: dbdb2a7c-ec6d-4512-9378-14eb2764619e]"}
2025-05-14 12:58:10,923 - ERROR - Token validation failed: HTTP error occurred: 403 Client Error: Forbidden for url: https://dbc-df998298-4c7e.cloud.databricks.com/api/2.0/preview/scim/v2/Me, Response: {"error_code":403,"message":"Invalid access to Org: 3416276235813320 [ReqId: dbdb2a7c-ec6d-4512-9378-14eb2764619e]"}
2025-05-14 13:43:18,052 - ERROR - Failed to submit one-time run via /runs/submit: HTTPSConnectionPool(host='https', port=443): Max retries exceeded with url: /dbc-df998298-4c7e.cloud.databricks.com/api/2.2/jobs/runs/submit (Caused by NameResolutionError("<urllib3.connection.HTTPSConnection object at 0x1040d25d0>: Failed to resolve 'https' ([Errno 8] nodename nor servname provided, or not known)"))
Traceback (most recent call last):
  File "/Users/johnrush/repos/clamp-internal/.venv/lib/python3.13/site-packages/urllib3/connection.py", line 198, in _new_conn
    sock = connection.create_connection(
        (self._dns_host, self.port),
    ...<2 lines>...
        socket_options=self.socket_options,
    )
  File "/Users/johnrush/repos/clamp-internal/.venv/lib/python3.13/site-packages/urllib3/util/connection.py", line 60, in create_connection
    for res in socket.getaddrinfo(host, port, family, socket.SOCK_STREAM):
               ~~~~~~~~~~~~~~~~~~^^^^^^^^^^^^^^^^^^^^^^^^^^^^^^^^^^^^^^^^
  File "/opt/homebrew/Cellar/python@3.13/3.13.2/Frameworks/Python.framework/Versions/3.13/lib/python3.13/socket.py", line 977, in getaddrinfo
    for res in _socket.getaddrinfo(host, port, family, type, proto, flags):
               ~~~~~~~~~~~~~~~~~~~^^^^^^^^^^^^^^^^^^^^^^^^^^^^^^^^^^^^^^^^
socket.gaierror: [Errno 8] nodename nor servname provided, or not known

The above exception was the direct cause of the following exception:

Traceback (most recent call last):
  File "/Users/johnrush/repos/clamp-internal/.venv/lib/python3.13/site-packages/urllib3/connectionpool.py", line 787, in urlopen
    response = self._make_request(
        conn,
    ...<10 lines>...
        **response_kw,
    )
  File "/Users/johnrush/repos/clamp-internal/.venv/lib/python3.13/site-packages/urllib3/connectionpool.py", line 488, in _make_request
    raise new_e
  File "/Users/johnrush/repos/clamp-internal/.venv/lib/python3.13/site-packages/urllib3/connectionpool.py", line 464, in _make_request
    self._validate_conn(conn)
    ~~~~~~~~~~~~~~~~~~~^^^^^^
  File "/Users/johnrush/repos/clamp-internal/.venv/lib/python3.13/site-packages/urllib3/connectionpool.py", line 1093, in _validate_conn
    conn.connect()
    ~~~~~~~~~~~~^^
  File "/Users/johnrush/repos/clamp-internal/.venv/lib/python3.13/site-packages/urllib3/connection.py", line 704, in connect
    self.sock = sock = self._new_conn()
                       ~~~~~~~~~~~~~~^^
  File "/Users/johnrush/repos/clamp-internal/.venv/lib/python3.13/site-packages/urllib3/connection.py", line 205, in _new_conn
    raise NameResolutionError(self.host, self, e) from e
urllib3.exceptions.NameResolutionError: <urllib3.connection.HTTPSConnection object at 0x1040d25d0>: Failed to resolve 'https' ([Errno 8] nodename nor servname provided, or not known)

The above exception was the direct cause of the following exception:

Traceback (most recent call last):
  File "/Users/johnrush/repos/clamp-internal/.venv/lib/python3.13/site-packages/requests/adapters.py", line 667, in send
    resp = conn.urlopen(
        method=request.method,
    ...<9 lines>...
        chunked=chunked,
    )
  File "/Users/johnrush/repos/clamp-internal/.venv/lib/python3.13/site-packages/urllib3/connectionpool.py", line 841, in urlopen
    retries = retries.increment(
        method, url, error=new_e, _pool=self, _stacktrace=sys.exc_info()[2]
    )
  File "/Users/johnrush/repos/clamp-internal/.venv/lib/python3.13/site-packages/urllib3/util/retry.py", line 519, in increment
    raise MaxRetryError(_pool, url, reason) from reason  # type: ignore[arg-type]
    ^^^^^^^^^^^^^^^^^^^^^^^^^^^^^^^^^^^^^^^^^^^^^^^^^^^
urllib3.exceptions.MaxRetryError: HTTPSConnectionPool(host='https', port=443): Max retries exceeded with url: /dbc-df998298-4c7e.cloud.databricks.com/api/2.2/jobs/runs/submit (Caused by NameResolutionError("<urllib3.connection.HTTPSConnection object at 0x1040d25d0>: Failed to resolve 'https' ([Errno 8] nodename nor servname provided, or not known)"))

During handling of the above exception, another exception occurred:

Traceback (most recent call last):
  File "/Users/johnrush/repos/clamp-internal/src/command_handlers.py", line 622, in handle_launch_job
    run_resp = requests.post(run_api_url, headers=headers, json=run_payload)
  File "/Users/johnrush/repos/clamp-internal/.venv/lib/python3.13/site-packages/requests/api.py", line 115, in post
    return request("post", url, data=data, json=json, **kwargs)
  File "/Users/johnrush/repos/clamp-internal/.venv/lib/python3.13/site-packages/requests/api.py", line 59, in request
    return session.request(method=method, url=url, **kwargs)
           ~~~~~~~~~~~~~~~^^^^^^^^^^^^^^^^^^^^^^^^^^^^^^^^^^
  File "/Users/johnrush/repos/clamp-internal/.venv/lib/python3.13/site-packages/requests/sessions.py", line 589, in request
    resp = self.send(prep, **send_kwargs)
  File "/Users/johnrush/repos/clamp-internal/.venv/lib/python3.13/site-packages/requests/sessions.py", line 703, in send
    r = adapter.send(request, **kwargs)
  File "/Users/johnrush/repos/clamp-internal/.venv/lib/python3.13/site-packages/requests/adapters.py", line 700, in send
    raise ConnectionError(e, request=request)
requests.exceptions.ConnectionError: HTTPSConnectionPool(host='https', port=443): Max retries exceeded with url: /dbc-df998298-4c7e.cloud.databricks.com/api/2.2/jobs/runs/submit (Caused by NameResolutionError("<urllib3.connection.HTTPSConnection object at 0x1040d25d0>: Failed to resolve 'https' ([Errno 8] nodename nor servname provided, or not known)"))
2025-05-14 13:43:18,083 - ERROR - Stitch setup error: 'NoneType' object has no attribute 'get'
2025-05-14 13:44:43,919 - ERROR - Failed to submit one-time run via /runs/submit: HTTPSConnectionPool(host='https', port=443): Max retries exceeded with url: /dbc-df998298-4c7e.cloud.databricks.com/api/2.2/jobs/runs/submit (Caused by NameResolutionError("<urllib3.connection.HTTPSConnection object at 0x1040d25d0>: Failed to resolve 'https' ([Errno 8] nodename nor servname provided, or not known)"))
Traceback (most recent call last):
  File "/Users/johnrush/repos/clamp-internal/.venv/lib/python3.13/site-packages/urllib3/connection.py", line 198, in _new_conn
    sock = connection.create_connection(
        (self._dns_host, self.port),
    ...<2 lines>...
        socket_options=self.socket_options,
    )
  File "/Users/johnrush/repos/clamp-internal/.venv/lib/python3.13/site-packages/urllib3/util/connection.py", line 60, in create_connection
    for res in socket.getaddrinfo(host, port, family, socket.SOCK_STREAM):
               ~~~~~~~~~~~~~~~~~~^^^^^^^^^^^^^^^^^^^^^^^^^^^^^^^^^^^^^^^^
  File "/opt/homebrew/Cellar/python@3.13/3.13.2/Frameworks/Python.framework/Versions/3.13/lib/python3.13/socket.py", line 977, in getaddrinfo
    for res in _socket.getaddrinfo(host, port, family, type, proto, flags):
               ~~~~~~~~~~~~~~~~~~~^^^^^^^^^^^^^^^^^^^^^^^^^^^^^^^^^^^^^^^^
socket.gaierror: [Errno 8] nodename nor servname provided, or not known

The above exception was the direct cause of the following exception:

Traceback (most recent call last):
  File "/Users/johnrush/repos/clamp-internal/.venv/lib/python3.13/site-packages/urllib3/connectionpool.py", line 787, in urlopen
    response = self._make_request(
        conn,
    ...<10 lines>...
        **response_kw,
    )
  File "/Users/johnrush/repos/clamp-internal/.venv/lib/python3.13/site-packages/urllib3/connectionpool.py", line 488, in _make_request
    raise new_e
  File "/Users/johnrush/repos/clamp-internal/.venv/lib/python3.13/site-packages/urllib3/connectionpool.py", line 464, in _make_request
    self._validate_conn(conn)
    ~~~~~~~~~~~~~~~~~~~^^^^^^
  File "/Users/johnrush/repos/clamp-internal/.venv/lib/python3.13/site-packages/urllib3/connectionpool.py", line 1093, in _validate_conn
    conn.connect()
    ~~~~~~~~~~~~^^
  File "/Users/johnrush/repos/clamp-internal/.venv/lib/python3.13/site-packages/urllib3/connection.py", line 704, in connect
    self.sock = sock = self._new_conn()
                       ~~~~~~~~~~~~~~^^
  File "/Users/johnrush/repos/clamp-internal/.venv/lib/python3.13/site-packages/urllib3/connection.py", line 205, in _new_conn
    raise NameResolutionError(self.host, self, e) from e
urllib3.exceptions.NameResolutionError: <urllib3.connection.HTTPSConnection object at 0x1040d25d0>: Failed to resolve 'https' ([Errno 8] nodename nor servname provided, or not known)

The above exception was the direct cause of the following exception:

Traceback (most recent call last):
  File "/Users/johnrush/repos/clamp-internal/.venv/lib/python3.13/site-packages/requests/adapters.py", line 667, in send
    resp = conn.urlopen(
        method=request.method,
    ...<9 lines>...
        chunked=chunked,
    )
  File "/Users/johnrush/repos/clamp-internal/.venv/lib/python3.13/site-packages/urllib3/connectionpool.py", line 841, in urlopen
    retries = retries.increment(
        method, url, error=new_e, _pool=self, _stacktrace=sys.exc_info()[2]
    )
  File "/Users/johnrush/repos/clamp-internal/.venv/lib/python3.13/site-packages/urllib3/util/retry.py", line 519, in increment
    raise MaxRetryError(_pool, url, reason) from reason  # type: ignore[arg-type]
    ^^^^^^^^^^^^^^^^^^^^^^^^^^^^^^^^^^^^^^^^^^^^^^^^^^^
urllib3.exceptions.MaxRetryError: HTTPSConnectionPool(host='https', port=443): Max retries exceeded with url: /dbc-df998298-4c7e.cloud.databricks.com/api/2.2/jobs/runs/submit (Caused by NameResolutionError("<urllib3.connection.HTTPSConnection object at 0x1040d25d0>: Failed to resolve 'https' ([Errno 8] nodename nor servname provided, or not known)"))

During handling of the above exception, another exception occurred:

Traceback (most recent call last):
  File "/Users/johnrush/repos/clamp-internal/src/command_handlers.py", line 622, in handle_launch_job
    run_resp = requests.post(run_api_url, headers=headers, json=run_payload)
  File "/Users/johnrush/repos/clamp-internal/.venv/lib/python3.13/site-packages/requests/api.py", line 115, in post
    return request("post", url, data=data, json=json, **kwargs)
  File "/Users/johnrush/repos/clamp-internal/.venv/lib/python3.13/site-packages/requests/api.py", line 59, in request
    return session.request(method=method, url=url, **kwargs)
           ~~~~~~~~~~~~~~~^^^^^^^^^^^^^^^^^^^^^^^^^^^^^^^^^^
  File "/Users/johnrush/repos/clamp-internal/.venv/lib/python3.13/site-packages/requests/sessions.py", line 589, in request
    resp = self.send(prep, **send_kwargs)
  File "/Users/johnrush/repos/clamp-internal/.venv/lib/python3.13/site-packages/requests/sessions.py", line 703, in send
    r = adapter.send(request, **kwargs)
  File "/Users/johnrush/repos/clamp-internal/.venv/lib/python3.13/site-packages/requests/adapters.py", line 700, in send
    raise ConnectionError(e, request=request)
requests.exceptions.ConnectionError: HTTPSConnectionPool(host='https', port=443): Max retries exceeded with url: /dbc-df998298-4c7e.cloud.databricks.com/api/2.2/jobs/runs/submit (Caused by NameResolutionError("<urllib3.connection.HTTPSConnection object at 0x1040d25d0>: Failed to resolve 'https' ([Errno 8] nodename nor servname provided, or not known)"))
2025-05-14 13:44:43,924 - ERROR - Stitch setup error: 'NoneType' object has no attribute 'get'
