2025-06-06 17:04:15,986 - DEBUG - Logging initialized. Writing to /Users/johnrush/repos/chuck-data/log/sessions/2025-06-06_17-04-15.log
2025-06-06 17:04:15,991 - DEBUG - HTTP error: HTTP 401, Response: {"status":401,"message":"Unauthorized"}
2025-06-06 17:04:15,993 - DEBUG - GET request to: https://test-workspace.cloud.databricks.com/test-endpoint
2025-06-06 17:04:15,993 - DEBUG - Connection error: Connection failed
2025-06-06 17:04:15,995 - DEBUG - GET request to: https://test-workspace.cloud.databricks.com/test-endpoint
2025-06-06 17:04:15,995 - DEBUG - HTTP error: HTTP 404, Response: Not Found
2025-06-06 17:04:15,998 - DEBUG - GET request to: https://test-workspace.cloud.databricks.com/test-endpoint
2025-06-06 17:04:16,000 - DEBUG - POST request to: https://test-workspace.cloud.databricks.com/test-endpoint
2025-06-06 17:04:16,001 - DEBUG - Connection error: Connection failed
2025-06-06 17:04:16,003 - DEBUG - POST request to: https://test-workspace.cloud.databricks.com/test-endpoint
2025-06-06 17:04:16,003 - DEBUG - HTTP error: HTTP 400, Response: Bad Request
2025-06-06 17:04:16,004 - DEBUG - POST request to: https://test-workspace.cloud.databricks.com/test-endpoint
2025-06-06 17:04:16,010 - DEBUG - Saved configuration to /var/folders/3f/2n5sjdw50vj9gfnrxjbptj4c0000gn/T/tmpp5mx80ji/test_config.json
2025-06-06 17:04:16,010 - DEBUG - Loaded configuration from /var/folders/3f/2n5sjdw50vj9gfnrxjbptj4c0000gn/T/tmpp5mx80ji/test_config.json
2025-06-06 17:04:16,010 - DEBUG - Loaded configuration from /var/folders/3f/2n5sjdw50vj9gfnrxjbptj4c0000gn/T/tmpp5mx80ji/test_config.json
2025-06-06 17:04:16,010 - DEBUG - Saved configuration to /var/folders/3f/2n5sjdw50vj9gfnrxjbptj4c0000gn/T/tmpp5mx80ji/test_config.json
2025-06-06 17:04:16,011 - DEBUG - Loaded configuration from /var/folders/3f/2n5sjdw50vj9gfnrxjbptj4c0000gn/T/tmpp5mx80ji/test_config.json
2025-06-06 17:04:16,011 - DEBUG - Saved configuration to /var/folders/3f/2n5sjdw50vj9gfnrxjbptj4c0000gn/T/tmpp5mx80ji/test_config.json
2025-06-06 17:04:16,011 - DEBUG - Loaded configuration from /var/folders/3f/2n5sjdw50vj9gfnrxjbptj4c0000gn/T/tmpp5mx80ji/test_config.json
2025-06-06 17:04:16,012 - DEBUG - Saved configuration to /var/folders/3f/2n5sjdw50vj9gfnrxjbptj4c0000gn/T/tmpp5mx80ji/test_config.json
2025-06-06 17:04:16,012 - DEBUG - Loaded configuration from /var/folders/3f/2n5sjdw50vj9gfnrxjbptj4c0000gn/T/tmpp5mx80ji/test_config.json
2025-06-06 17:04:16,012 - DEBUG - Saved configuration to /var/folders/3f/2n5sjdw50vj9gfnrxjbptj4c0000gn/T/tmpp5mx80ji/test_config.json
2025-06-06 17:04:16,012 - DEBUG - Loaded configuration from /var/folders/3f/2n5sjdw50vj9gfnrxjbptj4c0000gn/T/tmpp5mx80ji/test_config.json
2025-06-06 17:04:16,012 - DEBUG - Loaded configuration from /var/folders/3f/2n5sjdw50vj9gfnrxjbptj4c0000gn/T/tmpp5mx80ji/test_config.json
2025-06-06 17:04:16,012 - DEBUG - Loaded configuration from /var/folders/3f/2n5sjdw50vj9gfnrxjbptj4c0000gn/T/tmpp5mx80ji/test_config.json
2025-06-06 17:04:16,013 - DEBUG - Loaded configuration from /var/folders/3f/2n5sjdw50vj9gfnrxjbptj4c0000gn/T/tmpp5mx80ji/test_config.json
2025-06-06 17:04:16,013 - DEBUG - Loaded configuration from /var/folders/3f/2n5sjdw50vj9gfnrxjbptj4c0000gn/T/tmpp5mx80ji/test_config.json
2025-06-06 17:04:16,015 - DEBUG - Saved configuration to /var/folders/3f/2n5sjdw50vj9gfnrxjbptj4c0000gn/T/tmpa7czk6hx/test_config.json
2025-06-06 17:04:16,015 - DEBUG - Loaded configuration from /var/folders/3f/2n5sjdw50vj9gfnrxjbptj4c0000gn/T/tmpa7czk6hx/test_config.json
2025-06-06 17:04:16,017 - DEBUG - Saved configuration to /var/folders/3f/2n5sjdw50vj9gfnrxjbptj4c0000gn/T/tmprera5sul/test_config.json
2025-06-06 17:04:16,017 - DEBUG - Loaded configuration from /var/folders/3f/2n5sjdw50vj9gfnrxjbptj4c0000gn/T/tmprera5sul/test_config.json
2025-06-06 17:04:16,019 - DEBUG - Saved configuration to /var/folders/3f/2n5sjdw50vj9gfnrxjbptj4c0000gn/T/tmp9jlyjglb/test_config.json
2025-06-06 17:04:16,019 - DEBUG - Loaded configuration from /var/folders/3f/2n5sjdw50vj9gfnrxjbptj4c0000gn/T/tmp9jlyjglb/test_config.json
2025-06-06 17:04:16,020 - DEBUG - Loaded configuration from /var/folders/3f/2n5sjdw50vj9gfnrxjbptj4c0000gn/T/tmp9jlyjglb/test_config.json
2025-06-06 17:04:16,020 - DEBUG - Saved configuration to /var/folders/3f/2n5sjdw50vj9gfnrxjbptj4c0000gn/T/tmp9jlyjglb/test_config.json
2025-06-06 17:04:16,020 - DEBUG - Loaded configuration from /var/folders/3f/2n5sjdw50vj9gfnrxjbptj4c0000gn/T/tmp9jlyjglb/test_config.json
2025-06-06 17:04:16,020 - DEBUG - Loaded configuration from /var/folders/3f/2n5sjdw50vj9gfnrxjbptj4c0000gn/T/tmp9jlyjglb/test_config.json
2025-06-06 17:04:16,024 - DEBUG - Saved configuration to /var/folders/3f/2n5sjdw50vj9gfnrxjbptj4c0000gn/T/tmpzr2w9u4m/test_config.json
2025-06-06 17:04:16,024 - DEBUG - Loaded configuration from /var/folders/3f/2n5sjdw50vj9gfnrxjbptj4c0000gn/T/tmpzr2w9u4m/test_config.json
2025-06-06 17:04:16,024 - DEBUG - Loaded configuration from /var/folders/3f/2n5sjdw50vj9gfnrxjbptj4c0000gn/T/tmpzr2w9u4m/test_config.json
2025-06-06 17:04:16,024 - DEBUG - Saved configuration to /var/folders/3f/2n5sjdw50vj9gfnrxjbptj4c0000gn/T/tmpzr2w9u4m/test_config.json
2025-06-06 17:04:16,024 - DEBUG - Loaded configuration from /var/folders/3f/2n5sjdw50vj9gfnrxjbptj4c0000gn/T/tmpzr2w9u4m/test_config.json
2025-06-06 17:04:16,025 - DEBUG - Saved configuration to /var/folders/3f/2n5sjdw50vj9gfnrxjbptj4c0000gn/T/tmpzr2w9u4m/test_config.json
2025-06-06 17:04:16,025 - DEBUG - Loaded configuration from /var/folders/3f/2n5sjdw50vj9gfnrxjbptj4c0000gn/T/tmpzr2w9u4m/test_config.json
2025-06-06 17:04:16,025 - DEBUG - Saved configuration to /var/folders/3f/2n5sjdw50vj9gfnrxjbptj4c0000gn/T/tmpzr2w9u4m/test_config.json
2025-06-06 17:04:16,025 - DEBUG - Loaded configuration from /var/folders/3f/2n5sjdw50vj9gfnrxjbptj4c0000gn/T/tmpzr2w9u4m/test_config.json
2025-06-06 17:04:16,025 - DEBUG - Saved configuration to /var/folders/3f/2n5sjdw50vj9gfnrxjbptj4c0000gn/T/tmpzr2w9u4m/test_config.json
2025-06-06 17:04:16,025 - DEBUG - Loaded configuration from /var/folders/3f/2n5sjdw50vj9gfnrxjbptj4c0000gn/T/tmpzr2w9u4m/test_config.json
2025-06-06 17:04:16,025 - DEBUG - Using workspace_url from environment variable CHUCK_WORKSPACE_URL
2025-06-06 17:04:16,026 - DEBUG - Using active_model from environment variable CHUCK_ACTIVE_MODEL
2025-06-06 17:04:16,026 - DEBUG - Using warehouse_id from environment variable CHUCK_WAREHOUSE_ID
2025-06-06 17:04:16,026 - DEBUG - Using active_catalog from environment variable CHUCK_ACTIVE_CATALOG
2025-06-06 17:04:16,026 - DEBUG - Using active_schema from environment variable CHUCK_ACTIVE_SCHEMA
2025-06-06 17:04:16,026 - DEBUG - Using usage_tracking_consent from environment variable CHUCK_USAGE_TRACKING_CONSENT
2025-06-06 17:04:16,026 - DEBUG - Loaded configuration from /var/folders/3f/2n5sjdw50vj9gfnrxjbptj4c0000gn/T/tmpzr2w9u4m/test_config.json
2025-06-06 17:04:16,028 - DEBUG - Saved configuration to /var/folders/3f/2n5sjdw50vj9gfnrxjbptj4c0000gn/T/tmp01hv55fr/test_config.json
2025-06-06 17:04:16,028 - DEBUG - Loaded configuration from /var/folders/3f/2n5sjdw50vj9gfnrxjbptj4c0000gn/T/tmp01hv55fr/test_config.json
2025-06-06 17:04:16,028 - DEBUG - Loaded configuration from /var/folders/3f/2n5sjdw50vj9gfnrxjbptj4c0000gn/T/tmp01hv55fr/test_config.json
2025-06-06 17:04:16,028 - WARNING - Invalid workspace_url provided, using default instead
2025-06-06 17:04:16,029 - DEBUG - Saved configuration to /var/folders/3f/2n5sjdw50vj9gfnrxjbptj4c0000gn/T/tmp01hv55fr/test_config.json
2025-06-06 17:04:16,029 - DEBUG - Loaded configuration from /var/folders/3f/2n5sjdw50vj9gfnrxjbptj4c0000gn/T/tmp01hv55fr/test_config.json
2025-06-06 17:04:16,029 - DEBUG - Loaded configuration from /var/folders/3f/2n5sjdw50vj9gfnrxjbptj4c0000gn/T/tmp01hv55fr/test_config.json
2025-06-06 17:04:16,029 - DEBUG - Saved configuration to /var/folders/3f/2n5sjdw50vj9gfnrxjbptj4c0000gn/T/tmp01hv55fr/test_config.json
2025-06-06 17:04:16,030 - DEBUG - Loaded configuration from /var/folders/3f/2n5sjdw50vj9gfnrxjbptj4c0000gn/T/tmp01hv55fr/test_config.json
2025-06-06 17:04:16,032 - DEBUG - Using workspace_url from environment variable CHUCK_WORKSPACE_URL
2025-06-06 17:04:16,032 - DEBUG - Using workspace_url from environment variable CHUCK_WORKSPACE_URL
2025-06-06 17:04:16,032 - DEBUG - Using active_model from environment variable CHUCK_ACTIVE_MODEL
2025-06-06 17:04:16,033 - DEBUG - Using amperity_token from environment variable CHUCK_AMPERITY_TOKEN
2025-06-06 17:04:16,033 - DEBUG - Using databricks_token from environment variable CHUCK_DATABRICKS_TOKEN
2025-06-06 17:04:16,033 - DEBUG - Saved configuration to /var/folders/3f/2n5sjdw50vj9gfnrxjbptj4c0000gn/T/tmpbb4zxv52/test_config.json
2025-06-06 17:04:16,033 - DEBUG - Loaded configuration from /var/folders/3f/2n5sjdw50vj9gfnrxjbptj4c0000gn/T/tmpbb4zxv52/test_config.json
2025-06-06 17:04:16,036 - DEBUG - Saved configuration to /var/folders/3f/2n5sjdw50vj9gfnrxjbptj4c0000gn/T/tmpg099bvob/test_config.json
2025-06-06 17:04:16,057 - DEBUG - GET request to: https://adb-3856707039489412.12.azuredatabricks.net/test-endpoint
2025-06-06 17:04:16,064 - DEBUG - GET request to: https://test-workspace.cloud.databricks.com/test-endpoint
2025-06-06 17:04:16,064 - DEBUG - Connection error: Connection failed
2025-06-06 17:04:16,066 - DEBUG - GET request to: https://test-workspace.cloud.databricks.com/test-endpoint
2025-06-06 17:04:16,066 - DEBUG - HTTP error: HTTP 404, Response: Not Found
2025-06-06 17:04:16,068 - WARNING - Model 'nonexistent-model' not found
2025-06-06 17:04:16,070 - DEBUG - GET request to: https://test-workspace.cloud.databricks.com/test-endpoint
2025-06-06 17:04:16,080 - DEBUG - POST request to: https://test-workspace.cloud.databricks.com/test-endpoint
2025-06-06 17:04:16,080 - DEBUG - Connection error: Connection failed
2025-06-06 17:04:16,081 - DEBUG - POST request to: https://test-workspace.cloud.databricks.com/test-endpoint
2025-06-06 17:04:16,082 - DEBUG - HTTP error: HTTP 400, Response: Bad Request
2025-06-06 17:04:16,083 - DEBUG - POST request to: https://test-workspace.cloud.databricks.com/test-endpoint
2025-06-06 17:04:16,086 - DEBUG - File upload request to: https://test-workspace.cloud.databricks.com/api/2.0/fs/files/test/path.txt
2025-06-06 17:04:16,090 - DEBUG - File upload request to: https://test-workspace.cloud.databricks.com/api/2.0/fs/files/test/path.txt
2025-06-06 17:04:16,092 - DEBUG - Token validation failed: Token validation failed
2025-06-06 17:04:16,096 - DEBUG - Saved configuration to /tmp/.test_chuck_integration_config.json
2025-06-06 17:04:16,096 - DEBUG - Saved configuration to /tmp/.test_chuck_integration_config.json
2025-06-06 17:04:16,098 - DEBUG - Saved configuration to /tmp/.test_chuck_integration_config.json
2025-06-06 17:04:16,099 - DEBUG - Saved configuration to /tmp/.test_chuck_integration_config.json
2025-06-06 17:04:16,101 - DEBUG - Saved configuration to /tmp/.test_chuck_integration_config.json
2025-06-06 17:04:16,101 - DEBUG - Saved configuration to /tmp/.test_chuck_integration_config.json
2025-06-06 17:04:16,109 - DEBUG - Sending metric: {"event": "USAGE", "prompt": "test prompt"}...
2025-06-06 17:04:16,109 - DEBUG - Error sending metrics: Test exception
Traceback (most recent call last):
  File "/Users/johnrush/repos/chuck-data/chuck_data/metrics_collector.py", line 123, in send_metric
    return self._client.submit_metrics(payload, token)
           ^^^^^^^^^^^^^^^^^^^^^^^^^^^^^^^^^^^^^^^^^^^
  File "/Users/johnrush/repos/chuck-data/tests/fixtures.py", line 60, in submit_metrics
    raise Exception("Test exception")
Exception: Test exception
2025-06-06 17:04:16,112 - DEBUG - Sending metric: {"event": "USAGE", "prompt": "test prompt"}...
2025-06-06 17:04:16,114 - DEBUG - Cannot send metrics - no authentication token available
2025-06-06 17:04:16,116 - DEBUG - Sending metric: {"event": "USAGE", "prompt": "test prompt"}...
2025-06-06 17:04:16,120 - DEBUG - Metrics tracking skipped - user has not provided consent
2025-06-06 17:04:16,124 - ERROR - Connection error when getting model: Connection failed
2025-06-06 17:04:16,125 - ERROR - Failed to get model: HTTP error occurred: 500 Internal Server Error
2025-06-06 17:04:16,129 - ERROR - Connection error when listing models: Connection failed
2025-06-06 17:04:16,131 - ERROR - Failed to list models: HTTP error occurred: 404 Not Found
2025-06-06 17:04:16,193 - ERROR - Error executing handler for command 'test_command': Command failed
Traceback (most recent call last):
  File "/Users/johnrush/repos/chuck-data/chuck_data/service.py", line 395, in execute_command
    result: CommandResult = command_def.handler(
                            ^^^^^^^^^^^^^^^^^^^^
  File "/usr/local/Cellar/python@3.11/3.11.4_1/Frameworks/Python.framework/Versions/3.11/lib/python3.11/unittest/mock.py", line 1124, in __call__
    return self._mock_call(*args, **kwargs)
           ^^^^^^^^^^^^^^^^^^^^^^^^^^^^^^^^
  File "/usr/local/Cellar/python@3.11/3.11.4_1/Frameworks/Python.framework/Versions/3.11/lib/python3.11/unittest/mock.py", line 1128, in _mock_call
    return self._execute_mock_call(*args, **kwargs)
           ^^^^^^^^^^^^^^^^^^^^^^^^^^^^^^^^^^^^^^^^
  File "/usr/local/Cellar/python@3.11/3.11.4_1/Frameworks/Python.framework/Versions/3.11/lib/python3.11/unittest/mock.py", line 1183, in _execute_mock_call
    raise effect
Exception: Command failed
2025-06-06 17:04:16,258 - DEBUG - Executing SQL: SELECT * INVALID SQL
2025-06-06 17:04:16,260 - DEBUG - Executing SQL: SELECT * INVALID SQL
2025-06-06 17:04:16,262 - DEBUG - Executing SQL: SELECT * FROM table
2025-06-06 17:04:16,264 - DEBUG - Executing SQL: SELECT * FROM table
2025-06-06 17:04:16,266 - DEBUG - Executing SQL: SELECT * FROM table
2025-06-06 17:04:16,269 - DEBUG - Executing SQL: SELECT * FROM table
2025-06-06 17:04:16,277 - ERROR - Authentication state polling received 401
2025-06-06 17:04:16,282 - ERROR - Error creating Stitch report: API Error
Traceback (most recent call last):
  File "/Users/johnrush/repos/chuck-data/chuck_data/commands/add_stitch_report.py", line 62, in handle_command
    result = client.create_stitch_notebook(table_path, custom_name)
             ^^^^^^^^^^^^^^^^^^^^^^^^^^^^^^^^^^^^^^^^^^^^^^^^^^^^^^
  File "/Users/johnrush/repos/chuck-data/tests/fixtures.py", line 528, in create_stitch_notebook
    raise self._create_stitch_notebook_error
ValueError: API Error
2025-06-06 17:04:16,289 - ERROR - Agent error: Agent error
Traceback (most recent call last):
  File "/Users/johnrush/repos/chuck-data/chuck_data/commands/agent.py", line 79, in handle_command
    agent = AgentManager(client, tool_output_callback=tool_output_callback)
            ^^^^^^^^^^^^^^^^^^^^^^^^^^^^^^^^^^^^^^^^^^^^^^^^^^^^^^^^^^^^^^^
  File "/usr/local/Cellar/python@3.11/3.11.4_1/Frameworks/Python.framework/Versions/3.11/lib/python3.11/unittest/mock.py", line 1124, in __call__
    return self._mock_call(*args, **kwargs)
           ^^^^^^^^^^^^^^^^^^^^^^^^^^^^^^^^
  File "/usr/local/Cellar/python@3.11/3.11.4_1/Frameworks/Python.framework/Versions/3.11/lib/python3.11/unittest/mock.py", line 1128, in _mock_call
    return self._execute_mock_call(*args, **kwargs)
           ^^^^^^^^^^^^^^^^^^^^^^^^^^^^^^^^^^^^^^^^
  File "/usr/local/Cellar/python@3.11/3.11.4_1/Frameworks/Python.framework/Versions/3.11/lib/python3.11/unittest/mock.py", line 1183, in _execute_mock_call
    raise effect
Exception: Agent error
2025-06-06 17:04:16,291 - DEBUG - Sending metric: {"event": "USAGE", "configuration": {"workspace_url": "https://dbc-df998298-4c7e.cloud.databricks.co...
2025-06-06 17:04:16,306 - DEBUG - Starting new HTTPS connection (1): chuck.amperity.com:443
2025-06-06 17:04:16,436 - DEBUG - https://chuck.amperity.com:443 "POST /api/usage HTTP/1.1" 204 0
2025-06-06 17:04:16,437 - DEBUG - Failed to send metrics: 204 - 
2025-06-06 17:04:16,441 - DEBUG - Sending metric: {"event": "USAGE", "configuration": {"workspace_url": "https://dbc-df998298-4c7e.cloud.databricks.co...
2025-06-06 17:04:16,443 - DEBUG - Starting new HTTPS connection (1): chuck.amperity.com:443
2025-06-06 17:04:16,568 - DEBUG - https://chuck.amperity.com:443 "POST /api/usage HTTP/1.1" 204 0
2025-06-06 17:04:16,569 - DEBUG - Failed to send metrics: 204 - 
2025-06-06 17:04:16,581 - DEBUG - Sending metric: {"event": "USAGE", "configuration": {"workspace_url": "https://dbc-df998298-4c7e.cloud.databricks.co...
2025-06-06 17:04:16,583 - DEBUG - Starting new HTTPS connection (1): chuck.amperity.com:443
2025-06-06 17:04:16,712 - DEBUG - https://chuck.amperity.com:443 "POST /api/usage HTTP/1.1" 204 0
2025-06-06 17:04:16,713 - DEBUG - Failed to send metrics: 204 - 
2025-06-06 17:04:16,715 - DEBUG - Sending metric: {"event": "USAGE", "configuration": {"workspace_url": "https://dbc-df998298-4c7e.cloud.databricks.co...
2025-06-06 17:04:16,717 - DEBUG - Starting new HTTPS connection (1): chuck.amperity.com:443
2025-06-06 17:04:16,845 - DEBUG - https://chuck.amperity.com:443 "POST /api/usage HTTP/1.1" 204 0
2025-06-06 17:04:16,845 - DEBUG - Failed to send metrics: 204 - 
2025-06-06 17:04:16,848 - DEBUG - Sending metric: {"event": "USAGE", "configuration": {"workspace_url": "https://dbc-df998298-4c7e.cloud.databricks.co...
2025-06-06 17:04:16,850 - DEBUG - Starting new HTTPS connection (1): chuck.amperity.com:443
2025-06-06 17:04:16,970 - DEBUG - https://chuck.amperity.com:443 "POST /api/usage HTTP/1.1" 204 0
2025-06-06 17:04:16,970 - DEBUG - Failed to send metrics: 204 - 
2025-06-06 17:04:16,978 - INFO - Databricks token set successfully
2025-06-06 17:04:16,980 - INFO - Databricks token cleared
2025-06-06 17:04:16,980 - INFO - Amperity token cleared
2025-06-06 17:04:16,982 - INFO - Amperity token cleared
2025-06-06 17:04:16,983 - INFO - Databricks token cleared
2025-06-06 17:04:16,985 - INFO - Amperity token cleared
2025-06-06 17:04:16,998 - DEBUG - Bug report submitted successfully
2025-06-06 17:04:17,047 - ERROR - Error submitting bug report: Network error
Traceback (most recent call last):
  File "/Users/johnrush/repos/chuck-data/chuck_data/commands/bug.py", line 72, in handle_command
    success, message = amperity_client.submit_bug_report(payload, amperity_token)
                       ^^^^^^^^^^^^^^^^^^^^^^^^^^^^^^^^^^^^^^^^^^^^^^^^^^^^^^^^^^
  File "/Users/johnrush/repos/chuck-data/tests/commands/test_bug.py", line 115, in submit_bug_report
    raise Exception("Network error")
Exception: Network error
2025-06-06 17:04:17,050 - DEBUG - Loaded configuration from /var/folders/3f/2n5sjdw50vj9gfnrxjbptj4c0000gn/T/tmpjywsdes6.json
2025-06-06 17:04:17,053 - DEBUG - Loaded configuration from /var/folders/3f/2n5sjdw50vj9gfnrxjbptj4c0000gn/T/tmpyv_3nwgc.json
2025-06-06 17:04:17,065 - DEBUG - Bug report submitted successfully
2025-06-06 17:04:17,074 - DEBUG - Saved configuration to /var/folders/3f/2n5sjdw50vj9gfnrxjbptj4c0000gn/T/tmpnkdganlf/test_config.json
2025-06-06 17:04:17,076 - DEBUG - Saved configuration to /var/folders/3f/2n5sjdw50vj9gfnrxjbptj4c0000gn/T/tmpufo3wemd/test_config.json
2025-06-06 17:04:17,078 - DEBUG - Saved configuration to /var/folders/3f/2n5sjdw50vj9gfnrxjbptj4c0000gn/T/tmprq2dqlc8/test_config.json
2025-06-06 17:04:17,078 - DEBUG - Loaded configuration from /var/folders/3f/2n5sjdw50vj9gfnrxjbptj4c0000gn/T/tmprq2dqlc8/test_config.json
2025-06-06 17:04:17,082 - INFO - Cluster init script uploaded successfully to /Volumes/main/default/chuck/cluster_init-2025-06-02_14-30.sh
2025-06-06 17:04:17,091 - DEBUG - Volume 'chuck' not found in main.default. Attempting to create.
2025-06-06 17:04:17,091 - DEBUG - Volume 'chuck' created successfully.
2025-06-06 17:04:17,091 - INFO - Cluster init script uploaded successfully to /Volumes/main/default/chuck/cluster_init-2025-06-02_14-30.sh
2025-06-06 17:04:17,094 - DEBUG - Volume 'chuck' not found in main.default. Attempting to create.
2025-06-06 17:04:17,094 - DEBUG - Volume 'chuck' created successfully.
2025-06-06 17:04:17,094 - INFO - Cluster init script uploaded successfully to /Volumes/main/default/chuck/cluster_init-2025-06-02_14-30.sh
2025-06-06 17:04:17,097 - DEBUG - Volume 'chuck' not found in main.default. Attempting to create.
2025-06-06 17:04:17,099 - DEBUG - Volume 'chuck' not found in main.default. Attempting to create.
2025-06-06 17:04:17,105 - INFO - Cluster init script uploaded successfully to /Volumes/test_catalog/test_schema/chuck/cluster_init-2025-12-31_23-59.sh
2025-06-06 17:04:17,108 - ERROR - Error generating help: Test error
Traceback (most recent call last):
  File "/Users/johnrush/repos/chuck-data/chuck_data/commands/help.py", line 31, in handle_command
    user_commands = get_user_commands()
                    ^^^^^^^^^^^^^^^^^^^
  File "/usr/local/Cellar/python@3.11/3.11.4_1/Frameworks/Python.framework/Versions/3.11/lib/python3.11/unittest/mock.py", line 1124, in __call__
    return self._mock_call(*args, **kwargs)
           ^^^^^^^^^^^^^^^^^^^^^^^^^^^^^^^^
  File "/usr/local/Cellar/python@3.11/3.11.4_1/Frameworks/Python.framework/Versions/3.11/lib/python3.11/unittest/mock.py", line 1128, in _mock_call
    return self._execute_mock_call(*args, **kwargs)
           ^^^^^^^^^^^^^^^^^^^^^^^^^^^^^^^^^^^^^^^^
  File "/usr/local/Cellar/python@3.11/3.11.4_1/Frameworks/Python.framework/Versions/3.11/lib/python3.11/unittest/mock.py", line 1183, in _execute_mock_call
    raise effect
Exception: Test error
2025-06-06 17:04:17,114 - ERROR - Failed to get job status for run '999999': Not Found
Traceback (most recent call last):
  File "/Users/johnrush/repos/chuck-data/chuck_data/commands/jobs.py", line 67, in handle_job_status
    data = client.get_job_run_status(run_id_str)
           ^^^^^^^^^^^^^^^^^^^^^^^^^^^^^^^^^^^^^
  File "/Users/johnrush/repos/chuck-data/tests/commands/test_jobs.py", line 119, in get_job_run_status
    raise Exception("Not Found")
Exception: Not Found
2025-06-06 17:04:17,119 - ERROR - Failed to submit job: Bad Request
Traceback (most recent call last):
  File "/Users/johnrush/repos/chuck-data/chuck_data/commands/jobs.py", line 32, in handle_launch_job
    run_data = client.submit_job_run(
               ^^^^^^^^^^^^^^^^^^^^^^
  File "/Users/johnrush/repos/chuck-data/tests/commands/test_jobs.py", line 70, in submit_job_run
    raise Exception("Bad Request")
Exception: Bad Request
2025-06-06 17:04:17,124 - ERROR - Failed to launch job, no run_id: {}
2025-06-06 17:04:17,129 - ERROR - Error listing catalogs: API error
2025-06-06 17:04:17,140 - DEBUG - Saved configuration to /var/folders/3f/2n5sjdw50vj9gfnrxjbptj4c0000gn/T/tmpwi2cepzl/test_config.json
2025-06-06 17:04:17,141 - DEBUG - Loaded configuration from /var/folders/3f/2n5sjdw50vj9gfnrxjbptj4c0000gn/T/tmpwi2cepzl/test_config.json
2025-06-06 17:04:17,143 - DEBUG - Saved configuration to /var/folders/3f/2n5sjdw50vj9gfnrxjbptj4c0000gn/T/tmpf9qpro91/test_config.json
2025-06-06 17:04:17,143 - DEBUG - Loaded configuration from /var/folders/3f/2n5sjdw50vj9gfnrxjbptj4c0000gn/T/tmpf9qpro91/test_config.json
2025-06-06 17:04:17,147 - DEBUG - Saved configuration to /var/folders/3f/2n5sjdw50vj9gfnrxjbptj4c0000gn/T/tmpm9lxalxc/test_config.json
2025-06-06 17:04:17,147 - DEBUG - Loaded configuration from /var/folders/3f/2n5sjdw50vj9gfnrxjbptj4c0000gn/T/tmpm9lxalxc/test_config.json
2025-06-06 17:04:17,149 - ERROR - Failed to list models: API error
Traceback (most recent call last):
  File "/Users/johnrush/repos/chuck-data/chuck_data/commands/list_models.py", line 31, in handle_command
    models_list = list_models_api(client)
                  ^^^^^^^^^^^^^^^^^^^^^^^
  File "/Users/johnrush/repos/chuck-data/chuck_data/models.py", line 19, in list_models
    return client.list_models()
           ^^^^^^^^^^^^^^^^^^^^
  File "/Users/johnrush/repos/chuck-data/tests/commands/test_list_models.py", line 112, in list_models
    raise Exception("API error")
Exception: API error
2025-06-06 17:04:17,152 - DEBUG - Saved configuration to /var/folders/3f/2n5sjdw50vj9gfnrxjbptj4c0000gn/T/tmpm69g7x4y/test_config.json
2025-06-06 17:04:17,152 - DEBUG - Loaded configuration from /var/folders/3f/2n5sjdw50vj9gfnrxjbptj4c0000gn/T/tmpm69g7x4y/test_config.json
2025-06-06 17:04:17,152 - DEBUG - Loaded configuration from /var/folders/3f/2n5sjdw50vj9gfnrxjbptj4c0000gn/T/tmpm69g7x4y/test_config.json
2025-06-06 17:04:17,156 - DEBUG - Saved configuration to /var/folders/3f/2n5sjdw50vj9gfnrxjbptj4c0000gn/T/tmpah110fhe/test_config.json
2025-06-06 17:04:17,156 - DEBUG - Loaded configuration from /var/folders/3f/2n5sjdw50vj9gfnrxjbptj4c0000gn/T/tmpah110fhe/test_config.json
2025-06-06 17:04:17,156 - DEBUG - Loaded configuration from /var/folders/3f/2n5sjdw50vj9gfnrxjbptj4c0000gn/T/tmpah110fhe/test_config.json
2025-06-06 17:04:17,159 - DEBUG - Saved configuration to /var/folders/3f/2n5sjdw50vj9gfnrxjbptj4c0000gn/T/tmprs87x30j/test_config.json
2025-06-06 17:04:17,159 - DEBUG - Loaded configuration from /var/folders/3f/2n5sjdw50vj9gfnrxjbptj4c0000gn/T/tmprs87x30j/test_config.json
2025-06-06 17:04:17,159 - DEBUG - Loaded configuration from /var/folders/3f/2n5sjdw50vj9gfnrxjbptj4c0000gn/T/tmprs87x30j/test_config.json
2025-06-06 17:04:17,161 - DEBUG - Saved configuration to /var/folders/3f/2n5sjdw50vj9gfnrxjbptj4c0000gn/T/tmpmnxl8tjy/test_config.json
2025-06-06 17:04:17,161 - DEBUG - Loaded configuration from /var/folders/3f/2n5sjdw50vj9gfnrxjbptj4c0000gn/T/tmpmnxl8tjy/test_config.json
2025-06-06 17:04:17,162 - DEBUG - Loaded configuration from /var/folders/3f/2n5sjdw50vj9gfnrxjbptj4c0000gn/T/tmpmnxl8tjy/test_config.json
2025-06-06 17:04:17,162 - DEBUG - Saved configuration to /var/folders/3f/2n5sjdw50vj9gfnrxjbptj4c0000gn/T/tmpmnxl8tjy/test_config.json
2025-06-06 17:04:17,162 - DEBUG - Loaded configuration from /var/folders/3f/2n5sjdw50vj9gfnrxjbptj4c0000gn/T/tmpmnxl8tjy/test_config.json
2025-06-06 17:04:17,164 - DEBUG - Saved configuration to /var/folders/3f/2n5sjdw50vj9gfnrxjbptj4c0000gn/T/tmpw0k3c_36/test_config.json
2025-06-06 17:04:17,164 - DEBUG - Loaded configuration from /var/folders/3f/2n5sjdw50vj9gfnrxjbptj4c0000gn/T/tmpw0k3c_36/test_config.json
2025-06-06 17:04:17,165 - DEBUG - Loaded configuration from /var/folders/3f/2n5sjdw50vj9gfnrxjbptj4c0000gn/T/tmpw0k3c_36/test_config.json
2025-06-06 17:04:17,165 - DEBUG - Saved configuration to /var/folders/3f/2n5sjdw50vj9gfnrxjbptj4c0000gn/T/tmpw0k3c_36/test_config.json
2025-06-06 17:04:17,165 - DEBUG - Loaded configuration from /var/folders/3f/2n5sjdw50vj9gfnrxjbptj4c0000gn/T/tmpw0k3c_36/test_config.json
2025-06-06 17:04:17,170 - DEBUG - Saved configuration to /var/folders/3f/2n5sjdw50vj9gfnrxjbptj4c0000gn/T/tmpjhal4ekg/test_config.json
2025-06-06 17:04:17,171 - DEBUG - Loaded configuration from /var/folders/3f/2n5sjdw50vj9gfnrxjbptj4c0000gn/T/tmpjhal4ekg/test_config.json
2025-06-06 17:04:17,173 - DEBUG - Saved configuration to /var/folders/3f/2n5sjdw50vj9gfnrxjbptj4c0000gn/T/tmpyr3t2liq/test_config.json
2025-06-06 17:04:17,173 - DEBUG - Loaded configuration from /var/folders/3f/2n5sjdw50vj9gfnrxjbptj4c0000gn/T/tmpyr3t2liq/test_config.json
2025-06-06 17:04:17,173 - DEBUG - Loaded configuration from /var/folders/3f/2n5sjdw50vj9gfnrxjbptj4c0000gn/T/tmpyr3t2liq/test_config.json
2025-06-06 17:04:17,174 - DEBUG - Saved configuration to /var/folders/3f/2n5sjdw50vj9gfnrxjbptj4c0000gn/T/tmpyr3t2liq/test_config.json
2025-06-06 17:04:17,177 - ERROR - Error listing tables: API error
2025-06-06 17:04:17,184 - DEBUG - Saved configuration to /var/folders/3f/2n5sjdw50vj9gfnrxjbptj4c0000gn/T/tmpartdyn_m/test_config.json
2025-06-06 17:04:17,184 - DEBUG - Loaded configuration from /var/folders/3f/2n5sjdw50vj9gfnrxjbptj4c0000gn/T/tmpartdyn_m/test_config.json
2025-06-06 17:04:17,184 - DEBUG - Loaded configuration from /var/folders/3f/2n5sjdw50vj9gfnrxjbptj4c0000gn/T/tmpartdyn_m/test_config.json
2025-06-06 17:04:17,188 - DEBUG - Saved configuration to /var/folders/3f/2n5sjdw50vj9gfnrxjbptj4c0000gn/T/tmp9msyb8ix/test_config.json
2025-06-06 17:04:17,188 - DEBUG - Loaded configuration from /var/folders/3f/2n5sjdw50vj9gfnrxjbptj4c0000gn/T/tmp9msyb8ix/test_config.json
2025-06-06 17:04:17,188 - DEBUG - Saved configuration to /var/folders/3f/2n5sjdw50vj9gfnrxjbptj4c0000gn/T/tmp9msyb8ix/test_config.json
2025-06-06 17:04:17,189 - DEBUG - Loaded configuration from /var/folders/3f/2n5sjdw50vj9gfnrxjbptj4c0000gn/T/tmp9msyb8ix/test_config.json
2025-06-06 17:04:17,189 - DEBUG - Loaded configuration from /var/folders/3f/2n5sjdw50vj9gfnrxjbptj4c0000gn/T/tmp9msyb8ix/test_config.json
2025-06-06 17:04:17,195 - ERROR - Error fetching warehouses: API connection error
2025-06-06 17:04:17,208 - ERROR - Failed to set model 'claude-v1': API error
Traceback (most recent call last):
  File "/Users/johnrush/repos/chuck-data/chuck_data/commands/model_selection.py", line 28, in handle_command
    models_list = list_models_api(client)
                  ^^^^^^^^^^^^^^^^^^^^^^^
  File "/Users/johnrush/repos/chuck-data/chuck_data/models.py", line 19, in list_models
    return client.list_models()
           ^^^^^^^^^^^^^^^^^^^^
  File "/Users/johnrush/repos/chuck-data/tests/commands/test_model_selection.py", line 79, in list_models
    raise Exception("API error")
Exception: API error
2025-06-06 17:04:17,210 - DEBUG - Saved configuration to /var/folders/3f/2n5sjdw50vj9gfnrxjbptj4c0000gn/T/tmp5ocw3j17/test_config.json
2025-06-06 17:04:17,211 - DEBUG - Loaded configuration from /var/folders/3f/2n5sjdw50vj9gfnrxjbptj4c0000gn/T/tmp5ocw3j17/test_config.json
2025-06-06 17:04:17,213 - DEBUG - Saved configuration to /var/folders/3f/2n5sjdw50vj9gfnrxjbptj4c0000gn/T/tmph3rt47h8/test_config.json
2025-06-06 17:04:17,213 - DEBUG - Loaded configuration from /var/folders/3f/2n5sjdw50vj9gfnrxjbptj4c0000gn/T/tmph3rt47h8/test_config.json
2025-06-06 17:04:17,216 - DEBUG - Saved configuration to /var/folders/3f/2n5sjdw50vj9gfnrxjbptj4c0000gn/T/tmpmsmi2r8q/test_config.json
2025-06-06 17:04:17,216 - DEBUG - Loaded configuration from /var/folders/3f/2n5sjdw50vj9gfnrxjbptj4c0000gn/T/tmpmsmi2r8q/test_config.json
2025-06-06 17:04:17,221 - DEBUG - Saved configuration to /var/folders/3f/2n5sjdw50vj9gfnrxjbptj4c0000gn/T/tmp24cb06ad/test_config.json
2025-06-06 17:04:17,221 - DEBUG - Loaded configuration from /var/folders/3f/2n5sjdw50vj9gfnrxjbptj4c0000gn/T/tmp24cb06ad/test_config.json
2025-06-06 17:04:17,229 - INFO - Starting PII Scan for 2 tables in test_cat.test_schema.
2025-06-06 17:04:17,240 - ERROR - Bulk PII scan error: LLM client error
Traceback (most recent call last):
  File "/Users/johnrush/repos/chuck-data/chuck_data/commands/scan_pii.py", line 46, in handle_command
    llm_client = LLMClient()
                 ^^^^^^^^^^^
  File "/usr/local/Cellar/python@3.11/3.11.4_1/Frameworks/Python.framework/Versions/3.11/lib/python3.11/unittest/mock.py", line 1124, in __call__
    return self._mock_call(*args, **kwargs)
           ^^^^^^^^^^^^^^^^^^^^^^^^^^^^^^^^
  File "/usr/local/Cellar/python@3.11/3.11.4_1/Frameworks/Python.framework/Versions/3.11/lib/python3.11/unittest/mock.py", line 1128, in _mock_call
    return self._execute_mock_call(*args, **kwargs)
           ^^^^^^^^^^^^^^^^^^^^^^^^^^^^^^^^^^^^^^^^
  File "/usr/local/Cellar/python@3.11/3.11.4_1/Frameworks/Python.framework/Versions/3.11/lib/python3.11/unittest/mock.py", line 1183, in _execute_mock_call
    raise effect
Exception: LLM client error
2025-06-06 17:04:17,250 - DEBUG - Saved configuration to /var/folders/3f/2n5sjdw50vj9gfnrxjbptj4c0000gn/T/tmpvjd2kr2b/test_config.json
2025-06-06 17:04:17,250 - DEBUG - Loaded configuration from /var/folders/3f/2n5sjdw50vj9gfnrxjbptj4c0000gn/T/tmpvjd2kr2b/test_config.json
2025-06-06 17:04:17,250 - ERROR - Failed to set schema: Failed to list schemas
Traceback (most recent call last):
  File "/Users/johnrush/repos/chuck-data/chuck_data/commands/schema_selection.py", line 110, in handle_command
    result = get_schemas_list(client=client, catalog_name=catalog_name)
             ^^^^^^^^^^^^^^^^^^^^^^^^^^^^^^^^^^^^^^^^^^^^^^^^^^^^^^^^^^
  File "/Users/johnrush/repos/chuck-data/chuck_data/catalogs.py", line 56, in list_schemas
    return client.list_schemas(catalog_name, include_browse, max_results, page_token)
           ^^^^^^^^^^^^^^^^^^^^^^^^^^^^^^^^^^^^^^^^^^^^^^^^^^^^^^^^^^^^^^^^^^^^^^^^^^
  File "/Users/johnrush/repos/chuck-data/tests/commands/test_schema_selection.py", line 102, in list_schemas
    raise Exception("Failed to list schemas")
Exception: Failed to list schemas
2025-06-06 17:04:17,253 - DEBUG - Saved configuration to /var/folders/3f/2n5sjdw50vj9gfnrxjbptj4c0000gn/T/tmpxdrjsce9/test_config.json
2025-06-06 17:04:17,254 - DEBUG - Loaded configuration from /var/folders/3f/2n5sjdw50vj9gfnrxjbptj4c0000gn/T/tmpxdrjsce9/test_config.json
2025-06-06 17:04:17,256 - DEBUG - Saved configuration to /var/folders/3f/2n5sjdw50vj9gfnrxjbptj4c0000gn/T/tmpdk2_3pld/test_config.json
2025-06-06 17:04:17,256 - DEBUG - Loaded configuration from /var/folders/3f/2n5sjdw50vj9gfnrxjbptj4c0000gn/T/tmpdk2_3pld/test_config.json
2025-06-06 17:04:17,256 - DEBUG - Loaded configuration from /var/folders/3f/2n5sjdw50vj9gfnrxjbptj4c0000gn/T/tmpdk2_3pld/test_config.json
2025-06-06 17:04:17,257 - DEBUG - Saved configuration to /var/folders/3f/2n5sjdw50vj9gfnrxjbptj4c0000gn/T/tmpdk2_3pld/test_config.json
2025-06-06 17:04:17,257 - DEBUG - Loaded configuration from /var/folders/3f/2n5sjdw50vj9gfnrxjbptj4c0000gn/T/tmpdk2_3pld/test_config.json
2025-06-06 17:04:17,263 - DEBUG - Sending metric: {"event": "USAGE", "configuration": {"workspace_url": "https://dbc-df998298-4c7e.cloud.databricks.co...
2025-06-06 17:04:17,266 - DEBUG - Starting new HTTPS connection (1): chuck.amperity.com:443
2025-06-06 17:04:17,387 - DEBUG - https://chuck.amperity.com:443 "POST /api/usage HTTP/1.1" 204 0
2025-06-06 17:04:17,388 - DEBUG - Failed to send metrics: 204 - 
2025-06-06 17:04:17,391 - ERROR - Stitch setup error: LLM client error
Traceback (most recent call last):
  File "/Users/johnrush/repos/chuck-data/chuck_data/commands/setup_stitch.py", line 111, in handle_command
    return _phase_1_prepare_config(
           ^^^^^^^^^^^^^^^^^^^^^^^^
  File "/Users/johnrush/repos/chuck-data/chuck_data/commands/setup_stitch.py", line 273, in _phase_1_prepare_config
    llm_client = LLMClient()
                 ^^^^^^^^^^^
  File "/usr/local/Cellar/python@3.11/3.11.4_1/Frameworks/Python.framework/Versions/3.11/lib/python3.11/unittest/mock.py", line 1124, in __call__
    return self._mock_call(*args, **kwargs)
           ^^^^^^^^^^^^^^^^^^^^^^^^^^^^^^^^
  File "/usr/local/Cellar/python@3.11/3.11.4_1/Frameworks/Python.framework/Versions/3.11/lib/python3.11/unittest/mock.py", line 1128, in _mock_call
    return self._execute_mock_call(*args, **kwargs)
           ^^^^^^^^^^^^^^^^^^^^^^^^^^^^^^^^^^^^^^^^
  File "/usr/local/Cellar/python@3.11/3.11.4_1/Frameworks/Python.framework/Versions/3.11/lib/python3.11/unittest/mock.py", line 1183, in _execute_mock_call
    raise effect
Exception: LLM client error
2025-06-06 17:04:17,404 - DEBUG - GET request to: https://.cloud.databricks.com/api/2.0/preview/scim/v2/Me
2025-06-06 17:04:17,405 - DEBUG - Connection error: URL has an invalid label.
2025-06-06 17:04:17,405 - DEBUG - Token validation failed: Connection error occurred: URL has an invalid label.
2025-06-06 17:04:17,409 - ERROR - Error validating token: Connection failed
2025-06-06 17:04:17,416 - DEBUG - GET request to: https://invalid-workspace.nonexistent.com.cloud.databricks.com/api/2.0/preview/scim/v2/Me
2025-06-06 17:04:17,418 - DEBUG - Starting new HTTPS connection (1): invalid-workspace.nonexistent.com.cloud.databricks.com:443
2025-06-06 17:04:17,420 - DEBUG - Connection error: HTTPSConnectionPool(host='invalid-workspace.nonexistent.com.cloud.databricks.com', port=443): Max retries exceeded with url: /api/2.0/preview/scim/v2/Me (Caused by NameResolutionError("<urllib3.connection.HTTPSConnection object at 0x10ea16750>: Failed to resolve 'invalid-workspace.nonexistent.com.cloud.databricks.com' ([Errno 8] nodename nor servname provided, or not known)"))
2025-06-06 17:04:17,420 - DEBUG - Token validation failed: Connection error occurred: HTTPSConnectionPool(host='invalid-workspace.nonexistent.com.cloud.databricks.com', port=443): Max retries exceeded with url: /api/2.0/preview/scim/v2/Me (Caused by NameResolutionError("<urllib3.connection.HTTPSConnection object at 0x10ea16750>: Failed to resolve 'invalid-workspace.nonexistent.com.cloud.databricks.com' ([Errno 8] nodename nor servname provided, or not known)"))
2025-06-06 17:04:17,532 - DEBUG - GET request to: https://invalid.nonexistent.com.cloud.databricks.com/api/2.0/preview/scim/v2/Me
2025-06-06 17:04:17,535 - DEBUG - Starting new HTTPS connection (1): invalid.nonexistent.com.cloud.databricks.com:443
2025-06-06 17:04:17,536 - DEBUG - Connection error: HTTPSConnectionPool(host='invalid.nonexistent.com.cloud.databricks.com', port=443): Max retries exceeded with url: /api/2.0/preview/scim/v2/Me (Caused by NameResolutionError("<urllib3.connection.HTTPSConnection object at 0x10e68d0d0>: Failed to resolve 'invalid.nonexistent.com.cloud.databricks.com' ([Errno 8] nodename nor servname provided, or not known)"))
2025-06-06 17:04:17,536 - DEBUG - Token validation failed: Connection error occurred: HTTPSConnectionPool(host='invalid.nonexistent.com.cloud.databricks.com', port=443): Max retries exceeded with url: /api/2.0/preview/scim/v2/Me (Caused by NameResolutionError("<urllib3.connection.HTTPSConnection object at 0x10e68d0d0>: Failed to resolve 'invalid.nonexistent.com.cloud.databricks.com' ([Errno 8] nodename nor servname provided, or not known)"))
2025-06-06 17:04:17,537 - ERROR - Error validating token: Validation failed
2025-06-06 17:04:17,660 - ERROR - Error validating token: Connection failed
2025-06-06 17:04:17,696 - ERROR - Error validating token: Network error with secret details
2025-06-06 17:04:17,735 - ERROR - Error validating token: Connection error: Failed to resolve 'workspace123.cloud.databricks.com'
2025-06-06 17:04:17,751 - ERROR - Error fetching Amperity init script: API Error
Traceback (most recent call last):
  File "/Users/johnrush/repos/chuck-data/chuck_data/commands/stitch_tools.py", line 179, in _helper_prepare_stitch_config
    init_script_data = client.fetch_amperity_job_init(amperity_token)
                       ^^^^^^^^^^^^^^^^^^^^^^^^^^^^^^^^^^^^^^^^^^^^^^
  File "/usr/local/Cellar/python@3.11/3.11.4_1/Frameworks/Python.framework/Versions/3.11/lib/python3.11/unittest/mock.py", line 1124, in __call__
    return self._mock_call(*args, **kwargs)
           ^^^^^^^^^^^^^^^^^^^^^^^^^^^^^^^^
  File "/usr/local/Cellar/python@3.11/3.11.4_1/Frameworks/Python.framework/Versions/3.11/lib/python3.11/unittest/mock.py", line 1128, in _mock_call
    return self._execute_mock_call(*args, **kwargs)
           ^^^^^^^^^^^^^^^^^^^^^^^^^^^^^^^^^^^^^^^^
  File "/usr/local/Cellar/python@3.11/3.11.4_1/Frameworks/Python.framework/Versions/3.11/lib/python3.11/unittest/mock.py", line 1183, in _execute_mock_call
    raise effect
Exception: API Error
2025-06-06 17:04:17,763 - DEBUG - Versioned cluster init script uploaded to /Volumes/test_catalog/test_schema/chuck/cluster_init-2025-06-02_14-30.sh
2025-06-06 17:04:17,766 - DEBUG - Versioned cluster init script uploaded to /Volumes/test_catalog/test_schema/chuck/cluster_init-2025-06-02_14-30.sh
2025-06-06 17:04:17,770 - DEBUG - Volume 'chuck' not found in test_catalog.test_schema. Attempting to create.
2025-06-06 17:04:17,783 - DEBUG - Saved configuration to /var/folders/3f/2n5sjdw50vj9gfnrxjbptj4c0000gn/T/tmpe5at4q_h/test_config.json
2025-06-06 17:04:17,783 - DEBUG - Loaded configuration from /var/folders/3f/2n5sjdw50vj9gfnrxjbptj4c0000gn/T/tmpe5at4q_h/test_config.json
2025-06-06 17:04:17,783 - DEBUG - Loaded configuration from /var/folders/3f/2n5sjdw50vj9gfnrxjbptj4c0000gn/T/tmpe5at4q_h/test_config.json
2025-06-06 17:04:17,783 - DEBUG - Loaded configuration from /var/folders/3f/2n5sjdw50vj9gfnrxjbptj4c0000gn/T/tmpe5at4q_h/test_config.json
2025-06-06 17:04:17,786 - DEBUG - Saved configuration to /var/folders/3f/2n5sjdw50vj9gfnrxjbptj4c0000gn/T/tmptv944xj7/test_config.json
2025-06-06 17:04:17,786 - DEBUG - Loaded configuration from /var/folders/3f/2n5sjdw50vj9gfnrxjbptj4c0000gn/T/tmptv944xj7/test_config.json
2025-06-06 17:04:17,786 - DEBUG - Saved configuration to /var/folders/3f/2n5sjdw50vj9gfnrxjbptj4c0000gn/T/tmptv944xj7/test_config.json
2025-06-06 17:04:17,786 - DEBUG - Loaded configuration from /var/folders/3f/2n5sjdw50vj9gfnrxjbptj4c0000gn/T/tmptv944xj7/test_config.json
2025-06-06 17:04:17,787 - DEBUG - Saved configuration to /var/folders/3f/2n5sjdw50vj9gfnrxjbptj4c0000gn/T/tmptv944xj7/test_config.json
2025-06-06 17:04:17,787 - DEBUG - Loaded configuration from /var/folders/3f/2n5sjdw50vj9gfnrxjbptj4c0000gn/T/tmptv944xj7/test_config.json
2025-06-06 17:04:17,787 - DEBUG - Loaded configuration from /var/folders/3f/2n5sjdw50vj9gfnrxjbptj4c0000gn/T/tmptv944xj7/test_config.json
2025-06-06 17:04:17,787 - DEBUG - Loaded configuration from /var/folders/3f/2n5sjdw50vj9gfnrxjbptj4c0000gn/T/tmptv944xj7/test_config.json
2025-06-06 17:04:17,789 - INFO - Applying tag 'email' to column 'email_col'
2025-06-06 17:04:17,789 - INFO - Applying tag 'given-name' to column 'name_col'
2025-06-06 17:04:17,791 - INFO - Applying tag 'phone' to column 'good_col'
2025-06-06 17:04:17,792 - INFO - Applying tag 'email' to column 'email_col'
2025-06-06 17:04:17,794 - INFO - Applying tag 'email' to column 'email_col'
2025-06-06 17:04:17,794 - ERROR - Error applying tag to email_col: Connection error
2025-06-06 17:04:17,798 - DEBUG - Saved configuration to /var/folders/3f/2n5sjdw50vj9gfnrxjbptj4c0000gn/T/tmp4eo2nj99/test_config.json
2025-06-06 17:04:17,799 - DEBUG - Loaded configuration from /var/folders/3f/2n5sjdw50vj9gfnrxjbptj4c0000gn/T/tmp4eo2nj99/test_config.json
2025-06-06 17:04:17,801 - DEBUG - Saved configuration to /var/folders/3f/2n5sjdw50vj9gfnrxjbptj4c0000gn/T/tmpaowkyt2e/test_config.json
2025-06-06 17:04:17,802 - ERROR - Failed to set warehouse: Failed to list warehouses
Traceback (most recent call last):
  File "/Users/johnrush/repos/chuck-data/chuck_data/commands/warehouse_selection.py", line 106, in handle_command
    warehouses = client.list_warehouses()
                 ^^^^^^^^^^^^^^^^^^^^^^^^
  File "/Users/johnrush/repos/chuck-data/tests/commands/test_warehouse_selection.py", line 110, in list_warehouses
    raise Exception("Failed to list warehouses")
Exception: Failed to list warehouses
2025-06-06 17:04:17,805 - DEBUG - Saved configuration to /var/folders/3f/2n5sjdw50vj9gfnrxjbptj4c0000gn/T/tmp02oy2p9m/test_config.json
2025-06-06 17:04:17,815 - ERROR - Failed to set workspace URL: Validation error
Traceback (most recent call last):
  File "/Users/johnrush/repos/chuck-data/chuck_data/commands/workspace_selection.py", line 37, in handle_command
    is_valid, error_message = validate_workspace_url(workspace_url)
                              ^^^^^^^^^^^^^^^^^^^^^^^^^^^^^^^^^^^^^
  File "/usr/local/Cellar/python@3.11/3.11.4_1/Frameworks/Python.framework/Versions/3.11/lib/python3.11/unittest/mock.py", line 1124, in __call__
    return self._mock_call(*args, **kwargs)
           ^^^^^^^^^^^^^^^^^^^^^^^^^^^^^^^^
  File "/usr/local/Cellar/python@3.11/3.11.4_1/Frameworks/Python.framework/Versions/3.11/lib/python3.11/unittest/mock.py", line 1128, in _mock_call
    return self._execute_mock_call(*args, **kwargs)
           ^^^^^^^^^^^^^^^^^^^^^^^^^^^^^^^^^^^^^^^^
  File "/usr/local/Cellar/python@3.11/3.11.4_1/Frameworks/Python.framework/Versions/3.11/lib/python3.11/unittest/mock.py", line 1183, in _execute_mock_call
    raise effect
Exception: Validation error
