2025-06-05 12:19:53,279 - DEBUG - Logging initialized. Writing to /Users/johnrush/repos/chuck-data/log/sessions/2025-06-05_12-19-53.log
2025-06-05 12:19:53,283 - DEBUG - HTTP error: HTTP 401, Response: {"status":401,"message":"Unauthorized"}
2025-06-05 12:19:53,285 - DEBUG - GET request to: https://test-workspace.cloud.databricks.com/test-endpoint
2025-06-05 12:19:53,285 - DEBUG - Connection error: Connection failed
2025-06-05 12:19:53,286 - DEBUG - GET request to: https://test-workspace.cloud.databricks.com/test-endpoint
2025-06-05 12:19:53,286 - DEBUG - HTTP error: HTTP 404, Response: Not Found
2025-06-05 12:19:53,287 - DEBUG - GET request to: https://test-workspace.cloud.databricks.com/test-endpoint
2025-06-05 12:19:53,288 - DEBUG - POST request to: https://test-workspace.cloud.databricks.com/test-endpoint
2025-06-05 12:19:53,288 - DEBUG - Connection error: Connection failed
2025-06-05 12:19:53,290 - DEBUG - POST request to: https://test-workspace.cloud.databricks.com/test-endpoint
2025-06-05 12:19:53,290 - DEBUG - HTTP error: HTTP 400, Response: Bad Request
2025-06-05 12:19:53,291 - DEBUG - POST request to: https://test-workspace.cloud.databricks.com/test-endpoint
2025-06-05 12:19:53,295 - DEBUG - Saved configuration to /var/folders/3f/2n5sjdw50vj9gfnrxjbptj4c0000gn/T/tmpgbv5zyw4/test_config.json
2025-06-05 12:19:53,295 - DEBUG - Loaded configuration from /var/folders/3f/2n5sjdw50vj9gfnrxjbptj4c0000gn/T/tmpgbv5zyw4/test_config.json
2025-06-05 12:19:53,295 - DEBUG - Loaded configuration from /var/folders/3f/2n5sjdw50vj9gfnrxjbptj4c0000gn/T/tmpgbv5zyw4/test_config.json
2025-06-05 12:19:53,296 - DEBUG - Saved configuration to /var/folders/3f/2n5sjdw50vj9gfnrxjbptj4c0000gn/T/tmpgbv5zyw4/test_config.json
2025-06-05 12:19:53,296 - DEBUG - Loaded configuration from /var/folders/3f/2n5sjdw50vj9gfnrxjbptj4c0000gn/T/tmpgbv5zyw4/test_config.json
2025-06-05 12:19:53,296 - DEBUG - Saved configuration to /var/folders/3f/2n5sjdw50vj9gfnrxjbptj4c0000gn/T/tmpgbv5zyw4/test_config.json
2025-06-05 12:19:53,296 - DEBUG - Loaded configuration from /var/folders/3f/2n5sjdw50vj9gfnrxjbptj4c0000gn/T/tmpgbv5zyw4/test_config.json
2025-06-05 12:19:53,297 - DEBUG - Saved configuration to /var/folders/3f/2n5sjdw50vj9gfnrxjbptj4c0000gn/T/tmpgbv5zyw4/test_config.json
2025-06-05 12:19:53,297 - DEBUG - Loaded configuration from /var/folders/3f/2n5sjdw50vj9gfnrxjbptj4c0000gn/T/tmpgbv5zyw4/test_config.json
2025-06-05 12:19:53,297 - DEBUG - Saved configuration to /var/folders/3f/2n5sjdw50vj9gfnrxjbptj4c0000gn/T/tmpgbv5zyw4/test_config.json
2025-06-05 12:19:53,298 - DEBUG - Loaded configuration from /var/folders/3f/2n5sjdw50vj9gfnrxjbptj4c0000gn/T/tmpgbv5zyw4/test_config.json
2025-06-05 12:19:53,298 - DEBUG - Loaded configuration from /var/folders/3f/2n5sjdw50vj9gfnrxjbptj4c0000gn/T/tmpgbv5zyw4/test_config.json
2025-06-05 12:19:53,298 - DEBUG - Loaded configuration from /var/folders/3f/2n5sjdw50vj9gfnrxjbptj4c0000gn/T/tmpgbv5zyw4/test_config.json
2025-06-05 12:19:53,298 - DEBUG - Loaded configuration from /var/folders/3f/2n5sjdw50vj9gfnrxjbptj4c0000gn/T/tmpgbv5zyw4/test_config.json
2025-06-05 12:19:53,298 - DEBUG - Loaded configuration from /var/folders/3f/2n5sjdw50vj9gfnrxjbptj4c0000gn/T/tmpgbv5zyw4/test_config.json
2025-06-05 12:19:53,300 - DEBUG - Saved configuration to /var/folders/3f/2n5sjdw50vj9gfnrxjbptj4c0000gn/T/tmpxpe111fx/test_config.json
2025-06-05 12:19:53,300 - DEBUG - Loaded configuration from /var/folders/3f/2n5sjdw50vj9gfnrxjbptj4c0000gn/T/tmpxpe111fx/test_config.json
2025-06-05 12:19:53,302 - DEBUG - Saved configuration to /var/folders/3f/2n5sjdw50vj9gfnrxjbptj4c0000gn/T/tmpgwxpkv4o/test_config.json
2025-06-05 12:19:53,302 - DEBUG - Loaded configuration from /var/folders/3f/2n5sjdw50vj9gfnrxjbptj4c0000gn/T/tmpgwxpkv4o/test_config.json
2025-06-05 12:19:53,304 - DEBUG - Saved configuration to /var/folders/3f/2n5sjdw50vj9gfnrxjbptj4c0000gn/T/tmpo04y8qba/test_config.json
2025-06-05 12:19:53,304 - DEBUG - Loaded configuration from /var/folders/3f/2n5sjdw50vj9gfnrxjbptj4c0000gn/T/tmpo04y8qba/test_config.json
2025-06-05 12:19:53,304 - DEBUG - Loaded configuration from /var/folders/3f/2n5sjdw50vj9gfnrxjbptj4c0000gn/T/tmpo04y8qba/test_config.json
2025-06-05 12:19:53,304 - DEBUG - Saved configuration to /var/folders/3f/2n5sjdw50vj9gfnrxjbptj4c0000gn/T/tmpo04y8qba/test_config.json
2025-06-05 12:19:53,304 - DEBUG - Loaded configuration from /var/folders/3f/2n5sjdw50vj9gfnrxjbptj4c0000gn/T/tmpo04y8qba/test_config.json
2025-06-05 12:19:53,305 - DEBUG - Loaded configuration from /var/folders/3f/2n5sjdw50vj9gfnrxjbptj4c0000gn/T/tmpo04y8qba/test_config.json
2025-06-05 12:19:53,308 - DEBUG - Saved configuration to /var/folders/3f/2n5sjdw50vj9gfnrxjbptj4c0000gn/T/tmp740g_sw1/test_config.json
2025-06-05 12:19:53,308 - DEBUG - Loaded configuration from /var/folders/3f/2n5sjdw50vj9gfnrxjbptj4c0000gn/T/tmp740g_sw1/test_config.json
2025-06-05 12:19:53,308 - DEBUG - Loaded configuration from /var/folders/3f/2n5sjdw50vj9gfnrxjbptj4c0000gn/T/tmp740g_sw1/test_config.json
2025-06-05 12:19:53,308 - DEBUG - Saved configuration to /var/folders/3f/2n5sjdw50vj9gfnrxjbptj4c0000gn/T/tmp740g_sw1/test_config.json
2025-06-05 12:19:53,308 - DEBUG - Loaded configuration from /var/folders/3f/2n5sjdw50vj9gfnrxjbptj4c0000gn/T/tmp740g_sw1/test_config.json
2025-06-05 12:19:53,309 - DEBUG - Saved configuration to /var/folders/3f/2n5sjdw50vj9gfnrxjbptj4c0000gn/T/tmp740g_sw1/test_config.json
2025-06-05 12:19:53,309 - DEBUG - Loaded configuration from /var/folders/3f/2n5sjdw50vj9gfnrxjbptj4c0000gn/T/tmp740g_sw1/test_config.json
2025-06-05 12:19:53,309 - DEBUG - Saved configuration to /var/folders/3f/2n5sjdw50vj9gfnrxjbptj4c0000gn/T/tmp740g_sw1/test_config.json
2025-06-05 12:19:53,309 - DEBUG - Loaded configuration from /var/folders/3f/2n5sjdw50vj9gfnrxjbptj4c0000gn/T/tmp740g_sw1/test_config.json
2025-06-05 12:19:53,310 - DEBUG - Saved configuration to /var/folders/3f/2n5sjdw50vj9gfnrxjbptj4c0000gn/T/tmp740g_sw1/test_config.json
2025-06-05 12:19:53,310 - DEBUG - Loaded configuration from /var/folders/3f/2n5sjdw50vj9gfnrxjbptj4c0000gn/T/tmp740g_sw1/test_config.json
2025-06-05 12:19:53,310 - DEBUG - Using workspace_url from environment variable CHUCK_WORKSPACE_URL
2025-06-05 12:19:53,310 - DEBUG - Using active_model from environment variable CHUCK_ACTIVE_MODEL
2025-06-05 12:19:53,310 - DEBUG - Using warehouse_id from environment variable CHUCK_WAREHOUSE_ID
2025-06-05 12:19:53,310 - DEBUG - Using active_catalog from environment variable CHUCK_ACTIVE_CATALOG
2025-06-05 12:19:53,310 - DEBUG - Using active_schema from environment variable CHUCK_ACTIVE_SCHEMA
2025-06-05 12:19:53,310 - DEBUG - Using usage_tracking_consent from environment variable CHUCK_USAGE_TRACKING_CONSENT
2025-06-05 12:19:53,310 - DEBUG - Loaded configuration from /var/folders/3f/2n5sjdw50vj9gfnrxjbptj4c0000gn/T/tmp740g_sw1/test_config.json
2025-06-05 12:19:53,312 - DEBUG - Saved configuration to /var/folders/3f/2n5sjdw50vj9gfnrxjbptj4c0000gn/T/tmphtlddv2k/test_config.json
2025-06-05 12:19:53,312 - DEBUG - Loaded configuration from /var/folders/3f/2n5sjdw50vj9gfnrxjbptj4c0000gn/T/tmphtlddv2k/test_config.json
2025-06-05 12:19:53,312 - DEBUG - Loaded configuration from /var/folders/3f/2n5sjdw50vj9gfnrxjbptj4c0000gn/T/tmphtlddv2k/test_config.json
2025-06-05 12:19:53,312 - WARNING - Invalid workspace_url provided, using default instead
2025-06-05 12:19:53,312 - DEBUG - Saved configuration to /var/folders/3f/2n5sjdw50vj9gfnrxjbptj4c0000gn/T/tmphtlddv2k/test_config.json
2025-06-05 12:19:53,313 - DEBUG - Loaded configuration from /var/folders/3f/2n5sjdw50vj9gfnrxjbptj4c0000gn/T/tmphtlddv2k/test_config.json
2025-06-05 12:19:53,313 - DEBUG - Loaded configuration from /var/folders/3f/2n5sjdw50vj9gfnrxjbptj4c0000gn/T/tmphtlddv2k/test_config.json
2025-06-05 12:19:53,313 - DEBUG - Saved configuration to /var/folders/3f/2n5sjdw50vj9gfnrxjbptj4c0000gn/T/tmphtlddv2k/test_config.json
2025-06-05 12:19:53,313 - DEBUG - Loaded configuration from /var/folders/3f/2n5sjdw50vj9gfnrxjbptj4c0000gn/T/tmphtlddv2k/test_config.json
2025-06-05 12:19:53,315 - DEBUG - Using workspace_url from environment variable CHUCK_WORKSPACE_URL
2025-06-05 12:19:53,315 - DEBUG - Using workspace_url from environment variable CHUCK_WORKSPACE_URL
2025-06-05 12:19:53,315 - DEBUG - Using active_model from environment variable CHUCK_ACTIVE_MODEL
2025-06-05 12:19:53,315 - DEBUG - Using amperity_token from environment variable CHUCK_AMPERITY_TOKEN
2025-06-05 12:19:53,315 - DEBUG - Using databricks_token from environment variable CHUCK_DATABRICKS_TOKEN
2025-06-05 12:19:53,315 - DEBUG - Saved configuration to /var/folders/3f/2n5sjdw50vj9gfnrxjbptj4c0000gn/T/tmpks2fw2w_/test_config.json
2025-06-05 12:19:53,316 - DEBUG - Loaded configuration from /var/folders/3f/2n5sjdw50vj9gfnrxjbptj4c0000gn/T/tmpks2fw2w_/test_config.json
2025-06-05 12:19:53,317 - DEBUG - Saved configuration to /var/folders/3f/2n5sjdw50vj9gfnrxjbptj4c0000gn/T/tmpb__zchz8/test_config.json
2025-06-05 12:19:53,329 - DEBUG - GET request to: https://adb-3856707039489412.12.azuredatabricks.net/test-endpoint
2025-06-05 12:19:53,332 - DEBUG - GET request to: https://test-workspace.cloud.databricks.com/test-endpoint
2025-06-05 12:19:53,332 - DEBUG - Connection error: Connection failed
2025-06-05 12:19:53,333 - DEBUG - GET request to: https://test-workspace.cloud.databricks.com/test-endpoint
2025-06-05 12:19:53,333 - DEBUG - HTTP error: HTTP 404, Response: Not Found
2025-06-05 12:19:53,335 - WARNING - Model 'nonexistent-model' not found
2025-06-05 12:19:53,336 - DEBUG - GET request to: https://test-workspace.cloud.databricks.com/test-endpoint
2025-06-05 12:19:53,342 - DEBUG - POST request to: https://test-workspace.cloud.databricks.com/test-endpoint
2025-06-05 12:19:53,342 - DEBUG - Connection error: Connection failed
2025-06-05 12:19:53,343 - DEBUG - POST request to: https://test-workspace.cloud.databricks.com/test-endpoint
2025-06-05 12:19:53,343 - DEBUG - HTTP error: HTTP 400, Response: Bad Request
2025-06-05 12:19:53,344 - DEBUG - POST request to: https://test-workspace.cloud.databricks.com/test-endpoint
2025-06-05 12:19:53,346 - DEBUG - File upload request to: https://test-workspace.cloud.databricks.com/api/2.0/fs/files/test/path.txt
2025-06-05 12:19:53,348 - DEBUG - File upload request to: https://test-workspace.cloud.databricks.com/api/2.0/fs/files/test/path.txt
2025-06-05 12:19:53,350 - DEBUG - Token validation failed: Token validation failed
2025-06-05 12:19:53,352 - DEBUG - Saved configuration to /tmp/.test_chuck_integration_config.json
2025-06-05 12:19:53,352 - DEBUG - Saved configuration to /tmp/.test_chuck_integration_config.json
2025-06-05 12:19:53,353 - DEBUG - Saved configuration to /tmp/.test_chuck_integration_config.json
2025-06-05 12:19:53,354 - DEBUG - Saved configuration to /tmp/.test_chuck_integration_config.json
2025-06-05 12:19:53,355 - DEBUG - Saved configuration to /tmp/.test_chuck_integration_config.json
2025-06-05 12:19:53,355 - DEBUG - Saved configuration to /tmp/.test_chuck_integration_config.json
2025-06-05 12:19:53,360 - DEBUG - Sending metric: {"event": "USAGE", "prompt": "test prompt"}...
2025-06-05 12:19:53,360 - DEBUG - Error sending metrics: Test exception
Traceback (most recent call last):
  File "/Users/johnrush/repos/chuck-data/src/metrics_collector.py", line 123, in send_metric
    return self._client.submit_metrics(payload, token)
           ^^^^^^^^^^^^^^^^^^^^^^^^^^^^^^^^^^^^^^^^^^^
  File "/Users/johnrush/repos/chuck-data/tests/fixtures.py", line 60, in submit_metrics
    raise Exception("Test exception")
Exception: Test exception
2025-06-05 12:19:53,361 - DEBUG - Sending metric: {"event": "USAGE", "prompt": "test prompt"}...
2025-06-05 12:19:53,362 - DEBUG - Cannot send metrics - no authentication token available
2025-06-05 12:19:53,363 - DEBUG - Sending metric: {"event": "USAGE", "prompt": "test prompt"}...
2025-06-05 12:19:53,366 - DEBUG - Metrics tracking skipped - user has not provided consent
2025-06-05 12:19:53,368 - ERROR - Connection error when getting model: Connection failed
2025-06-05 12:19:53,369 - ERROR - Failed to get model: HTTP error occurred: 500 Internal Server Error
2025-06-05 12:19:53,371 - ERROR - Connection error when listing models: Connection failed
2025-06-05 12:19:53,372 - ERROR - Failed to list models: HTTP error occurred: 404 Not Found
2025-06-05 12:19:53,408 - ERROR - Error executing handler for command 'test_command': Command failed
Traceback (most recent call last):
  File "/Users/johnrush/repos/chuck-data/src/service.py", line 395, in execute_command
    result: CommandResult = command_def.handler(
                            ^^^^^^^^^^^^^^^^^^^^
  File "/usr/local/Cellar/python@3.11/3.11.4_1/Frameworks/Python.framework/Versions/3.11/lib/python3.11/unittest/mock.py", line 1124, in __call__
    return self._mock_call(*args, **kwargs)
           ^^^^^^^^^^^^^^^^^^^^^^^^^^^^^^^^
  File "/usr/local/Cellar/python@3.11/3.11.4_1/Frameworks/Python.framework/Versions/3.11/lib/python3.11/unittest/mock.py", line 1128, in _mock_call
    return self._execute_mock_call(*args, **kwargs)
           ^^^^^^^^^^^^^^^^^^^^^^^^^^^^^^^^^^^^^^^^
  File "/usr/local/Cellar/python@3.11/3.11.4_1/Frameworks/Python.framework/Versions/3.11/lib/python3.11/unittest/mock.py", line 1183, in _execute_mock_call
    raise effect
Exception: Command failed
2025-06-05 12:19:53,438 - DEBUG - Executing SQL: SELECT * INVALID SQL
2025-06-05 12:19:53,439 - DEBUG - Executing SQL: SELECT * INVALID SQL
2025-06-05 12:19:53,440 - DEBUG - Executing SQL: SELECT * FROM table
2025-06-05 12:19:53,441 - DEBUG - Executing SQL: SELECT * FROM table
2025-06-05 12:19:53,442 - DEBUG - Executing SQL: SELECT * FROM table
2025-06-05 12:19:53,443 - DEBUG - Executing SQL: SELECT * FROM table
2025-06-05 12:19:53,448 - ERROR - Authentication state polling received 401
2025-06-05 12:19:53,451 - ERROR - Error creating Stitch report: API Error
Traceback (most recent call last):
  File "/Users/johnrush/repos/chuck-data/src/commands/add_stitch_report.py", line 62, in handle_command
    result = client.create_stitch_notebook(table_path, custom_name)
             ^^^^^^^^^^^^^^^^^^^^^^^^^^^^^^^^^^^^^^^^^^^^^^^^^^^^^^
  File "/Users/johnrush/repos/chuck-data/tests/fixtures.py", line 509, in create_stitch_notebook
    raise self._create_stitch_notebook_error
ValueError: API Error
2025-06-05 12:19:53,455 - ERROR - Agent error: Agent error
Traceback (most recent call last):
  File "/Users/johnrush/repos/chuck-data/src/commands/agent.py", line 79, in handle_command
    agent = AgentManager(client, tool_output_callback=tool_output_callback)
            ^^^^^^^^^^^^^^^^^^^^^^^^^^^^^^^^^^^^^^^^^^^^^^^^^^^^^^^^^^^^^^^
  File "/usr/local/Cellar/python@3.11/3.11.4_1/Frameworks/Python.framework/Versions/3.11/lib/python3.11/unittest/mock.py", line 1124, in __call__
    return self._mock_call(*args, **kwargs)
           ^^^^^^^^^^^^^^^^^^^^^^^^^^^^^^^^
  File "/usr/local/Cellar/python@3.11/3.11.4_1/Frameworks/Python.framework/Versions/3.11/lib/python3.11/unittest/mock.py", line 1128, in _mock_call
    return self._execute_mock_call(*args, **kwargs)
           ^^^^^^^^^^^^^^^^^^^^^^^^^^^^^^^^^^^^^^^^
  File "/usr/local/Cellar/python@3.11/3.11.4_1/Frameworks/Python.framework/Versions/3.11/lib/python3.11/unittest/mock.py", line 1183, in _execute_mock_call
    raise effect
Exception: Agent error
2025-06-05 12:19:53,457 - DEBUG - Sending metric: {"event": "USAGE", "configuration": {"workspace_url": "https://dbc-df998298-4c7e.cloud.databricks.co...
2025-06-05 12:19:53,538 - DEBUG - Starting new HTTPS connection (1): chuck.amperity.com:443
2025-06-05 12:19:53,641 - DEBUG - https://chuck.amperity.com:443 "POST /api/usage HTTP/1.1" 204 0
2025-06-05 12:19:53,641 - DEBUG - Failed to send metrics: 204 - 
2025-06-05 12:19:53,644 - DEBUG - Sending metric: {"event": "USAGE", "configuration": {"workspace_url": "https://dbc-df998298-4c7e.cloud.databricks.co...
2025-06-05 12:19:53,647 - DEBUG - Starting new HTTPS connection (1): chuck.amperity.com:443
2025-06-05 12:19:53,732 - DEBUG - https://chuck.amperity.com:443 "POST /api/usage HTTP/1.1" 204 0
2025-06-05 12:19:53,733 - DEBUG - Failed to send metrics: 204 - 
2025-06-05 12:19:53,744 - DEBUG - Sending metric: {"event": "USAGE", "configuration": {"workspace_url": "https://dbc-df998298-4c7e.cloud.databricks.co...
2025-06-05 12:19:53,747 - DEBUG - Starting new HTTPS connection (1): chuck.amperity.com:443
2025-06-05 12:19:53,817 - DEBUG - https://chuck.amperity.com:443 "POST /api/usage HTTP/1.1" 204 0
2025-06-05 12:19:53,818 - DEBUG - Failed to send metrics: 204 - 
2025-06-05 12:19:53,821 - DEBUG - Sending metric: {"event": "USAGE", "configuration": {"workspace_url": "https://dbc-df998298-4c7e.cloud.databricks.co...
2025-06-05 12:19:53,824 - DEBUG - Starting new HTTPS connection (1): chuck.amperity.com:443
2025-06-05 12:19:53,897 - DEBUG - https://chuck.amperity.com:443 "POST /api/usage HTTP/1.1" 204 0
2025-06-05 12:19:53,898 - DEBUG - Failed to send metrics: 204 - 
2025-06-05 12:19:53,901 - DEBUG - Sending metric: {"event": "USAGE", "configuration": {"workspace_url": "https://dbc-df998298-4c7e.cloud.databricks.co...
2025-06-05 12:19:53,904 - DEBUG - Starting new HTTPS connection (1): chuck.amperity.com:443
2025-06-05 12:19:53,973 - DEBUG - https://chuck.amperity.com:443 "POST /api/usage HTTP/1.1" 204 0
2025-06-05 12:19:53,973 - DEBUG - Failed to send metrics: 204 - 
2025-06-05 12:19:53,983 - INFO - Databricks token set successfully
2025-06-05 12:19:53,985 - INFO - Databricks token cleared
2025-06-05 12:19:53,986 - INFO - Amperity token cleared
2025-06-05 12:19:53,987 - INFO - Amperity token cleared
2025-06-05 12:19:53,989 - INFO - Databricks token cleared
2025-06-05 12:19:53,991 - INFO - Amperity token cleared
2025-06-05 12:19:54,003 - DEBUG - Bug report submitted successfully
2025-06-05 12:19:54,056 - ERROR - Error submitting bug report: Network error
Traceback (most recent call last):
  File "/Users/johnrush/repos/chuck-data/src/commands/bug.py", line 72, in handle_command
    success, message = amperity_client.submit_bug_report(payload, amperity_token)
                       ^^^^^^^^^^^^^^^^^^^^^^^^^^^^^^^^^^^^^^^^^^^^^^^^^^^^^^^^^^
  File "/Users/johnrush/repos/chuck-data/tests/commands/test_bug.py", line 115, in submit_bug_report
    raise Exception("Network error")
Exception: Network error
2025-06-05 12:19:54,058 - DEBUG - Loaded configuration from /var/folders/3f/2n5sjdw50vj9gfnrxjbptj4c0000gn/T/tmponaqgxj0.json
2025-06-05 12:19:54,060 - DEBUG - Loaded configuration from /var/folders/3f/2n5sjdw50vj9gfnrxjbptj4c0000gn/T/tmpz0xjv0ip.json
2025-06-05 12:19:54,067 - DEBUG - Bug report submitted successfully
2025-06-05 12:19:54,069 - ERROR - Error saving config: [Errno 30] Read-only file system: '/invalid'
2025-06-05 12:19:54,070 - DEBUG - Saved configuration to /var/folders/3f/2n5sjdw50vj9gfnrxjbptj4c0000gn/T/tmpj4d7_1lz/test_config.json
2025-06-05 12:19:54,071 - DEBUG - Saved configuration to /var/folders/3f/2n5sjdw50vj9gfnrxjbptj4c0000gn/T/tmp4ol0v1yb/test_config.json
2025-06-05 12:19:54,072 - DEBUG - Loaded configuration from /var/folders/3f/2n5sjdw50vj9gfnrxjbptj4c0000gn/T/tmp4ol0v1yb/test_config.json
2025-06-05 12:19:54,074 - DEBUG - Saved configuration to /var/folders/3f/2n5sjdw50vj9gfnrxjbptj4c0000gn/T/tmp7nkg7lyc/test_config.json
2025-06-05 12:19:54,075 - DEBUG - Loaded configuration from /var/folders/3f/2n5sjdw50vj9gfnrxjbptj4c0000gn/T/tmp7nkg7lyc/test_config.json
2025-06-05 12:19:54,077 - INFO - Cluster init script uploaded successfully to /Volumes/main/default/chuck/cluster_init-2025-06-02_14-30.sh
2025-06-05 12:19:54,082 - DEBUG - Volume 'chuck' not found in main.default. Attempting to create.
2025-06-05 12:19:54,082 - DEBUG - Volume 'chuck' created successfully.
2025-06-05 12:19:54,082 - INFO - Cluster init script uploaded successfully to /Volumes/main/default/chuck/cluster_init-2025-06-02_14-30.sh
2025-06-05 12:19:54,084 - DEBUG - Volume 'chuck' not found in main.default. Attempting to create.
2025-06-05 12:19:54,084 - DEBUG - Volume 'chuck' created successfully.
2025-06-05 12:19:54,084 - INFO - Cluster init script uploaded successfully to /Volumes/main/default/chuck/cluster_init-2025-06-02_14-30.sh
2025-06-05 12:19:54,086 - DEBUG - Volume 'chuck' not found in main.default. Attempting to create.
2025-06-05 12:19:54,087 - DEBUG - Volume 'chuck' not found in main.default. Attempting to create.
2025-06-05 12:19:54,090 - INFO - Cluster init script uploaded successfully to /Volumes/test_catalog/test_schema/chuck/cluster_init-2025-12-31_23-59.sh
2025-06-05 12:19:54,092 - ERROR - Error generating help: Test error
Traceback (most recent call last):
  File "/Users/johnrush/repos/chuck-data/src/commands/help.py", line 27, in handle_command
    user_commands = get_user_commands()
                    ^^^^^^^^^^^^^^^^^^^
  File "/usr/local/Cellar/python@3.11/3.11.4_1/Frameworks/Python.framework/Versions/3.11/lib/python3.11/unittest/mock.py", line 1124, in __call__
    return self._mock_call(*args, **kwargs)
           ^^^^^^^^^^^^^^^^^^^^^^^^^^^^^^^^
  File "/usr/local/Cellar/python@3.11/3.11.4_1/Frameworks/Python.framework/Versions/3.11/lib/python3.11/unittest/mock.py", line 1128, in _mock_call
    return self._execute_mock_call(*args, **kwargs)
           ^^^^^^^^^^^^^^^^^^^^^^^^^^^^^^^^^^^^^^^^
  File "/usr/local/Cellar/python@3.11/3.11.4_1/Frameworks/Python.framework/Versions/3.11/lib/python3.11/unittest/mock.py", line 1183, in _execute_mock_call
    raise effect
Exception: Test error
2025-06-05 12:19:54,096 - ERROR - Failed to get job status for run '999999': Not Found
Traceback (most recent call last):
  File "/Users/johnrush/repos/chuck-data/src/commands/jobs.py", line 67, in handle_job_status
    data = client.get_job_run_status(run_id_str)
           ^^^^^^^^^^^^^^^^^^^^^^^^^^^^^^^^^^^^^
  File "/Users/johnrush/repos/chuck-data/tests/commands/test_jobs.py", line 119, in get_job_run_status
    raise Exception("Not Found")
Exception: Not Found
2025-06-05 12:19:54,100 - ERROR - Failed to submit job: Bad Request
Traceback (most recent call last):
  File "/Users/johnrush/repos/chuck-data/src/commands/jobs.py", line 32, in handle_launch_job
    run_data = client.submit_job_run(
               ^^^^^^^^^^^^^^^^^^^^^^
  File "/Users/johnrush/repos/chuck-data/tests/commands/test_jobs.py", line 70, in submit_job_run
    raise Exception("Bad Request")
Exception: Bad Request
2025-06-05 12:19:54,103 - ERROR - Failed to launch job, no run_id: {}
2025-06-05 12:19:54,106 - ERROR - Error listing catalogs: API error
2025-06-05 12:19:54,111 - DEBUG - Saved configuration to /var/folders/3f/2n5sjdw50vj9gfnrxjbptj4c0000gn/T/tmpu39n0m5z/test_config.json
2025-06-05 12:19:54,112 - DEBUG - Loaded configuration from /var/folders/3f/2n5sjdw50vj9gfnrxjbptj4c0000gn/T/tmpu39n0m5z/test_config.json
2025-06-05 12:19:54,114 - DEBUG - Saved configuration to /var/folders/3f/2n5sjdw50vj9gfnrxjbptj4c0000gn/T/tmpwa50ue_h/test_config.json
2025-06-05 12:19:54,114 - DEBUG - Loaded configuration from /var/folders/3f/2n5sjdw50vj9gfnrxjbptj4c0000gn/T/tmpwa50ue_h/test_config.json
2025-06-05 12:19:54,117 - DEBUG - Saved configuration to /var/folders/3f/2n5sjdw50vj9gfnrxjbptj4c0000gn/T/tmpwyjd1qko/test_config.json
2025-06-05 12:19:54,117 - DEBUG - Loaded configuration from /var/folders/3f/2n5sjdw50vj9gfnrxjbptj4c0000gn/T/tmpwyjd1qko/test_config.json
2025-06-05 12:19:54,118 - ERROR - Failed to list models: API error
Traceback (most recent call last):
  File "/Users/johnrush/repos/chuck-data/src/commands/list_models.py", line 31, in handle_command
    models_list = list_models_api(client)
                  ^^^^^^^^^^^^^^^^^^^^^^^
  File "/Users/johnrush/repos/chuck-data/src/models.py", line 19, in list_models
    return client.list_models()
           ^^^^^^^^^^^^^^^^^^^^
  File "/Users/johnrush/repos/chuck-data/tests/commands/test_list_models.py", line 112, in list_models
    raise Exception("API error")
Exception: API error
2025-06-05 12:19:54,121 - ERROR - Error listing tables: API error
2025-06-05 12:19:54,124 - DEBUG - Saved configuration to /var/folders/3f/2n5sjdw50vj9gfnrxjbptj4c0000gn/T/tmp_4v34c99/test_config.json
2025-06-05 12:19:54,124 - DEBUG - Loaded configuration from /var/folders/3f/2n5sjdw50vj9gfnrxjbptj4c0000gn/T/tmp_4v34c99/test_config.json
2025-06-05 12:19:54,124 - DEBUG - Loaded configuration from /var/folders/3f/2n5sjdw50vj9gfnrxjbptj4c0000gn/T/tmp_4v34c99/test_config.json
2025-06-05 12:19:54,127 - DEBUG - Saved configuration to /var/folders/3f/2n5sjdw50vj9gfnrxjbptj4c0000gn/T/tmp5pul1i7s/test_config.json
2025-06-05 12:19:54,127 - DEBUG - Loaded configuration from /var/folders/3f/2n5sjdw50vj9gfnrxjbptj4c0000gn/T/tmp5pul1i7s/test_config.json
2025-06-05 12:19:54,127 - DEBUG - Saved configuration to /var/folders/3f/2n5sjdw50vj9gfnrxjbptj4c0000gn/T/tmp5pul1i7s/test_config.json
2025-06-05 12:19:54,128 - DEBUG - Loaded configuration from /var/folders/3f/2n5sjdw50vj9gfnrxjbptj4c0000gn/T/tmp5pul1i7s/test_config.json
2025-06-05 12:19:54,128 - DEBUG - Loaded configuration from /var/folders/3f/2n5sjdw50vj9gfnrxjbptj4c0000gn/T/tmp5pul1i7s/test_config.json
2025-06-05 12:19:54,133 - ERROR - Failed to set model 'claude-v1': API error
Traceback (most recent call last):
  File "/Users/johnrush/repos/chuck-data/src/commands/model_selection.py", line 28, in handle_command
    models_list = list_models_api(client)
                  ^^^^^^^^^^^^^^^^^^^^^^^
  File "/Users/johnrush/repos/chuck-data/src/models.py", line 19, in list_models
    return client.list_models()
           ^^^^^^^^^^^^^^^^^^^^
  File "/Users/johnrush/repos/chuck-data/tests/commands/test_model_selection.py", line 79, in list_models
    raise Exception("API error")
Exception: API error
2025-06-05 12:19:54,135 - DEBUG - Saved configuration to /var/folders/3f/2n5sjdw50vj9gfnrxjbptj4c0000gn/T/tmplv1rhu33/test_config.json
2025-06-05 12:19:54,135 - DEBUG - Loaded configuration from /var/folders/3f/2n5sjdw50vj9gfnrxjbptj4c0000gn/T/tmplv1rhu33/test_config.json
2025-06-05 12:19:54,137 - DEBUG - Saved configuration to /var/folders/3f/2n5sjdw50vj9gfnrxjbptj4c0000gn/T/tmpq3i4ktvn/test_config.json
2025-06-05 12:19:54,137 - DEBUG - Loaded configuration from /var/folders/3f/2n5sjdw50vj9gfnrxjbptj4c0000gn/T/tmpq3i4ktvn/test_config.json
2025-06-05 12:19:54,139 - DEBUG - Saved configuration to /var/folders/3f/2n5sjdw50vj9gfnrxjbptj4c0000gn/T/tmprgm5sb0a/test_config.json
2025-06-05 12:19:54,139 - DEBUG - Loaded configuration from /var/folders/3f/2n5sjdw50vj9gfnrxjbptj4c0000gn/T/tmprgm5sb0a/test_config.json
2025-06-05 12:19:54,143 - DEBUG - Saved configuration to /var/folders/3f/2n5sjdw50vj9gfnrxjbptj4c0000gn/T/tmp4jaevo3f/test_config.json
2025-06-05 12:19:54,143 - DEBUG - Loaded configuration from /var/folders/3f/2n5sjdw50vj9gfnrxjbptj4c0000gn/T/tmp4jaevo3f/test_config.json
2025-06-05 12:19:54,149 - INFO - Starting PII Scan for 2 tables in test_cat.test_schema.
2025-06-05 12:19:54,155 - ERROR - Bulk PII scan error: LLM client error
Traceback (most recent call last):
  File "/Users/johnrush/repos/chuck-data/src/commands/scan_pii.py", line 46, in handle_command
    llm_client = LLMClient()
                 ^^^^^^^^^^^
  File "/usr/local/Cellar/python@3.11/3.11.4_1/Frameworks/Python.framework/Versions/3.11/lib/python3.11/unittest/mock.py", line 1124, in __call__
    return self._mock_call(*args, **kwargs)
           ^^^^^^^^^^^^^^^^^^^^^^^^^^^^^^^^
  File "/usr/local/Cellar/python@3.11/3.11.4_1/Frameworks/Python.framework/Versions/3.11/lib/python3.11/unittest/mock.py", line 1128, in _mock_call
    return self._execute_mock_call(*args, **kwargs)
           ^^^^^^^^^^^^^^^^^^^^^^^^^^^^^^^^^^^^^^^^
  File "/usr/local/Cellar/python@3.11/3.11.4_1/Frameworks/Python.framework/Versions/3.11/lib/python3.11/unittest/mock.py", line 1183, in _execute_mock_call
    raise effect
Exception: LLM client error
2025-06-05 12:19:54,161 - DEBUG - Saved configuration to /var/folders/3f/2n5sjdw50vj9gfnrxjbptj4c0000gn/T/tmpn6iqazdq/test_config.json
2025-06-05 12:19:54,162 - DEBUG - Loaded configuration from /var/folders/3f/2n5sjdw50vj9gfnrxjbptj4c0000gn/T/tmpn6iqazdq/test_config.json
2025-06-05 12:19:54,162 - DEBUG - Loaded configuration from /var/folders/3f/2n5sjdw50vj9gfnrxjbptj4c0000gn/T/tmpn6iqazdq/test_config.json
2025-06-05 12:19:54,162 - DEBUG - Saved configuration to /var/folders/3f/2n5sjdw50vj9gfnrxjbptj4c0000gn/T/tmpn6iqazdq/test_config.json
2025-06-05 12:19:54,164 - DEBUG - Saved configuration to /var/folders/3f/2n5sjdw50vj9gfnrxjbptj4c0000gn/T/tmp9j0wj2n8/test_config.json
2025-06-05 12:19:54,164 - DEBUG - Loaded configuration from /var/folders/3f/2n5sjdw50vj9gfnrxjbptj4c0000gn/T/tmp9j0wj2n8/test_config.json
2025-06-05 12:19:54,164 - DEBUG - Loaded configuration from /var/folders/3f/2n5sjdw50vj9gfnrxjbptj4c0000gn/T/tmp9j0wj2n8/test_config.json
2025-06-05 12:19:54,164 - DEBUG - Saved configuration to /var/folders/3f/2n5sjdw50vj9gfnrxjbptj4c0000gn/T/tmp9j0wj2n8/test_config.json
2025-06-05 12:19:54,165 - DEBUG - Loaded configuration from /var/folders/3f/2n5sjdw50vj9gfnrxjbptj4c0000gn/T/tmp9j0wj2n8/test_config.json
2025-06-05 12:19:54,166 - DEBUG - Saved configuration to /var/folders/3f/2n5sjdw50vj9gfnrxjbptj4c0000gn/T/tmpmckdzi23/test_config.json
2025-06-05 12:19:54,166 - DEBUG - Loaded configuration from /var/folders/3f/2n5sjdw50vj9gfnrxjbptj4c0000gn/T/tmpmckdzi23/test_config.json
2025-06-05 12:19:54,166 - DEBUG - Loaded configuration from /var/folders/3f/2n5sjdw50vj9gfnrxjbptj4c0000gn/T/tmpmckdzi23/test_config.json
2025-06-05 12:19:54,167 - DEBUG - Saved configuration to /var/folders/3f/2n5sjdw50vj9gfnrxjbptj4c0000gn/T/tmpmckdzi23/test_config.json
2025-06-05 12:19:54,167 - DEBUG - Loaded configuration from /var/folders/3f/2n5sjdw50vj9gfnrxjbptj4c0000gn/T/tmpmckdzi23/test_config.json
2025-06-05 12:19:54,171 - DEBUG - Sending metric: {"event": "USAGE", "configuration": {"workspace_url": "https://dbc-df998298-4c7e.cloud.databricks.co...
2025-06-05 12:19:54,174 - DEBUG - Starting new HTTPS connection (1): chuck.amperity.com:443
2025-06-05 12:19:54,244 - DEBUG - https://chuck.amperity.com:443 "POST /api/usage HTTP/1.1" 204 0
2025-06-05 12:19:54,244 - DEBUG - Failed to send metrics: 204 - 
2025-06-05 12:19:54,247 - ERROR - Stitch setup error: LLM client error
Traceback (most recent call last):
  File "/Users/johnrush/repos/chuck-data/src/commands/setup_stitch.py", line 111, in handle_command
    return _phase_1_prepare_config(
           ^^^^^^^^^^^^^^^^^^^^^^^^
  File "/Users/johnrush/repos/chuck-data/src/commands/setup_stitch.py", line 273, in _phase_1_prepare_config
    llm_client = LLMClient()
                 ^^^^^^^^^^^
  File "/usr/local/Cellar/python@3.11/3.11.4_1/Frameworks/Python.framework/Versions/3.11/lib/python3.11/unittest/mock.py", line 1124, in __call__
    return self._mock_call(*args, **kwargs)
           ^^^^^^^^^^^^^^^^^^^^^^^^^^^^^^^^
  File "/usr/local/Cellar/python@3.11/3.11.4_1/Frameworks/Python.framework/Versions/3.11/lib/python3.11/unittest/mock.py", line 1128, in _mock_call
    return self._execute_mock_call(*args, **kwargs)
           ^^^^^^^^^^^^^^^^^^^^^^^^^^^^^^^^^^^^^^^^
  File "/usr/local/Cellar/python@3.11/3.11.4_1/Frameworks/Python.framework/Versions/3.11/lib/python3.11/unittest/mock.py", line 1183, in _execute_mock_call
    raise effect
Exception: LLM client error
2025-06-05 12:19:54,255 - DEBUG - GET request to: https://.cloud.databricks.com/api/2.0/preview/scim/v2/Me
2025-06-05 12:19:54,255 - DEBUG - Connection error: URL has an invalid label.
2025-06-05 12:19:54,255 - DEBUG - Token validation failed: Connection error occurred: URL has an invalid label.
2025-06-05 12:19:54,258 - ERROR - Error validating token: Connection failed
2025-06-05 12:19:54,263 - DEBUG - GET request to: https://invalid-workspace.nonexistent.com.cloud.databricks.com/api/2.0/preview/scim/v2/Me
2025-06-05 12:19:54,313 - DEBUG - Starting new HTTPS connection (1): invalid-workspace.nonexistent.com.cloud.databricks.com:443
2025-06-05 12:19:54,314 - DEBUG - Connection error: HTTPSConnectionPool(host='invalid-workspace.nonexistent.com.cloud.databricks.com', port=443): Max retries exceeded with url: /api/2.0/preview/scim/v2/Me (Caused by NameResolutionError("<urllib3.connection.HTTPSConnection object at 0x10fd75190>: Failed to resolve 'invalid-workspace.nonexistent.com.cloud.databricks.com' ([Errno 8] nodename nor servname provided, or not known)"))
2025-06-05 12:19:54,314 - DEBUG - Token validation failed: Connection error occurred: HTTPSConnectionPool(host='invalid-workspace.nonexistent.com.cloud.databricks.com', port=443): Max retries exceeded with url: /api/2.0/preview/scim/v2/Me (Caused by NameResolutionError("<urllib3.connection.HTTPSConnection object at 0x10fd75190>: Failed to resolve 'invalid-workspace.nonexistent.com.cloud.databricks.com' ([Errno 8] nodename nor servname provided, or not known)"))
2025-06-05 12:19:54,416 - DEBUG - GET request to: https://invalid.nonexistent.com.cloud.databricks.com/api/2.0/preview/scim/v2/Me
2025-06-05 12:19:54,462 - DEBUG - Starting new HTTPS connection (1): invalid.nonexistent.com.cloud.databricks.com:443
2025-06-05 12:19:54,464 - DEBUG - Connection error: HTTPSConnectionPool(host='invalid.nonexistent.com.cloud.databricks.com', port=443): Max retries exceeded with url: /api/2.0/preview/scim/v2/Me (Caused by NameResolutionError("<urllib3.connection.HTTPSConnection object at 0x10fd387d0>: Failed to resolve 'invalid.nonexistent.com.cloud.databricks.com' ([Errno 8] nodename nor servname provided, or not known)"))
2025-06-05 12:19:54,464 - DEBUG - Token validation failed: Connection error occurred: HTTPSConnectionPool(host='invalid.nonexistent.com.cloud.databricks.com', port=443): Max retries exceeded with url: /api/2.0/preview/scim/v2/Me (Caused by NameResolutionError("<urllib3.connection.HTTPSConnection object at 0x10fd387d0>: Failed to resolve 'invalid.nonexistent.com.cloud.databricks.com' ([Errno 8] nodename nor servname provided, or not known)"))
2025-06-05 12:19:54,465 - ERROR - Error validating token: Validation failed
2025-06-05 12:19:54,574 - ERROR - Error validating token: Connection failed
2025-06-05 12:19:54,607 - ERROR - Error validating token: Network error with secret details
2025-06-05 12:19:54,639 - ERROR - Error validating token: Connection error: Failed to resolve 'workspace123.cloud.databricks.com'
2025-06-05 12:19:54,648 - ERROR - Error fetching Amperity init script: API Error
Traceback (most recent call last):
  File "/Users/johnrush/repos/chuck-data/src/commands/stitch_tools.py", line 179, in _helper_prepare_stitch_config
    init_script_data = client.fetch_amperity_job_init(amperity_token)
                       ^^^^^^^^^^^^^^^^^^^^^^^^^^^^^^^^^^^^^^^^^^^^^^
  File "/usr/local/Cellar/python@3.11/3.11.4_1/Frameworks/Python.framework/Versions/3.11/lib/python3.11/unittest/mock.py", line 1124, in __call__
    return self._mock_call(*args, **kwargs)
           ^^^^^^^^^^^^^^^^^^^^^^^^^^^^^^^^
  File "/usr/local/Cellar/python@3.11/3.11.4_1/Frameworks/Python.framework/Versions/3.11/lib/python3.11/unittest/mock.py", line 1128, in _mock_call
    return self._execute_mock_call(*args, **kwargs)
           ^^^^^^^^^^^^^^^^^^^^^^^^^^^^^^^^^^^^^^^^
  File "/usr/local/Cellar/python@3.11/3.11.4_1/Frameworks/Python.framework/Versions/3.11/lib/python3.11/unittest/mock.py", line 1183, in _execute_mock_call
    raise effect
Exception: API Error
2025-06-05 12:19:54,655 - DEBUG - Versioned cluster init script uploaded to /Volumes/test_catalog/test_schema/chuck/cluster_init-2025-06-02_14-30.sh
2025-06-05 12:19:54,657 - DEBUG - Versioned cluster init script uploaded to /Volumes/test_catalog/test_schema/chuck/cluster_init-2025-06-02_14-30.sh
2025-06-05 12:19:54,660 - DEBUG - Volume 'chuck' not found in test_catalog.test_schema. Attempting to create.
2025-06-05 12:19:54,670 - DEBUG - Saved configuration to /var/folders/3f/2n5sjdw50vj9gfnrxjbptj4c0000gn/T/tmpozuwlv7s/test_config.json
2025-06-05 12:19:54,670 - DEBUG - Loaded configuration from /var/folders/3f/2n5sjdw50vj9gfnrxjbptj4c0000gn/T/tmpozuwlv7s/test_config.json
2025-06-05 12:19:54,670 - DEBUG - Loaded configuration from /var/folders/3f/2n5sjdw50vj9gfnrxjbptj4c0000gn/T/tmpozuwlv7s/test_config.json
2025-06-05 12:19:54,670 - DEBUG - Loaded configuration from /var/folders/3f/2n5sjdw50vj9gfnrxjbptj4c0000gn/T/tmpozuwlv7s/test_config.json
2025-06-05 12:19:54,672 - DEBUG - Saved configuration to /var/folders/3f/2n5sjdw50vj9gfnrxjbptj4c0000gn/T/tmpfuemoc_s/test_config.json
2025-06-05 12:19:54,672 - DEBUG - Loaded configuration from /var/folders/3f/2n5sjdw50vj9gfnrxjbptj4c0000gn/T/tmpfuemoc_s/test_config.json
2025-06-05 12:19:54,672 - DEBUG - Saved configuration to /var/folders/3f/2n5sjdw50vj9gfnrxjbptj4c0000gn/T/tmpfuemoc_s/test_config.json
2025-06-05 12:19:54,673 - DEBUG - Loaded configuration from /var/folders/3f/2n5sjdw50vj9gfnrxjbptj4c0000gn/T/tmpfuemoc_s/test_config.json
2025-06-05 12:19:54,673 - DEBUG - Saved configuration to /var/folders/3f/2n5sjdw50vj9gfnrxjbptj4c0000gn/T/tmpfuemoc_s/test_config.json
2025-06-05 12:19:54,673 - DEBUG - Loaded configuration from /var/folders/3f/2n5sjdw50vj9gfnrxjbptj4c0000gn/T/tmpfuemoc_s/test_config.json
2025-06-05 12:19:54,673 - DEBUG - Loaded configuration from /var/folders/3f/2n5sjdw50vj9gfnrxjbptj4c0000gn/T/tmpfuemoc_s/test_config.json
2025-06-05 12:19:54,673 - DEBUG - Loaded configuration from /var/folders/3f/2n5sjdw50vj9gfnrxjbptj4c0000gn/T/tmpfuemoc_s/test_config.json
2025-06-05 12:19:54,675 - INFO - Applying tag 'email' to column 'email_col'
2025-06-05 12:19:54,675 - INFO - Applying tag 'given-name' to column 'name_col'
2025-06-05 12:19:54,676 - INFO - Applying tag 'phone' to column 'good_col'
2025-06-05 12:19:54,677 - INFO - Applying tag 'email' to column 'email_col'
2025-06-05 12:19:54,678 - INFO - Applying tag 'email' to column 'email_col'
2025-06-05 12:19:54,678 - ERROR - Error applying tag to email_col: Connection error
2025-06-05 12:19:54,681 - DEBUG - Saved configuration to /var/folders/3f/2n5sjdw50vj9gfnrxjbptj4c0000gn/T/tmpqj3p6e6k/test_config.json
2025-06-05 12:19:54,681 - DEBUG - Loaded configuration from /var/folders/3f/2n5sjdw50vj9gfnrxjbptj4c0000gn/T/tmpqj3p6e6k/test_config.json
2025-06-05 12:19:54,683 - DEBUG - Saved configuration to /var/folders/3f/2n5sjdw50vj9gfnrxjbptj4c0000gn/T/tmpbvh6di3t/test_config.json
2025-06-05 12:19:54,684 - DEBUG - Saved configuration to /var/folders/3f/2n5sjdw50vj9gfnrxjbptj4c0000gn/T/tmpfj57e2dj/test_config.json
2025-06-05 12:19:54,684 - DEBUG - Loaded configuration from /var/folders/3f/2n5sjdw50vj9gfnrxjbptj4c0000gn/T/tmpfj57e2dj/test_config.json
2025-06-05 12:19:54,686 - DEBUG - Saved configuration to /var/folders/3f/2n5sjdw50vj9gfnrxjbptj4c0000gn/T/tmp9mc8zdsu/test_config.json
2025-06-05 12:19:54,686 - DEBUG - Loaded configuration from /var/folders/3f/2n5sjdw50vj9gfnrxjbptj4c0000gn/T/tmp9mc8zdsu/test_config.json
2025-06-05 12:19:54,690 - ERROR - Failed to set workspace URL: Validation error
Traceback (most recent call last):
  File "/Users/johnrush/repos/chuck-data/src/commands/workspace_selection.py", line 37, in handle_command
    is_valid, error_message = validate_workspace_url(workspace_url)
                              ^^^^^^^^^^^^^^^^^^^^^^^^^^^^^^^^^^^^^
  File "/usr/local/Cellar/python@3.11/3.11.4_1/Frameworks/Python.framework/Versions/3.11/lib/python3.11/unittest/mock.py", line 1124, in __call__
    return self._mock_call(*args, **kwargs)
           ^^^^^^^^^^^^^^^^^^^^^^^^^^^^^^^^
  File "/usr/local/Cellar/python@3.11/3.11.4_1/Frameworks/Python.framework/Versions/3.11/lib/python3.11/unittest/mock.py", line 1128, in _mock_call
    return self._execute_mock_call(*args, **kwargs)
           ^^^^^^^^^^^^^^^^^^^^^^^^^^^^^^^^^^^^^^^^
  File "/usr/local/Cellar/python@3.11/3.11.4_1/Frameworks/Python.framework/Versions/3.11/lib/python3.11/unittest/mock.py", line 1183, in _execute_mock_call
    raise effect
Exception: Validation error
