2025-06-06 02:06:57,713 - DEBUG - Logging initialized. Writing to /Users/johnrush/repos/chuck-data/log/sessions/2025-06-06_02-06-57.log
2025-06-06 02:06:57,717 - DEBUG - HTTP error: HTTP 401, Response: {"status":401,"message":"Unauthorized"}
2025-06-06 02:06:57,718 - DEBUG - GET request to: https://test-workspace.cloud.databricks.com/test-endpoint
2025-06-06 02:06:57,718 - DEBUG - Connection error: Connection failed
2025-06-06 02:06:57,719 - DEBUG - GET request to: https://test-workspace.cloud.databricks.com/test-endpoint
2025-06-06 02:06:57,719 - DEBUG - HTTP error: HTTP 404, Response: Not Found
2025-06-06 02:06:57,720 - DEBUG - GET request to: https://test-workspace.cloud.databricks.com/test-endpoint
2025-06-06 02:06:57,721 - DEBUG - POST request to: https://test-workspace.cloud.databricks.com/test-endpoint
2025-06-06 02:06:57,721 - DEBUG - Connection error: Connection failed
2025-06-06 02:06:57,722 - DEBUG - POST request to: https://test-workspace.cloud.databricks.com/test-endpoint
2025-06-06 02:06:57,723 - DEBUG - HTTP error: HTTP 400, Response: Bad Request
2025-06-06 02:06:57,724 - DEBUG - POST request to: https://test-workspace.cloud.databricks.com/test-endpoint
2025-06-06 02:06:57,740 - ERROR - Error listing catalogs: Database connection failed
2025-06-06 02:06:57,743 - ERROR - Error listing schemas: Network error
2025-06-06 02:06:57,789 - DEBUG - Saved configuration to /var/folders/3f/2n5sjdw50vj9gfnrxjbptj4c0000gn/T/tmpvfaeq8xn/test_config.json
2025-06-06 02:06:57,789 - DEBUG - Loaded configuration from /var/folders/3f/2n5sjdw50vj9gfnrxjbptj4c0000gn/T/tmpvfaeq8xn/test_config.json
2025-06-06 02:06:57,789 - DEBUG - Loaded configuration from /var/folders/3f/2n5sjdw50vj9gfnrxjbptj4c0000gn/T/tmpvfaeq8xn/test_config.json
2025-06-06 02:06:57,790 - DEBUG - Saved configuration to /var/folders/3f/2n5sjdw50vj9gfnrxjbptj4c0000gn/T/tmpvfaeq8xn/test_config.json
2025-06-06 02:06:57,790 - DEBUG - Loaded configuration from /var/folders/3f/2n5sjdw50vj9gfnrxjbptj4c0000gn/T/tmpvfaeq8xn/test_config.json
2025-06-06 02:06:57,790 - DEBUG - Saved configuration to /var/folders/3f/2n5sjdw50vj9gfnrxjbptj4c0000gn/T/tmpvfaeq8xn/test_config.json
2025-06-06 02:06:57,791 - DEBUG - Loaded configuration from /var/folders/3f/2n5sjdw50vj9gfnrxjbptj4c0000gn/T/tmpvfaeq8xn/test_config.json
2025-06-06 02:06:57,791 - DEBUG - Saved configuration to /var/folders/3f/2n5sjdw50vj9gfnrxjbptj4c0000gn/T/tmpvfaeq8xn/test_config.json
2025-06-06 02:06:57,791 - DEBUG - Loaded configuration from /var/folders/3f/2n5sjdw50vj9gfnrxjbptj4c0000gn/T/tmpvfaeq8xn/test_config.json
2025-06-06 02:06:57,791 - DEBUG - Saved configuration to /var/folders/3f/2n5sjdw50vj9gfnrxjbptj4c0000gn/T/tmpvfaeq8xn/test_config.json
2025-06-06 02:06:57,792 - DEBUG - Loaded configuration from /var/folders/3f/2n5sjdw50vj9gfnrxjbptj4c0000gn/T/tmpvfaeq8xn/test_config.json
2025-06-06 02:06:57,792 - DEBUG - Loaded configuration from /var/folders/3f/2n5sjdw50vj9gfnrxjbptj4c0000gn/T/tmpvfaeq8xn/test_config.json
2025-06-06 02:06:57,792 - DEBUG - Loaded configuration from /var/folders/3f/2n5sjdw50vj9gfnrxjbptj4c0000gn/T/tmpvfaeq8xn/test_config.json
2025-06-06 02:06:57,792 - DEBUG - Loaded configuration from /var/folders/3f/2n5sjdw50vj9gfnrxjbptj4c0000gn/T/tmpvfaeq8xn/test_config.json
2025-06-06 02:06:57,792 - DEBUG - Loaded configuration from /var/folders/3f/2n5sjdw50vj9gfnrxjbptj4c0000gn/T/tmpvfaeq8xn/test_config.json
2025-06-06 02:06:57,794 - DEBUG - Saved configuration to /var/folders/3f/2n5sjdw50vj9gfnrxjbptj4c0000gn/T/tmp93lifg4m/test_config.json
2025-06-06 02:06:57,794 - DEBUG - Loaded configuration from /var/folders/3f/2n5sjdw50vj9gfnrxjbptj4c0000gn/T/tmp93lifg4m/test_config.json
2025-06-06 02:06:57,796 - DEBUG - Saved configuration to /var/folders/3f/2n5sjdw50vj9gfnrxjbptj4c0000gn/T/tmpfd589fm5/test_config.json
2025-06-06 02:06:57,796 - DEBUG - Loaded configuration from /var/folders/3f/2n5sjdw50vj9gfnrxjbptj4c0000gn/T/tmpfd589fm5/test_config.json
2025-06-06 02:06:57,797 - DEBUG - Saved configuration to /var/folders/3f/2n5sjdw50vj9gfnrxjbptj4c0000gn/T/tmpjzcjqn09/test_config.json
2025-06-06 02:06:57,797 - DEBUG - Loaded configuration from /var/folders/3f/2n5sjdw50vj9gfnrxjbptj4c0000gn/T/tmpjzcjqn09/test_config.json
2025-06-06 02:06:57,797 - DEBUG - Loaded configuration from /var/folders/3f/2n5sjdw50vj9gfnrxjbptj4c0000gn/T/tmpjzcjqn09/test_config.json
2025-06-06 02:06:57,798 - DEBUG - Saved configuration to /var/folders/3f/2n5sjdw50vj9gfnrxjbptj4c0000gn/T/tmpjzcjqn09/test_config.json
2025-06-06 02:06:57,798 - DEBUG - Loaded configuration from /var/folders/3f/2n5sjdw50vj9gfnrxjbptj4c0000gn/T/tmpjzcjqn09/test_config.json
2025-06-06 02:06:57,798 - DEBUG - Loaded configuration from /var/folders/3f/2n5sjdw50vj9gfnrxjbptj4c0000gn/T/tmpjzcjqn09/test_config.json
2025-06-06 02:06:57,801 - DEBUG - Saved configuration to /var/folders/3f/2n5sjdw50vj9gfnrxjbptj4c0000gn/T/tmpeqaf56nw/test_config.json
2025-06-06 02:06:57,801 - DEBUG - Loaded configuration from /var/folders/3f/2n5sjdw50vj9gfnrxjbptj4c0000gn/T/tmpeqaf56nw/test_config.json
2025-06-06 02:06:57,801 - DEBUG - Loaded configuration from /var/folders/3f/2n5sjdw50vj9gfnrxjbptj4c0000gn/T/tmpeqaf56nw/test_config.json
2025-06-06 02:06:57,802 - DEBUG - Saved configuration to /var/folders/3f/2n5sjdw50vj9gfnrxjbptj4c0000gn/T/tmpeqaf56nw/test_config.json
2025-06-06 02:06:57,802 - DEBUG - Loaded configuration from /var/folders/3f/2n5sjdw50vj9gfnrxjbptj4c0000gn/T/tmpeqaf56nw/test_config.json
2025-06-06 02:06:57,802 - DEBUG - Saved configuration to /var/folders/3f/2n5sjdw50vj9gfnrxjbptj4c0000gn/T/tmpeqaf56nw/test_config.json
2025-06-06 02:06:57,802 - DEBUG - Loaded configuration from /var/folders/3f/2n5sjdw50vj9gfnrxjbptj4c0000gn/T/tmpeqaf56nw/test_config.json
2025-06-06 02:06:57,802 - DEBUG - Saved configuration to /var/folders/3f/2n5sjdw50vj9gfnrxjbptj4c0000gn/T/tmpeqaf56nw/test_config.json
2025-06-06 02:06:57,803 - DEBUG - Loaded configuration from /var/folders/3f/2n5sjdw50vj9gfnrxjbptj4c0000gn/T/tmpeqaf56nw/test_config.json
2025-06-06 02:06:57,803 - DEBUG - Saved configuration to /var/folders/3f/2n5sjdw50vj9gfnrxjbptj4c0000gn/T/tmpeqaf56nw/test_config.json
2025-06-06 02:06:57,803 - DEBUG - Loaded configuration from /var/folders/3f/2n5sjdw50vj9gfnrxjbptj4c0000gn/T/tmpeqaf56nw/test_config.json
2025-06-06 02:06:57,803 - DEBUG - Using workspace_url from environment variable CHUCK_WORKSPACE_URL
2025-06-06 02:06:57,803 - DEBUG - Using active_model from environment variable CHUCK_ACTIVE_MODEL
2025-06-06 02:06:57,803 - DEBUG - Using warehouse_id from environment variable CHUCK_WAREHOUSE_ID
2025-06-06 02:06:57,803 - DEBUG - Using active_catalog from environment variable CHUCK_ACTIVE_CATALOG
2025-06-06 02:06:57,803 - DEBUG - Using active_schema from environment variable CHUCK_ACTIVE_SCHEMA
2025-06-06 02:06:57,803 - DEBUG - Using usage_tracking_consent from environment variable CHUCK_USAGE_TRACKING_CONSENT
2025-06-06 02:06:57,803 - DEBUG - Loaded configuration from /var/folders/3f/2n5sjdw50vj9gfnrxjbptj4c0000gn/T/tmpeqaf56nw/test_config.json
2025-06-06 02:06:57,805 - DEBUG - Saved configuration to /var/folders/3f/2n5sjdw50vj9gfnrxjbptj4c0000gn/T/tmpagkrdd5_/test_config.json
2025-06-06 02:06:57,805 - DEBUG - Loaded configuration from /var/folders/3f/2n5sjdw50vj9gfnrxjbptj4c0000gn/T/tmpagkrdd5_/test_config.json
2025-06-06 02:06:57,806 - DEBUG - Loaded configuration from /var/folders/3f/2n5sjdw50vj9gfnrxjbptj4c0000gn/T/tmpagkrdd5_/test_config.json
2025-06-06 02:06:57,806 - WARNING - Invalid workspace_url provided, using default instead
2025-06-06 02:06:57,806 - DEBUG - Saved configuration to /var/folders/3f/2n5sjdw50vj9gfnrxjbptj4c0000gn/T/tmpagkrdd5_/test_config.json
2025-06-06 02:06:57,806 - DEBUG - Loaded configuration from /var/folders/3f/2n5sjdw50vj9gfnrxjbptj4c0000gn/T/tmpagkrdd5_/test_config.json
2025-06-06 02:06:57,806 - DEBUG - Loaded configuration from /var/folders/3f/2n5sjdw50vj9gfnrxjbptj4c0000gn/T/tmpagkrdd5_/test_config.json
2025-06-06 02:06:57,806 - DEBUG - Saved configuration to /var/folders/3f/2n5sjdw50vj9gfnrxjbptj4c0000gn/T/tmpagkrdd5_/test_config.json
2025-06-06 02:06:57,807 - DEBUG - Loaded configuration from /var/folders/3f/2n5sjdw50vj9gfnrxjbptj4c0000gn/T/tmpagkrdd5_/test_config.json
2025-06-06 02:06:57,808 - DEBUG - Using workspace_url from environment variable CHUCK_WORKSPACE_URL
2025-06-06 02:06:57,808 - DEBUG - Using workspace_url from environment variable CHUCK_WORKSPACE_URL
2025-06-06 02:06:57,809 - DEBUG - Using active_model from environment variable CHUCK_ACTIVE_MODEL
2025-06-06 02:06:57,809 - DEBUG - Using amperity_token from environment variable CHUCK_AMPERITY_TOKEN
2025-06-06 02:06:57,809 - DEBUG - Using databricks_token from environment variable CHUCK_DATABRICKS_TOKEN
2025-06-06 02:06:57,809 - DEBUG - Saved configuration to /var/folders/3f/2n5sjdw50vj9gfnrxjbptj4c0000gn/T/tmptr6vbsz7/test_config.json
2025-06-06 02:06:57,809 - DEBUG - Loaded configuration from /var/folders/3f/2n5sjdw50vj9gfnrxjbptj4c0000gn/T/tmptr6vbsz7/test_config.json
2025-06-06 02:06:57,811 - DEBUG - Saved configuration to /var/folders/3f/2n5sjdw50vj9gfnrxjbptj4c0000gn/T/tmpiowxin6c/test_config.json
2025-06-06 02:06:57,823 - DEBUG - GET request to: https://adb-3856707039489412.12.azuredatabricks.net/test-endpoint
2025-06-06 02:06:57,827 - DEBUG - GET request to: https://test-workspace.cloud.databricks.com/test-endpoint
2025-06-06 02:06:57,827 - DEBUG - Connection error: Connection failed
2025-06-06 02:06:57,828 - DEBUG - GET request to: https://test-workspace.cloud.databricks.com/test-endpoint
2025-06-06 02:06:57,828 - DEBUG - HTTP error: HTTP 404, Response: Not Found
2025-06-06 02:06:57,830 - WARNING - Model 'nonexistent-model' not found
2025-06-06 02:06:57,831 - DEBUG - GET request to: https://test-workspace.cloud.databricks.com/test-endpoint
2025-06-06 02:06:57,836 - DEBUG - POST request to: https://test-workspace.cloud.databricks.com/test-endpoint
2025-06-06 02:06:57,836 - DEBUG - Connection error: Connection failed
2025-06-06 02:06:57,837 - DEBUG - POST request to: https://test-workspace.cloud.databricks.com/test-endpoint
2025-06-06 02:06:57,837 - DEBUG - HTTP error: HTTP 400, Response: Bad Request
2025-06-06 02:06:57,838 - DEBUG - POST request to: https://test-workspace.cloud.databricks.com/test-endpoint
2025-06-06 02:06:57,840 - DEBUG - File upload request to: https://test-workspace.cloud.databricks.com/api/2.0/fs/files/test/path.txt
2025-06-06 02:06:57,843 - DEBUG - File upload request to: https://test-workspace.cloud.databricks.com/api/2.0/fs/files/test/path.txt
2025-06-06 02:06:57,844 - DEBUG - Token validation failed: Token validation failed
2025-06-06 02:06:57,850 - ERROR - Error listing catalogs: Random failure 3
2025-06-06 02:06:57,852 - ERROR - Error listing catalogs: Random failure 6
2025-06-06 02:06:57,855 - ERROR - Error listing catalogs: Random failure 9
2025-06-06 02:06:58,107 - ERROR - Error displaying table: Console error
2025-06-06 02:06:58,109 - ERROR - Error listing catalogs: 403 Forbidden: Insufficient permissions
2025-06-06 02:06:58,110 - ERROR - Error listing catalogs: 401 Unauthorized: Invalid token
2025-06-06 02:06:58,110 - ERROR - Error listing catalogs: Access denied to resource
2025-06-06 02:06:58,113 - ERROR - Error listing catalogs: 'NoneType' object has no attribute 'get'
2025-06-06 02:06:58,117 - ERROR - Error listing catalogs: 'str' object has no attribute 'get'
2025-06-06 02:06:58,224 - ERROR - Error listing catalogs: Connection failed
2025-06-06 02:06:58,225 - ERROR - Error listing catalogs: Request timed out
2025-06-06 02:06:58,226 - ERROR - Error listing catalogs: 404 Not Found
2025-06-06 02:06:58,261 - DEBUG - Saved configuration to /tmp/.test_chuck_integration_config.json
2025-06-06 02:06:58,261 - DEBUG - Saved configuration to /tmp/.test_chuck_integration_config.json
2025-06-06 02:06:58,263 - DEBUG - Saved configuration to /tmp/.test_chuck_integration_config.json
2025-06-06 02:06:58,263 - DEBUG - Saved configuration to /tmp/.test_chuck_integration_config.json
2025-06-06 02:06:58,265 - DEBUG - Saved configuration to /tmp/.test_chuck_integration_config.json
2025-06-06 02:06:58,265 - DEBUG - Saved configuration to /tmp/.test_chuck_integration_config.json
2025-06-06 02:06:58,280 - DEBUG - Sending metric: {"event": "USAGE", "prompt": "test prompt"}...
2025-06-06 02:06:58,280 - DEBUG - Error sending metrics: Test exception
Traceback (most recent call last):
  File "/Users/johnrush/repos/chuck-data/src/metrics_collector.py", line 123, in send_metric
    return self._client.submit_metrics(payload, token)
           ^^^^^^^^^^^^^^^^^^^^^^^^^^^^^^^^^^^^^^^^^^^
  File "/Users/johnrush/repos/chuck-data/tests/fixtures.py", line 60, in submit_metrics
    raise Exception("Test exception")
Exception: Test exception
2025-06-06 02:06:58,283 - DEBUG - Sending metric: {"event": "USAGE", "prompt": "test prompt"}...
2025-06-06 02:06:58,284 - DEBUG - Cannot send metrics - no authentication token available
2025-06-06 02:06:58,285 - DEBUG - Sending metric: {"event": "USAGE", "prompt": "test prompt"}...
2025-06-06 02:06:58,287 - DEBUG - Metrics tracking skipped - user has not provided consent
2025-06-06 02:06:58,289 - ERROR - Connection error when getting model: Connection failed
2025-06-06 02:06:58,290 - ERROR - Failed to get model: HTTP error occurred: 500 Internal Server Error
2025-06-06 02:06:58,291 - ERROR - Connection error when listing models: Connection failed
2025-06-06 02:06:58,293 - ERROR - Failed to list models: HTTP error occurred: 404 Not Found
2025-06-06 02:06:58,329 - ERROR - Error executing handler for command 'test_command': Command failed
Traceback (most recent call last):
  File "/Users/johnrush/repos/chuck-data/src/service.py", line 395, in execute_command
    result: CommandResult = command_def.handler(
                            ^^^^^^^^^^^^^^^^^^^^
  File "/usr/local/Cellar/python@3.11/3.11.4_1/Frameworks/Python.framework/Versions/3.11/lib/python3.11/unittest/mock.py", line 1124, in __call__
    return self._mock_call(*args, **kwargs)
           ^^^^^^^^^^^^^^^^^^^^^^^^^^^^^^^^
  File "/usr/local/Cellar/python@3.11/3.11.4_1/Frameworks/Python.framework/Versions/3.11/lib/python3.11/unittest/mock.py", line 1128, in _mock_call
    return self._execute_mock_call(*args, **kwargs)
           ^^^^^^^^^^^^^^^^^^^^^^^^^^^^^^^^^^^^^^^^
  File "/usr/local/Cellar/python@3.11/3.11.4_1/Frameworks/Python.framework/Versions/3.11/lib/python3.11/unittest/mock.py", line 1183, in _execute_mock_call
    raise effect
Exception: Command failed
2025-06-06 02:06:58,424 - DEBUG - Executing SQL: SELECT * INVALID SQL
2025-06-06 02:06:58,426 - DEBUG - Executing SQL: SELECT * INVALID SQL
2025-06-06 02:06:58,427 - DEBUG - Executing SQL: SELECT * FROM table
2025-06-06 02:06:58,428 - DEBUG - Executing SQL: SELECT * FROM table
2025-06-06 02:06:58,430 - DEBUG - Executing SQL: SELECT * FROM table
2025-06-06 02:06:58,431 - DEBUG - Executing SQL: SELECT * FROM table
2025-06-06 02:06:58,436 - ERROR - Authentication state polling received 401
2025-06-06 02:06:58,438 - ERROR - Error creating Stitch report: API Error
Traceback (most recent call last):
  File "/Users/johnrush/repos/chuck-data/src/commands/add_stitch_report.py", line 62, in handle_command
    result = client.create_stitch_notebook(table_path, custom_name)
             ^^^^^^^^^^^^^^^^^^^^^^^^^^^^^^^^^^^^^^^^^^^^^^^^^^^^^^
  File "/Users/johnrush/repos/chuck-data/tests/fixtures.py", line 509, in create_stitch_notebook
    raise self._create_stitch_notebook_error
ValueError: API Error
2025-06-06 02:06:58,443 - ERROR - Agent error: Agent error
Traceback (most recent call last):
  File "/Users/johnrush/repos/chuck-data/src/commands/agent.py", line 79, in handle_command
    agent = AgentManager(client, tool_output_callback=tool_output_callback)
            ^^^^^^^^^^^^^^^^^^^^^^^^^^^^^^^^^^^^^^^^^^^^^^^^^^^^^^^^^^^^^^^
  File "/usr/local/Cellar/python@3.11/3.11.4_1/Frameworks/Python.framework/Versions/3.11/lib/python3.11/unittest/mock.py", line 1124, in __call__
    return self._mock_call(*args, **kwargs)
           ^^^^^^^^^^^^^^^^^^^^^^^^^^^^^^^^
  File "/usr/local/Cellar/python@3.11/3.11.4_1/Frameworks/Python.framework/Versions/3.11/lib/python3.11/unittest/mock.py", line 1128, in _mock_call
    return self._execute_mock_call(*args, **kwargs)
           ^^^^^^^^^^^^^^^^^^^^^^^^^^^^^^^^^^^^^^^^
  File "/usr/local/Cellar/python@3.11/3.11.4_1/Frameworks/Python.framework/Versions/3.11/lib/python3.11/unittest/mock.py", line 1183, in _execute_mock_call
    raise effect
Exception: Agent error
2025-06-06 02:06:58,445 - DEBUG - Sending metric: {"event": "USAGE", "configuration": {"workspace_url": "https://dbc-df998298-4c7e.cloud.databricks.co...
2025-06-06 02:06:58,459 - DEBUG - Starting new HTTPS connection (1): chuck.amperity.com:443
2025-06-06 02:06:58,604 - DEBUG - https://chuck.amperity.com:443 "POST /api/usage HTTP/1.1" 204 0
2025-06-06 02:06:58,604 - DEBUG - Failed to send metrics: 204 - 
2025-06-06 02:06:58,607 - DEBUG - Sending metric: {"event": "USAGE", "configuration": {"workspace_url": "https://dbc-df998298-4c7e.cloud.databricks.co...
2025-06-06 02:06:58,610 - DEBUG - Starting new HTTPS connection (1): chuck.amperity.com:443
2025-06-06 02:06:58,741 - DEBUG - https://chuck.amperity.com:443 "POST /api/usage HTTP/1.1" 204 0
2025-06-06 02:06:58,742 - DEBUG - Failed to send metrics: 204 - 
2025-06-06 02:06:58,754 - DEBUG - Sending metric: {"event": "USAGE", "configuration": {"workspace_url": "https://dbc-df998298-4c7e.cloud.databricks.co...
2025-06-06 02:06:58,756 - DEBUG - Starting new HTTPS connection (1): chuck.amperity.com:443
2025-06-06 02:06:58,886 - DEBUG - https://chuck.amperity.com:443 "POST /api/usage HTTP/1.1" 204 0
2025-06-06 02:06:58,886 - DEBUG - Failed to send metrics: 204 - 
2025-06-06 02:06:58,889 - DEBUG - Sending metric: {"event": "USAGE", "configuration": {"workspace_url": "https://dbc-df998298-4c7e.cloud.databricks.co...
2025-06-06 02:06:58,891 - DEBUG - Starting new HTTPS connection (1): chuck.amperity.com:443
2025-06-06 02:06:59,019 - DEBUG - https://chuck.amperity.com:443 "POST /api/usage HTTP/1.1" 204 0
2025-06-06 02:06:59,019 - DEBUG - Failed to send metrics: 204 - 
2025-06-06 02:06:59,021 - DEBUG - Sending metric: {"event": "USAGE", "configuration": {"workspace_url": "https://dbc-df998298-4c7e.cloud.databricks.co...
2025-06-06 02:06:59,023 - DEBUG - Starting new HTTPS connection (1): chuck.amperity.com:443
2025-06-06 02:06:59,151 - DEBUG - https://chuck.amperity.com:443 "POST /api/usage HTTP/1.1" 204 0
2025-06-06 02:06:59,151 - DEBUG - Failed to send metrics: 204 - 
2025-06-06 02:06:59,159 - INFO - Databricks token set successfully
2025-06-06 02:06:59,161 - INFO - Databricks token cleared
2025-06-06 02:06:59,161 - INFO - Amperity token cleared
2025-06-06 02:06:59,162 - INFO - Amperity token cleared
2025-06-06 02:06:59,163 - INFO - Databricks token cleared
2025-06-06 02:06:59,165 - INFO - Amperity token cleared
2025-06-06 02:06:59,175 - DEBUG - Bug report submitted successfully
2025-06-06 02:06:59,230 - ERROR - Error submitting bug report: Network error
Traceback (most recent call last):
  File "/Users/johnrush/repos/chuck-data/src/commands/bug.py", line 72, in handle_command
    success, message = amperity_client.submit_bug_report(payload, amperity_token)
                       ^^^^^^^^^^^^^^^^^^^^^^^^^^^^^^^^^^^^^^^^^^^^^^^^^^^^^^^^^^
  File "/Users/johnrush/repos/chuck-data/tests/commands/test_bug.py", line 115, in submit_bug_report
    raise Exception("Network error")
Exception: Network error
2025-06-06 02:06:59,233 - DEBUG - Loaded configuration from /var/folders/3f/2n5sjdw50vj9gfnrxjbptj4c0000gn/T/tmp4bijx79a.json
2025-06-06 02:06:59,235 - DEBUG - Loaded configuration from /var/folders/3f/2n5sjdw50vj9gfnrxjbptj4c0000gn/T/tmp14vn_o3v.json
2025-06-06 02:06:59,243 - DEBUG - Bug report submitted successfully
2025-06-06 02:06:59,245 - ERROR - Error saving config: [Errno 30] Read-only file system: '/invalid'
2025-06-06 02:06:59,246 - DEBUG - Saved configuration to /var/folders/3f/2n5sjdw50vj9gfnrxjbptj4c0000gn/T/tmpkzsxucr4/test_config.json
2025-06-06 02:06:59,247 - DEBUG - Saved configuration to /var/folders/3f/2n5sjdw50vj9gfnrxjbptj4c0000gn/T/tmpb5y1y3f1/test_config.json
2025-06-06 02:06:59,248 - DEBUG - Loaded configuration from /var/folders/3f/2n5sjdw50vj9gfnrxjbptj4c0000gn/T/tmpb5y1y3f1/test_config.json
2025-06-06 02:06:59,250 - DEBUG - Saved configuration to /var/folders/3f/2n5sjdw50vj9gfnrxjbptj4c0000gn/T/tmpti79bewe/test_config.json
2025-06-06 02:06:59,250 - DEBUG - Loaded configuration from /var/folders/3f/2n5sjdw50vj9gfnrxjbptj4c0000gn/T/tmpti79bewe/test_config.json
2025-06-06 02:06:59,253 - INFO - Cluster init script uploaded successfully to /Volumes/main/default/chuck/cluster_init-2025-06-02_14-30.sh
2025-06-06 02:06:59,257 - DEBUG - Volume 'chuck' not found in main.default. Attempting to create.
2025-06-06 02:06:59,257 - DEBUG - Volume 'chuck' created successfully.
2025-06-06 02:06:59,257 - INFO - Cluster init script uploaded successfully to /Volumes/main/default/chuck/cluster_init-2025-06-02_14-30.sh
2025-06-06 02:06:59,259 - DEBUG - Volume 'chuck' not found in main.default. Attempting to create.
2025-06-06 02:06:59,259 - DEBUG - Volume 'chuck' created successfully.
2025-06-06 02:06:59,259 - INFO - Cluster init script uploaded successfully to /Volumes/main/default/chuck/cluster_init-2025-06-02_14-30.sh
2025-06-06 02:06:59,261 - DEBUG - Volume 'chuck' not found in main.default. Attempting to create.
2025-06-06 02:06:59,262 - DEBUG - Volume 'chuck' not found in main.default. Attempting to create.
2025-06-06 02:06:59,265 - INFO - Cluster init script uploaded successfully to /Volumes/test_catalog/test_schema/chuck/cluster_init-2025-12-31_23-59.sh
2025-06-06 02:06:59,266 - ERROR - Error generating help: Test error
Traceback (most recent call last):
  File "/Users/johnrush/repos/chuck-data/src/commands/help.py", line 27, in handle_command
    user_commands = get_user_commands()
                    ^^^^^^^^^^^^^^^^^^^
  File "/usr/local/Cellar/python@3.11/3.11.4_1/Frameworks/Python.framework/Versions/3.11/lib/python3.11/unittest/mock.py", line 1124, in __call__
    return self._mock_call(*args, **kwargs)
           ^^^^^^^^^^^^^^^^^^^^^^^^^^^^^^^^
  File "/usr/local/Cellar/python@3.11/3.11.4_1/Frameworks/Python.framework/Versions/3.11/lib/python3.11/unittest/mock.py", line 1128, in _mock_call
    return self._execute_mock_call(*args, **kwargs)
           ^^^^^^^^^^^^^^^^^^^^^^^^^^^^^^^^^^^^^^^^
  File "/usr/local/Cellar/python@3.11/3.11.4_1/Frameworks/Python.framework/Versions/3.11/lib/python3.11/unittest/mock.py", line 1183, in _execute_mock_call
    raise effect
Exception: Test error
2025-06-06 02:06:59,270 - ERROR - Failed to get job status for run '999999': Not Found
Traceback (most recent call last):
  File "/Users/johnrush/repos/chuck-data/src/commands/jobs.py", line 67, in handle_job_status
    data = client.get_job_run_status(run_id_str)
           ^^^^^^^^^^^^^^^^^^^^^^^^^^^^^^^^^^^^^
  File "/Users/johnrush/repos/chuck-data/tests/commands/test_jobs.py", line 119, in get_job_run_status
    raise Exception("Not Found")
Exception: Not Found
2025-06-06 02:06:59,273 - ERROR - Failed to submit job: Bad Request
Traceback (most recent call last):
  File "/Users/johnrush/repos/chuck-data/src/commands/jobs.py", line 32, in handle_launch_job
    run_data = client.submit_job_run(
               ^^^^^^^^^^^^^^^^^^^^^^
  File "/Users/johnrush/repos/chuck-data/tests/commands/test_jobs.py", line 70, in submit_job_run
    raise Exception("Bad Request")
Exception: Bad Request
2025-06-06 02:06:59,276 - ERROR - Failed to launch job, no run_id: {}
2025-06-06 02:06:59,279 - ERROR - Error listing catalogs: API error
2025-06-06 02:06:59,284 - DEBUG - Saved configuration to /var/folders/3f/2n5sjdw50vj9gfnrxjbptj4c0000gn/T/tmpbjwjt29s/test_config.json
2025-06-06 02:06:59,284 - DEBUG - Loaded configuration from /var/folders/3f/2n5sjdw50vj9gfnrxjbptj4c0000gn/T/tmpbjwjt29s/test_config.json
2025-06-06 02:06:59,285 - DEBUG - Saved configuration to /var/folders/3f/2n5sjdw50vj9gfnrxjbptj4c0000gn/T/tmp7rbxgmiv/test_config.json
2025-06-06 02:06:59,285 - DEBUG - Loaded configuration from /var/folders/3f/2n5sjdw50vj9gfnrxjbptj4c0000gn/T/tmp7rbxgmiv/test_config.json
2025-06-06 02:06:59,288 - DEBUG - Saved configuration to /var/folders/3f/2n5sjdw50vj9gfnrxjbptj4c0000gn/T/tmpeowol4gc/test_config.json
2025-06-06 02:06:59,288 - DEBUG - Loaded configuration from /var/folders/3f/2n5sjdw50vj9gfnrxjbptj4c0000gn/T/tmpeowol4gc/test_config.json
2025-06-06 02:06:59,289 - ERROR - Failed to list models: API error
Traceback (most recent call last):
  File "/Users/johnrush/repos/chuck-data/src/commands/list_models.py", line 31, in handle_command
    models_list = list_models_api(client)
                  ^^^^^^^^^^^^^^^^^^^^^^^
  File "/Users/johnrush/repos/chuck-data/src/models.py", line 19, in list_models
    return client.list_models()
           ^^^^^^^^^^^^^^^^^^^^
  File "/Users/johnrush/repos/chuck-data/tests/commands/test_list_models.py", line 112, in list_models
    raise Exception("API error")
Exception: API error
2025-06-06 02:06:59,292 - ERROR - Error listing tables: API error
2025-06-06 02:06:59,294 - DEBUG - Saved configuration to /var/folders/3f/2n5sjdw50vj9gfnrxjbptj4c0000gn/T/tmpikn6u0bb/test_config.json
2025-06-06 02:06:59,295 - DEBUG - Loaded configuration from /var/folders/3f/2n5sjdw50vj9gfnrxjbptj4c0000gn/T/tmpikn6u0bb/test_config.json
2025-06-06 02:06:59,295 - DEBUG - Loaded configuration from /var/folders/3f/2n5sjdw50vj9gfnrxjbptj4c0000gn/T/tmpikn6u0bb/test_config.json
2025-06-06 02:06:59,297 - DEBUG - Saved configuration to /var/folders/3f/2n5sjdw50vj9gfnrxjbptj4c0000gn/T/tmp8mefspjt/test_config.json
2025-06-06 02:06:59,297 - DEBUG - Loaded configuration from /var/folders/3f/2n5sjdw50vj9gfnrxjbptj4c0000gn/T/tmp8mefspjt/test_config.json
2025-06-06 02:06:59,298 - DEBUG - Saved configuration to /var/folders/3f/2n5sjdw50vj9gfnrxjbptj4c0000gn/T/tmp8mefspjt/test_config.json
2025-06-06 02:06:59,298 - DEBUG - Loaded configuration from /var/folders/3f/2n5sjdw50vj9gfnrxjbptj4c0000gn/T/tmp8mefspjt/test_config.json
2025-06-06 02:06:59,298 - DEBUG - Loaded configuration from /var/folders/3f/2n5sjdw50vj9gfnrxjbptj4c0000gn/T/tmp8mefspjt/test_config.json
2025-06-06 02:06:59,302 - ERROR - Failed to set model 'claude-v1': API error
Traceback (most recent call last):
  File "/Users/johnrush/repos/chuck-data/src/commands/model_selection.py", line 28, in handle_command
    models_list = list_models_api(client)
                  ^^^^^^^^^^^^^^^^^^^^^^^
  File "/Users/johnrush/repos/chuck-data/src/models.py", line 19, in list_models
    return client.list_models()
           ^^^^^^^^^^^^^^^^^^^^
  File "/Users/johnrush/repos/chuck-data/tests/commands/test_model_selection.py", line 79, in list_models
    raise Exception("API error")
Exception: API error
2025-06-06 02:06:59,304 - DEBUG - Saved configuration to /var/folders/3f/2n5sjdw50vj9gfnrxjbptj4c0000gn/T/tmphfmakf8s/test_config.json
2025-06-06 02:06:59,304 - DEBUG - Loaded configuration from /var/folders/3f/2n5sjdw50vj9gfnrxjbptj4c0000gn/T/tmphfmakf8s/test_config.json
2025-06-06 02:06:59,306 - DEBUG - Saved configuration to /var/folders/3f/2n5sjdw50vj9gfnrxjbptj4c0000gn/T/tmpjco25til/test_config.json
2025-06-06 02:06:59,306 - DEBUG - Loaded configuration from /var/folders/3f/2n5sjdw50vj9gfnrxjbptj4c0000gn/T/tmpjco25til/test_config.json
2025-06-06 02:06:59,307 - DEBUG - Saved configuration to /var/folders/3f/2n5sjdw50vj9gfnrxjbptj4c0000gn/T/tmpwhntrraa/test_config.json
2025-06-06 02:06:59,308 - DEBUG - Loaded configuration from /var/folders/3f/2n5sjdw50vj9gfnrxjbptj4c0000gn/T/tmpwhntrraa/test_config.json
2025-06-06 02:06:59,311 - DEBUG - Saved configuration to /var/folders/3f/2n5sjdw50vj9gfnrxjbptj4c0000gn/T/tmpegh_5unh/test_config.json
2025-06-06 02:06:59,311 - DEBUG - Loaded configuration from /var/folders/3f/2n5sjdw50vj9gfnrxjbptj4c0000gn/T/tmpegh_5unh/test_config.json
2025-06-06 02:06:59,316 - INFO - Starting PII Scan for 2 tables in test_cat.test_schema.
2025-06-06 02:06:59,322 - ERROR - Bulk PII scan error: LLM client error
Traceback (most recent call last):
  File "/Users/johnrush/repos/chuck-data/src/commands/scan_pii.py", line 46, in handle_command
    llm_client = LLMClient()
                 ^^^^^^^^^^^
  File "/usr/local/Cellar/python@3.11/3.11.4_1/Frameworks/Python.framework/Versions/3.11/lib/python3.11/unittest/mock.py", line 1124, in __call__
    return self._mock_call(*args, **kwargs)
           ^^^^^^^^^^^^^^^^^^^^^^^^^^^^^^^^
  File "/usr/local/Cellar/python@3.11/3.11.4_1/Frameworks/Python.framework/Versions/3.11/lib/python3.11/unittest/mock.py", line 1128, in _mock_call
    return self._execute_mock_call(*args, **kwargs)
           ^^^^^^^^^^^^^^^^^^^^^^^^^^^^^^^^^^^^^^^^
  File "/usr/local/Cellar/python@3.11/3.11.4_1/Frameworks/Python.framework/Versions/3.11/lib/python3.11/unittest/mock.py", line 1183, in _execute_mock_call
    raise effect
Exception: LLM client error
2025-06-06 02:06:59,328 - DEBUG - Saved configuration to /var/folders/3f/2n5sjdw50vj9gfnrxjbptj4c0000gn/T/tmpapbp5ki2/test_config.json
2025-06-06 02:06:59,328 - DEBUG - Loaded configuration from /var/folders/3f/2n5sjdw50vj9gfnrxjbptj4c0000gn/T/tmpapbp5ki2/test_config.json
2025-06-06 02:06:59,328 - DEBUG - Loaded configuration from /var/folders/3f/2n5sjdw50vj9gfnrxjbptj4c0000gn/T/tmpapbp5ki2/test_config.json
2025-06-06 02:06:59,329 - DEBUG - Saved configuration to /var/folders/3f/2n5sjdw50vj9gfnrxjbptj4c0000gn/T/tmpapbp5ki2/test_config.json
2025-06-06 02:06:59,330 - DEBUG - Saved configuration to /var/folders/3f/2n5sjdw50vj9gfnrxjbptj4c0000gn/T/tmp1vvknyeh/test_config.json
2025-06-06 02:06:59,330 - DEBUG - Loaded configuration from /var/folders/3f/2n5sjdw50vj9gfnrxjbptj4c0000gn/T/tmp1vvknyeh/test_config.json
2025-06-06 02:06:59,330 - DEBUG - Loaded configuration from /var/folders/3f/2n5sjdw50vj9gfnrxjbptj4c0000gn/T/tmp1vvknyeh/test_config.json
2025-06-06 02:06:59,331 - DEBUG - Saved configuration to /var/folders/3f/2n5sjdw50vj9gfnrxjbptj4c0000gn/T/tmp1vvknyeh/test_config.json
2025-06-06 02:06:59,331 - DEBUG - Loaded configuration from /var/folders/3f/2n5sjdw50vj9gfnrxjbptj4c0000gn/T/tmp1vvknyeh/test_config.json
2025-06-06 02:06:59,332 - DEBUG - Saved configuration to /var/folders/3f/2n5sjdw50vj9gfnrxjbptj4c0000gn/T/tmp7ucsrlbb/test_config.json
2025-06-06 02:06:59,332 - DEBUG - Loaded configuration from /var/folders/3f/2n5sjdw50vj9gfnrxjbptj4c0000gn/T/tmp7ucsrlbb/test_config.json
2025-06-06 02:06:59,333 - DEBUG - Loaded configuration from /var/folders/3f/2n5sjdw50vj9gfnrxjbptj4c0000gn/T/tmp7ucsrlbb/test_config.json
2025-06-06 02:06:59,333 - DEBUG - Saved configuration to /var/folders/3f/2n5sjdw50vj9gfnrxjbptj4c0000gn/T/tmp7ucsrlbb/test_config.json
2025-06-06 02:06:59,333 - DEBUG - Loaded configuration from /var/folders/3f/2n5sjdw50vj9gfnrxjbptj4c0000gn/T/tmp7ucsrlbb/test_config.json
2025-06-06 02:06:59,337 - DEBUG - Sending metric: {"event": "USAGE", "configuration": {"workspace_url": "https://dbc-df998298-4c7e.cloud.databricks.co...
2025-06-06 02:06:59,339 - DEBUG - Starting new HTTPS connection (1): chuck.amperity.com:443
2025-06-06 02:06:59,457 - DEBUG - https://chuck.amperity.com:443 "POST /api/usage HTTP/1.1" 204 0
2025-06-06 02:06:59,458 - DEBUG - Failed to send metrics: 204 - 
2025-06-06 02:06:59,460 - ERROR - Stitch setup error: LLM client error
Traceback (most recent call last):
  File "/Users/johnrush/repos/chuck-data/src/commands/setup_stitch.py", line 111, in handle_command
    return _phase_1_prepare_config(
           ^^^^^^^^^^^^^^^^^^^^^^^^
  File "/Users/johnrush/repos/chuck-data/src/commands/setup_stitch.py", line 273, in _phase_1_prepare_config
    llm_client = LLMClient()
                 ^^^^^^^^^^^
  File "/usr/local/Cellar/python@3.11/3.11.4_1/Frameworks/Python.framework/Versions/3.11/lib/python3.11/unittest/mock.py", line 1124, in __call__
    return self._mock_call(*args, **kwargs)
           ^^^^^^^^^^^^^^^^^^^^^^^^^^^^^^^^
  File "/usr/local/Cellar/python@3.11/3.11.4_1/Frameworks/Python.framework/Versions/3.11/lib/python3.11/unittest/mock.py", line 1128, in _mock_call
    return self._execute_mock_call(*args, **kwargs)
           ^^^^^^^^^^^^^^^^^^^^^^^^^^^^^^^^^^^^^^^^
  File "/usr/local/Cellar/python@3.11/3.11.4_1/Frameworks/Python.framework/Versions/3.11/lib/python3.11/unittest/mock.py", line 1183, in _execute_mock_call
    raise effect
Exception: LLM client error
2025-06-06 02:06:59,468 - DEBUG - GET request to: https://.cloud.databricks.com/api/2.0/preview/scim/v2/Me
2025-06-06 02:06:59,468 - DEBUG - Connection error: URL has an invalid label.
2025-06-06 02:06:59,468 - DEBUG - Token validation failed: Connection error occurred: URL has an invalid label.
2025-06-06 02:06:59,470 - ERROR - Error validating token: Connection failed
2025-06-06 02:06:59,474 - DEBUG - GET request to: https://invalid-workspace.nonexistent.com.cloud.databricks.com/api/2.0/preview/scim/v2/Me
2025-06-06 02:06:59,477 - DEBUG - Starting new HTTPS connection (1): invalid-workspace.nonexistent.com.cloud.databricks.com:443
2025-06-06 02:06:59,478 - DEBUG - Connection error: HTTPSConnectionPool(host='invalid-workspace.nonexistent.com.cloud.databricks.com', port=443): Max retries exceeded with url: /api/2.0/preview/scim/v2/Me (Caused by NameResolutionError("<urllib3.connection.HTTPSConnection object at 0x111301890>: Failed to resolve 'invalid-workspace.nonexistent.com.cloud.databricks.com' ([Errno 8] nodename nor servname provided, or not known)"))
2025-06-06 02:06:59,478 - DEBUG - Token validation failed: Connection error occurred: HTTPSConnectionPool(host='invalid-workspace.nonexistent.com.cloud.databricks.com', port=443): Max retries exceeded with url: /api/2.0/preview/scim/v2/Me (Caused by NameResolutionError("<urllib3.connection.HTTPSConnection object at 0x111301890>: Failed to resolve 'invalid-workspace.nonexistent.com.cloud.databricks.com' ([Errno 8] nodename nor servname provided, or not known)"))
2025-06-06 02:06:59,572 - DEBUG - GET request to: https://invalid.nonexistent.com.cloud.databricks.com/api/2.0/preview/scim/v2/Me
2025-06-06 02:06:59,575 - DEBUG - Starting new HTTPS connection (1): invalid.nonexistent.com.cloud.databricks.com:443
2025-06-06 02:06:59,576 - DEBUG - Connection error: HTTPSConnectionPool(host='invalid.nonexistent.com.cloud.databricks.com', port=443): Max retries exceeded with url: /api/2.0/preview/scim/v2/Me (Caused by NameResolutionError("<urllib3.connection.HTTPSConnection object at 0x111366b10>: Failed to resolve 'invalid.nonexistent.com.cloud.databricks.com' ([Errno 8] nodename nor servname provided, or not known)"))
2025-06-06 02:06:59,576 - DEBUG - Token validation failed: Connection error occurred: HTTPSConnectionPool(host='invalid.nonexistent.com.cloud.databricks.com', port=443): Max retries exceeded with url: /api/2.0/preview/scim/v2/Me (Caused by NameResolutionError("<urllib3.connection.HTTPSConnection object at 0x111366b10>: Failed to resolve 'invalid.nonexistent.com.cloud.databricks.com' ([Errno 8] nodename nor servname provided, or not known)"))
2025-06-06 02:06:59,577 - ERROR - Error validating token: Validation failed
2025-06-06 02:06:59,694 - ERROR - Error validating token: Connection failed
2025-06-06 02:06:59,729 - ERROR - Error validating token: Network error with secret details
2025-06-06 02:06:59,765 - ERROR - Error validating token: Connection error: Failed to resolve 'workspace123.cloud.databricks.com'
2025-06-06 02:06:59,774 - ERROR - Error fetching Amperity init script: API Error
Traceback (most recent call last):
  File "/Users/johnrush/repos/chuck-data/src/commands/stitch_tools.py", line 179, in _helper_prepare_stitch_config
    init_script_data = client.fetch_amperity_job_init(amperity_token)
                       ^^^^^^^^^^^^^^^^^^^^^^^^^^^^^^^^^^^^^^^^^^^^^^
  File "/usr/local/Cellar/python@3.11/3.11.4_1/Frameworks/Python.framework/Versions/3.11/lib/python3.11/unittest/mock.py", line 1124, in __call__
    return self._mock_call(*args, **kwargs)
           ^^^^^^^^^^^^^^^^^^^^^^^^^^^^^^^^
  File "/usr/local/Cellar/python@3.11/3.11.4_1/Frameworks/Python.framework/Versions/3.11/lib/python3.11/unittest/mock.py", line 1128, in _mock_call
    return self._execute_mock_call(*args, **kwargs)
           ^^^^^^^^^^^^^^^^^^^^^^^^^^^^^^^^^^^^^^^^
  File "/usr/local/Cellar/python@3.11/3.11.4_1/Frameworks/Python.framework/Versions/3.11/lib/python3.11/unittest/mock.py", line 1183, in _execute_mock_call
    raise effect
Exception: API Error
2025-06-06 02:06:59,781 - DEBUG - Versioned cluster init script uploaded to /Volumes/test_catalog/test_schema/chuck/cluster_init-2025-06-02_14-30.sh
2025-06-06 02:06:59,782 - DEBUG - Versioned cluster init script uploaded to /Volumes/test_catalog/test_schema/chuck/cluster_init-2025-06-02_14-30.sh
2025-06-06 02:06:59,785 - DEBUG - Volume 'chuck' not found in test_catalog.test_schema. Attempting to create.
2025-06-06 02:06:59,793 - DEBUG - Saved configuration to /var/folders/3f/2n5sjdw50vj9gfnrxjbptj4c0000gn/T/tmp1u30cymp/test_config.json
2025-06-06 02:06:59,794 - DEBUG - Loaded configuration from /var/folders/3f/2n5sjdw50vj9gfnrxjbptj4c0000gn/T/tmp1u30cymp/test_config.json
2025-06-06 02:06:59,794 - DEBUG - Loaded configuration from /var/folders/3f/2n5sjdw50vj9gfnrxjbptj4c0000gn/T/tmp1u30cymp/test_config.json
2025-06-06 02:06:59,794 - DEBUG - Loaded configuration from /var/folders/3f/2n5sjdw50vj9gfnrxjbptj4c0000gn/T/tmp1u30cymp/test_config.json
2025-06-06 02:06:59,796 - DEBUG - Saved configuration to /var/folders/3f/2n5sjdw50vj9gfnrxjbptj4c0000gn/T/tmpnkfaoixg/test_config.json
2025-06-06 02:06:59,796 - DEBUG - Loaded configuration from /var/folders/3f/2n5sjdw50vj9gfnrxjbptj4c0000gn/T/tmpnkfaoixg/test_config.json
2025-06-06 02:06:59,796 - DEBUG - Saved configuration to /var/folders/3f/2n5sjdw50vj9gfnrxjbptj4c0000gn/T/tmpnkfaoixg/test_config.json
2025-06-06 02:06:59,796 - DEBUG - Loaded configuration from /var/folders/3f/2n5sjdw50vj9gfnrxjbptj4c0000gn/T/tmpnkfaoixg/test_config.json
2025-06-06 02:06:59,796 - DEBUG - Saved configuration to /var/folders/3f/2n5sjdw50vj9gfnrxjbptj4c0000gn/T/tmpnkfaoixg/test_config.json
2025-06-06 02:06:59,797 - DEBUG - Loaded configuration from /var/folders/3f/2n5sjdw50vj9gfnrxjbptj4c0000gn/T/tmpnkfaoixg/test_config.json
2025-06-06 02:06:59,797 - DEBUG - Loaded configuration from /var/folders/3f/2n5sjdw50vj9gfnrxjbptj4c0000gn/T/tmpnkfaoixg/test_config.json
2025-06-06 02:06:59,797 - DEBUG - Loaded configuration from /var/folders/3f/2n5sjdw50vj9gfnrxjbptj4c0000gn/T/tmpnkfaoixg/test_config.json
2025-06-06 02:06:59,798 - INFO - Applying tag 'email' to column 'email_col'
2025-06-06 02:06:59,798 - INFO - Applying tag 'given-name' to column 'name_col'
2025-06-06 02:06:59,799 - INFO - Applying tag 'phone' to column 'good_col'
2025-06-06 02:06:59,800 - INFO - Applying tag 'email' to column 'email_col'
2025-06-06 02:06:59,801 - INFO - Applying tag 'email' to column 'email_col'
2025-06-06 02:06:59,802 - ERROR - Error applying tag to email_col: Connection error
2025-06-06 02:06:59,804 - DEBUG - Saved configuration to /var/folders/3f/2n5sjdw50vj9gfnrxjbptj4c0000gn/T/tmplm7t5eni/test_config.json
2025-06-06 02:06:59,804 - DEBUG - Loaded configuration from /var/folders/3f/2n5sjdw50vj9gfnrxjbptj4c0000gn/T/tmplm7t5eni/test_config.json
2025-06-06 02:06:59,806 - DEBUG - Saved configuration to /var/folders/3f/2n5sjdw50vj9gfnrxjbptj4c0000gn/T/tmp6govwmwb/test_config.json
2025-06-06 02:06:59,807 - DEBUG - Saved configuration to /var/folders/3f/2n5sjdw50vj9gfnrxjbptj4c0000gn/T/tmprmzmblee/test_config.json
2025-06-06 02:06:59,807 - DEBUG - Loaded configuration from /var/folders/3f/2n5sjdw50vj9gfnrxjbptj4c0000gn/T/tmprmzmblee/test_config.json
2025-06-06 02:06:59,809 - DEBUG - Saved configuration to /var/folders/3f/2n5sjdw50vj9gfnrxjbptj4c0000gn/T/tmpcc5rfkm0/test_config.json
2025-06-06 02:06:59,809 - DEBUG - Loaded configuration from /var/folders/3f/2n5sjdw50vj9gfnrxjbptj4c0000gn/T/tmpcc5rfkm0/test_config.json
2025-06-06 02:06:59,813 - ERROR - Failed to set workspace URL: Validation error
Traceback (most recent call last):
  File "/Users/johnrush/repos/chuck-data/src/commands/workspace_selection.py", line 37, in handle_command
    is_valid, error_message = validate_workspace_url(workspace_url)
                              ^^^^^^^^^^^^^^^^^^^^^^^^^^^^^^^^^^^^^
  File "/usr/local/Cellar/python@3.11/3.11.4_1/Frameworks/Python.framework/Versions/3.11/lib/python3.11/unittest/mock.py", line 1124, in __call__
    return self._mock_call(*args, **kwargs)
           ^^^^^^^^^^^^^^^^^^^^^^^^^^^^^^^^
  File "/usr/local/Cellar/python@3.11/3.11.4_1/Frameworks/Python.framework/Versions/3.11/lib/python3.11/unittest/mock.py", line 1128, in _mock_call
    return self._execute_mock_call(*args, **kwargs)
           ^^^^^^^^^^^^^^^^^^^^^^^^^^^^^^^^^^^^^^^^
  File "/usr/local/Cellar/python@3.11/3.11.4_1/Frameworks/Python.framework/Versions/3.11/lib/python3.11/unittest/mock.py", line 1183, in _execute_mock_call
    raise effect
Exception: Validation error
