2025-06-06 17:00:06,530 - DEBUG - Logging initialized. Writing to /Users/johnrush/repos/chuck-data/log/sessions/2025-06-06_17-00-06.log
2025-06-06 17:00:06,535 - DEBUG - HTTP error: HTTP 401, Response: {"status":401,"message":"Unauthorized"}
2025-06-06 17:00:06,538 - DEBUG - GET request to: https://test-workspace.cloud.databricks.com/test-endpoint
2025-06-06 17:00:06,538 - DEBUG - Connection error: Connection failed
2025-06-06 17:00:06,540 - DEBUG - GET request to: https://test-workspace.cloud.databricks.com/test-endpoint
2025-06-06 17:00:06,541 - DEBUG - HTTP error: HTTP 404, Response: Not Found
2025-06-06 17:00:06,542 - DEBUG - GET request to: https://test-workspace.cloud.databricks.com/test-endpoint
2025-06-06 17:00:06,544 - DEBUG - POST request to: https://test-workspace.cloud.databricks.com/test-endpoint
2025-06-06 17:00:06,545 - DEBUG - Connection error: Connection failed
2025-06-06 17:00:06,546 - DEBUG - POST request to: https://test-workspace.cloud.databricks.com/test-endpoint
2025-06-06 17:00:06,547 - DEBUG - HTTP error: HTTP 400, Response: Bad Request
2025-06-06 17:00:06,549 - DEBUG - POST request to: https://test-workspace.cloud.databricks.com/test-endpoint
2025-06-06 17:00:06,554 - DEBUG - Saved configuration to /var/folders/3f/2n5sjdw50vj9gfnrxjbptj4c0000gn/T/tmpkipse73h/test_config.json
2025-06-06 17:00:06,554 - DEBUG - Loaded configuration from /var/folders/3f/2n5sjdw50vj9gfnrxjbptj4c0000gn/T/tmpkipse73h/test_config.json
2025-06-06 17:00:06,555 - DEBUG - Loaded configuration from /var/folders/3f/2n5sjdw50vj9gfnrxjbptj4c0000gn/T/tmpkipse73h/test_config.json
2025-06-06 17:00:06,555 - DEBUG - Saved configuration to /var/folders/3f/2n5sjdw50vj9gfnrxjbptj4c0000gn/T/tmpkipse73h/test_config.json
2025-06-06 17:00:06,555 - DEBUG - Loaded configuration from /var/folders/3f/2n5sjdw50vj9gfnrxjbptj4c0000gn/T/tmpkipse73h/test_config.json
2025-06-06 17:00:06,556 - DEBUG - Saved configuration to /var/folders/3f/2n5sjdw50vj9gfnrxjbptj4c0000gn/T/tmpkipse73h/test_config.json
2025-06-06 17:00:06,556 - DEBUG - Loaded configuration from /var/folders/3f/2n5sjdw50vj9gfnrxjbptj4c0000gn/T/tmpkipse73h/test_config.json
2025-06-06 17:00:06,556 - DEBUG - Saved configuration to /var/folders/3f/2n5sjdw50vj9gfnrxjbptj4c0000gn/T/tmpkipse73h/test_config.json
2025-06-06 17:00:06,556 - DEBUG - Loaded configuration from /var/folders/3f/2n5sjdw50vj9gfnrxjbptj4c0000gn/T/tmpkipse73h/test_config.json
2025-06-06 17:00:06,557 - DEBUG - Saved configuration to /var/folders/3f/2n5sjdw50vj9gfnrxjbptj4c0000gn/T/tmpkipse73h/test_config.json
2025-06-06 17:00:06,557 - DEBUG - Loaded configuration from /var/folders/3f/2n5sjdw50vj9gfnrxjbptj4c0000gn/T/tmpkipse73h/test_config.json
2025-06-06 17:00:06,557 - DEBUG - Loaded configuration from /var/folders/3f/2n5sjdw50vj9gfnrxjbptj4c0000gn/T/tmpkipse73h/test_config.json
2025-06-06 17:00:06,557 - DEBUG - Loaded configuration from /var/folders/3f/2n5sjdw50vj9gfnrxjbptj4c0000gn/T/tmpkipse73h/test_config.json
2025-06-06 17:00:06,557 - DEBUG - Loaded configuration from /var/folders/3f/2n5sjdw50vj9gfnrxjbptj4c0000gn/T/tmpkipse73h/test_config.json
2025-06-06 17:00:06,557 - DEBUG - Loaded configuration from /var/folders/3f/2n5sjdw50vj9gfnrxjbptj4c0000gn/T/tmpkipse73h/test_config.json
2025-06-06 17:00:06,560 - DEBUG - Saved configuration to /var/folders/3f/2n5sjdw50vj9gfnrxjbptj4c0000gn/T/tmpzifbgv1m/test_config.json
2025-06-06 17:00:06,560 - DEBUG - Loaded configuration from /var/folders/3f/2n5sjdw50vj9gfnrxjbptj4c0000gn/T/tmpzifbgv1m/test_config.json
2025-06-06 17:00:06,563 - DEBUG - Saved configuration to /var/folders/3f/2n5sjdw50vj9gfnrxjbptj4c0000gn/T/tmp5x8l1djn/test_config.json
2025-06-06 17:00:06,563 - DEBUG - Loaded configuration from /var/folders/3f/2n5sjdw50vj9gfnrxjbptj4c0000gn/T/tmp5x8l1djn/test_config.json
2025-06-06 17:00:06,565 - DEBUG - Saved configuration to /var/folders/3f/2n5sjdw50vj9gfnrxjbptj4c0000gn/T/tmpmckf7469/test_config.json
2025-06-06 17:00:06,565 - DEBUG - Loaded configuration from /var/folders/3f/2n5sjdw50vj9gfnrxjbptj4c0000gn/T/tmpmckf7469/test_config.json
2025-06-06 17:00:06,566 - DEBUG - Loaded configuration from /var/folders/3f/2n5sjdw50vj9gfnrxjbptj4c0000gn/T/tmpmckf7469/test_config.json
2025-06-06 17:00:06,566 - DEBUG - Saved configuration to /var/folders/3f/2n5sjdw50vj9gfnrxjbptj4c0000gn/T/tmpmckf7469/test_config.json
2025-06-06 17:00:06,566 - DEBUG - Loaded configuration from /var/folders/3f/2n5sjdw50vj9gfnrxjbptj4c0000gn/T/tmpmckf7469/test_config.json
2025-06-06 17:00:06,567 - DEBUG - Loaded configuration from /var/folders/3f/2n5sjdw50vj9gfnrxjbptj4c0000gn/T/tmpmckf7469/test_config.json
2025-06-06 17:00:06,570 - DEBUG - Saved configuration to /var/folders/3f/2n5sjdw50vj9gfnrxjbptj4c0000gn/T/tmppyf3ni42/test_config.json
2025-06-06 17:00:06,571 - DEBUG - Loaded configuration from /var/folders/3f/2n5sjdw50vj9gfnrxjbptj4c0000gn/T/tmppyf3ni42/test_config.json
2025-06-06 17:00:06,571 - DEBUG - Loaded configuration from /var/folders/3f/2n5sjdw50vj9gfnrxjbptj4c0000gn/T/tmppyf3ni42/test_config.json
2025-06-06 17:00:06,571 - DEBUG - Saved configuration to /var/folders/3f/2n5sjdw50vj9gfnrxjbptj4c0000gn/T/tmppyf3ni42/test_config.json
2025-06-06 17:00:06,571 - DEBUG - Loaded configuration from /var/folders/3f/2n5sjdw50vj9gfnrxjbptj4c0000gn/T/tmppyf3ni42/test_config.json
2025-06-06 17:00:06,572 - DEBUG - Saved configuration to /var/folders/3f/2n5sjdw50vj9gfnrxjbptj4c0000gn/T/tmppyf3ni42/test_config.json
2025-06-06 17:00:06,572 - DEBUG - Loaded configuration from /var/folders/3f/2n5sjdw50vj9gfnrxjbptj4c0000gn/T/tmppyf3ni42/test_config.json
2025-06-06 17:00:06,572 - DEBUG - Saved configuration to /var/folders/3f/2n5sjdw50vj9gfnrxjbptj4c0000gn/T/tmppyf3ni42/test_config.json
2025-06-06 17:00:06,573 - DEBUG - Loaded configuration from /var/folders/3f/2n5sjdw50vj9gfnrxjbptj4c0000gn/T/tmppyf3ni42/test_config.json
2025-06-06 17:00:06,573 - DEBUG - Saved configuration to /var/folders/3f/2n5sjdw50vj9gfnrxjbptj4c0000gn/T/tmppyf3ni42/test_config.json
2025-06-06 17:00:06,573 - DEBUG - Loaded configuration from /var/folders/3f/2n5sjdw50vj9gfnrxjbptj4c0000gn/T/tmppyf3ni42/test_config.json
2025-06-06 17:00:06,573 - DEBUG - Using workspace_url from environment variable CHUCK_WORKSPACE_URL
2025-06-06 17:00:06,573 - DEBUG - Using active_model from environment variable CHUCK_ACTIVE_MODEL
2025-06-06 17:00:06,573 - DEBUG - Using warehouse_id from environment variable CHUCK_WAREHOUSE_ID
2025-06-06 17:00:06,573 - DEBUG - Using active_catalog from environment variable CHUCK_ACTIVE_CATALOG
2025-06-06 17:00:06,573 - DEBUG - Using active_schema from environment variable CHUCK_ACTIVE_SCHEMA
2025-06-06 17:00:06,573 - DEBUG - Using usage_tracking_consent from environment variable CHUCK_USAGE_TRACKING_CONSENT
2025-06-06 17:00:06,574 - DEBUG - Loaded configuration from /var/folders/3f/2n5sjdw50vj9gfnrxjbptj4c0000gn/T/tmppyf3ni42/test_config.json
2025-06-06 17:00:06,576 - DEBUG - Saved configuration to /var/folders/3f/2n5sjdw50vj9gfnrxjbptj4c0000gn/T/tmp50xikh79/test_config.json
2025-06-06 17:00:06,576 - DEBUG - Loaded configuration from /var/folders/3f/2n5sjdw50vj9gfnrxjbptj4c0000gn/T/tmp50xikh79/test_config.json
2025-06-06 17:00:06,576 - DEBUG - Loaded configuration from /var/folders/3f/2n5sjdw50vj9gfnrxjbptj4c0000gn/T/tmp50xikh79/test_config.json
2025-06-06 17:00:06,576 - WARNING - Invalid workspace_url provided, using default instead
2025-06-06 17:00:06,577 - DEBUG - Saved configuration to /var/folders/3f/2n5sjdw50vj9gfnrxjbptj4c0000gn/T/tmp50xikh79/test_config.json
2025-06-06 17:00:06,577 - DEBUG - Loaded configuration from /var/folders/3f/2n5sjdw50vj9gfnrxjbptj4c0000gn/T/tmp50xikh79/test_config.json
2025-06-06 17:00:06,577 - DEBUG - Loaded configuration from /var/folders/3f/2n5sjdw50vj9gfnrxjbptj4c0000gn/T/tmp50xikh79/test_config.json
2025-06-06 17:00:06,577 - DEBUG - Saved configuration to /var/folders/3f/2n5sjdw50vj9gfnrxjbptj4c0000gn/T/tmp50xikh79/test_config.json
2025-06-06 17:00:06,577 - DEBUG - Loaded configuration from /var/folders/3f/2n5sjdw50vj9gfnrxjbptj4c0000gn/T/tmp50xikh79/test_config.json
2025-06-06 17:00:06,580 - DEBUG - Using workspace_url from environment variable CHUCK_WORKSPACE_URL
2025-06-06 17:00:06,580 - DEBUG - Using workspace_url from environment variable CHUCK_WORKSPACE_URL
2025-06-06 17:00:06,580 - DEBUG - Using active_model from environment variable CHUCK_ACTIVE_MODEL
2025-06-06 17:00:06,580 - DEBUG - Using amperity_token from environment variable CHUCK_AMPERITY_TOKEN
2025-06-06 17:00:06,580 - DEBUG - Using databricks_token from environment variable CHUCK_DATABRICKS_TOKEN
2025-06-06 17:00:06,581 - DEBUG - Saved configuration to /var/folders/3f/2n5sjdw50vj9gfnrxjbptj4c0000gn/T/tmpv74is_z9/test_config.json
2025-06-06 17:00:06,581 - DEBUG - Loaded configuration from /var/folders/3f/2n5sjdw50vj9gfnrxjbptj4c0000gn/T/tmpv74is_z9/test_config.json
2025-06-06 17:00:06,584 - DEBUG - Saved configuration to /var/folders/3f/2n5sjdw50vj9gfnrxjbptj4c0000gn/T/tmpar62ixq3/test_config.json
2025-06-06 17:00:06,604 - DEBUG - GET request to: https://adb-3856707039489412.12.azuredatabricks.net/test-endpoint
2025-06-06 17:00:06,611 - DEBUG - GET request to: https://test-workspace.cloud.databricks.com/test-endpoint
2025-06-06 17:00:06,611 - DEBUG - Connection error: Connection failed
2025-06-06 17:00:06,613 - DEBUG - GET request to: https://test-workspace.cloud.databricks.com/test-endpoint
2025-06-06 17:00:06,613 - DEBUG - HTTP error: HTTP 404, Response: Not Found
2025-06-06 17:00:06,615 - WARNING - Model 'nonexistent-model' not found
2025-06-06 17:00:06,617 - DEBUG - GET request to: https://test-workspace.cloud.databricks.com/test-endpoint
2025-06-06 17:00:06,628 - DEBUG - POST request to: https://test-workspace.cloud.databricks.com/test-endpoint
2025-06-06 17:00:06,628 - DEBUG - Connection error: Connection failed
2025-06-06 17:00:06,630 - DEBUG - POST request to: https://test-workspace.cloud.databricks.com/test-endpoint
2025-06-06 17:00:06,630 - DEBUG - HTTP error: HTTP 400, Response: Bad Request
2025-06-06 17:00:06,632 - DEBUG - POST request to: https://test-workspace.cloud.databricks.com/test-endpoint
2025-06-06 17:00:06,635 - DEBUG - File upload request to: https://test-workspace.cloud.databricks.com/api/2.0/fs/files/test/path.txt
2025-06-06 17:00:06,640 - DEBUG - File upload request to: https://test-workspace.cloud.databricks.com/api/2.0/fs/files/test/path.txt
2025-06-06 17:00:06,642 - DEBUG - Token validation failed: Token validation failed
2025-06-06 17:00:06,646 - DEBUG - Saved configuration to /tmp/.test_chuck_integration_config.json
2025-06-06 17:00:06,646 - DEBUG - Saved configuration to /tmp/.test_chuck_integration_config.json
2025-06-06 17:00:06,648 - DEBUG - Saved configuration to /tmp/.test_chuck_integration_config.json
2025-06-06 17:00:06,649 - DEBUG - Saved configuration to /tmp/.test_chuck_integration_config.json
2025-06-06 17:00:06,650 - DEBUG - Saved configuration to /tmp/.test_chuck_integration_config.json
2025-06-06 17:00:06,651 - DEBUG - Saved configuration to /tmp/.test_chuck_integration_config.json
2025-06-06 17:00:06,659 - DEBUG - Sending metric: {"event": "USAGE", "prompt": "test prompt"}...
2025-06-06 17:00:06,659 - DEBUG - Error sending metrics: Test exception
Traceback (most recent call last):
  File "/Users/johnrush/repos/chuck-data/chuck_data/metrics_collector.py", line 123, in send_metric
    return self._client.submit_metrics(payload, token)
           ^^^^^^^^^^^^^^^^^^^^^^^^^^^^^^^^^^^^^^^^^^^
  File "/Users/johnrush/repos/chuck-data/tests/fixtures.py", line 60, in submit_metrics
    raise Exception("Test exception")
Exception: Test exception
2025-06-06 17:00:06,662 - DEBUG - Sending metric: {"event": "USAGE", "prompt": "test prompt"}...
2025-06-06 17:00:06,663 - DEBUG - Cannot send metrics - no authentication token available
2025-06-06 17:00:06,665 - DEBUG - Sending metric: {"event": "USAGE", "prompt": "test prompt"}...
2025-06-06 17:00:06,670 - DEBUG - Metrics tracking skipped - user has not provided consent
2025-06-06 17:00:06,674 - ERROR - Connection error when getting model: Connection failed
2025-06-06 17:00:06,675 - ERROR - Failed to get model: HTTP error occurred: 500 Internal Server Error
2025-06-06 17:00:06,678 - ERROR - Connection error when listing models: Connection failed
2025-06-06 17:00:06,680 - ERROR - Failed to list models: HTTP error occurred: 404 Not Found
2025-06-06 17:00:06,745 - ERROR - Error executing handler for command 'test_command': Command failed
Traceback (most recent call last):
  File "/Users/johnrush/repos/chuck-data/chuck_data/service.py", line 395, in execute_command
    result: CommandResult = command_def.handler(
                            ^^^^^^^^^^^^^^^^^^^^
  File "/usr/local/Cellar/python@3.11/3.11.4_1/Frameworks/Python.framework/Versions/3.11/lib/python3.11/unittest/mock.py", line 1124, in __call__
    return self._mock_call(*args, **kwargs)
           ^^^^^^^^^^^^^^^^^^^^^^^^^^^^^^^^
  File "/usr/local/Cellar/python@3.11/3.11.4_1/Frameworks/Python.framework/Versions/3.11/lib/python3.11/unittest/mock.py", line 1128, in _mock_call
    return self._execute_mock_call(*args, **kwargs)
           ^^^^^^^^^^^^^^^^^^^^^^^^^^^^^^^^^^^^^^^^
  File "/usr/local/Cellar/python@3.11/3.11.4_1/Frameworks/Python.framework/Versions/3.11/lib/python3.11/unittest/mock.py", line 1183, in _execute_mock_call
    raise effect
Exception: Command failed
2025-06-06 17:00:06,811 - DEBUG - Executing SQL: SELECT * INVALID SQL
2025-06-06 17:00:06,813 - DEBUG - Executing SQL: SELECT * INVALID SQL
2025-06-06 17:00:06,815 - DEBUG - Executing SQL: SELECT * FROM table
2025-06-06 17:00:06,818 - DEBUG - Executing SQL: SELECT * FROM table
2025-06-06 17:00:06,820 - DEBUG - Executing SQL: SELECT * FROM table
2025-06-06 17:00:06,822 - DEBUG - Executing SQL: SELECT * FROM table
2025-06-06 17:00:06,831 - ERROR - Authentication state polling received 401
2025-06-06 17:00:06,836 - ERROR - Error creating Stitch report: API Error
Traceback (most recent call last):
  File "/Users/johnrush/repos/chuck-data/chuck_data/commands/add_stitch_report.py", line 62, in handle_command
    result = client.create_stitch_notebook(table_path, custom_name)
             ^^^^^^^^^^^^^^^^^^^^^^^^^^^^^^^^^^^^^^^^^^^^^^^^^^^^^^
  File "/Users/johnrush/repos/chuck-data/tests/fixtures.py", line 528, in create_stitch_notebook
    raise self._create_stitch_notebook_error
ValueError: API Error
2025-06-06 17:00:06,842 - ERROR - Agent error: Agent error
Traceback (most recent call last):
  File "/Users/johnrush/repos/chuck-data/chuck_data/commands/agent.py", line 79, in handle_command
    agent = AgentManager(client, tool_output_callback=tool_output_callback)
            ^^^^^^^^^^^^^^^^^^^^^^^^^^^^^^^^^^^^^^^^^^^^^^^^^^^^^^^^^^^^^^^
  File "/usr/local/Cellar/python@3.11/3.11.4_1/Frameworks/Python.framework/Versions/3.11/lib/python3.11/unittest/mock.py", line 1124, in __call__
    return self._mock_call(*args, **kwargs)
           ^^^^^^^^^^^^^^^^^^^^^^^^^^^^^^^^
  File "/usr/local/Cellar/python@3.11/3.11.4_1/Frameworks/Python.framework/Versions/3.11/lib/python3.11/unittest/mock.py", line 1128, in _mock_call
    return self._execute_mock_call(*args, **kwargs)
           ^^^^^^^^^^^^^^^^^^^^^^^^^^^^^^^^^^^^^^^^
  File "/usr/local/Cellar/python@3.11/3.11.4_1/Frameworks/Python.framework/Versions/3.11/lib/python3.11/unittest/mock.py", line 1183, in _execute_mock_call
    raise effect
Exception: Agent error
2025-06-06 17:00:06,845 - DEBUG - Sending metric: {"event": "USAGE", "configuration": {"workspace_url": "https://dbc-df998298-4c7e.cloud.databricks.co...
2025-06-06 17:00:06,860 - DEBUG - Starting new HTTPS connection (1): chuck.amperity.com:443
2025-06-06 17:00:06,994 - DEBUG - https://chuck.amperity.com:443 "POST /api/usage HTTP/1.1" 204 0
2025-06-06 17:00:06,994 - DEBUG - Failed to send metrics: 204 - 
2025-06-06 17:00:06,999 - DEBUG - Sending metric: {"event": "USAGE", "configuration": {"workspace_url": "https://dbc-df998298-4c7e.cloud.databricks.co...
2025-06-06 17:00:07,002 - DEBUG - Starting new HTTPS connection (1): chuck.amperity.com:443
2025-06-06 17:00:07,127 - DEBUG - https://chuck.amperity.com:443 "POST /api/usage HTTP/1.1" 204 0
2025-06-06 17:00:07,128 - DEBUG - Failed to send metrics: 204 - 
2025-06-06 17:00:07,140 - DEBUG - Sending metric: {"event": "USAGE", "configuration": {"workspace_url": "https://dbc-df998298-4c7e.cloud.databricks.co...
2025-06-06 17:00:07,143 - DEBUG - Starting new HTTPS connection (1): chuck.amperity.com:443
2025-06-06 17:00:07,267 - DEBUG - https://chuck.amperity.com:443 "POST /api/usage HTTP/1.1" 204 0
2025-06-06 17:00:07,268 - DEBUG - Failed to send metrics: 204 - 
2025-06-06 17:00:07,271 - DEBUG - Sending metric: {"event": "USAGE", "configuration": {"workspace_url": "https://dbc-df998298-4c7e.cloud.databricks.co...
2025-06-06 17:00:07,273 - DEBUG - Starting new HTTPS connection (1): chuck.amperity.com:443
2025-06-06 17:00:07,396 - DEBUG - https://chuck.amperity.com:443 "POST /api/usage HTTP/1.1" 204 0
2025-06-06 17:00:07,397 - DEBUG - Failed to send metrics: 204 - 
2025-06-06 17:00:07,402 - DEBUG - Sending metric: {"event": "USAGE", "configuration": {"workspace_url": "https://dbc-df998298-4c7e.cloud.databricks.co...
2025-06-06 17:00:07,405 - DEBUG - Starting new HTTPS connection (1): chuck.amperity.com:443
2025-06-06 17:00:07,533 - DEBUG - https://chuck.amperity.com:443 "POST /api/usage HTTP/1.1" 204 0
2025-06-06 17:00:07,533 - DEBUG - Failed to send metrics: 204 - 
2025-06-06 17:00:07,542 - INFO - Databricks token set successfully
2025-06-06 17:00:07,544 - INFO - Databricks token cleared
2025-06-06 17:00:07,544 - INFO - Amperity token cleared
2025-06-06 17:00:07,546 - INFO - Amperity token cleared
2025-06-06 17:00:07,548 - INFO - Databricks token cleared
2025-06-06 17:00:07,549 - INFO - Amperity token cleared
2025-06-06 17:00:07,565 - DEBUG - Bug report submitted successfully
2025-06-06 17:00:07,614 - ERROR - Error submitting bug report: Network error
Traceback (most recent call last):
  File "/Users/johnrush/repos/chuck-data/chuck_data/commands/bug.py", line 72, in handle_command
    success, message = amperity_client.submit_bug_report(payload, amperity_token)
                       ^^^^^^^^^^^^^^^^^^^^^^^^^^^^^^^^^^^^^^^^^^^^^^^^^^^^^^^^^^
  File "/Users/johnrush/repos/chuck-data/tests/commands/test_bug.py", line 115, in submit_bug_report
    raise Exception("Network error")
Exception: Network error
2025-06-06 17:00:07,617 - DEBUG - Loaded configuration from /var/folders/3f/2n5sjdw50vj9gfnrxjbptj4c0000gn/T/tmpisf5komn.json
2025-06-06 17:00:07,619 - DEBUG - Loaded configuration from /var/folders/3f/2n5sjdw50vj9gfnrxjbptj4c0000gn/T/tmp3w5hm5ay.json
2025-06-06 17:00:07,629 - DEBUG - Bug report submitted successfully
2025-06-06 17:00:07,637 - DEBUG - Saved configuration to /var/folders/3f/2n5sjdw50vj9gfnrxjbptj4c0000gn/T/tmpj45y9_gj/test_config.json
2025-06-06 17:00:07,640 - DEBUG - Saved configuration to /var/folders/3f/2n5sjdw50vj9gfnrxjbptj4c0000gn/T/tmpx_u2zpd4/test_config.json
2025-06-06 17:00:07,642 - DEBUG - Saved configuration to /var/folders/3f/2n5sjdw50vj9gfnrxjbptj4c0000gn/T/tmp166vuwxp/test_config.json
2025-06-06 17:00:07,642 - DEBUG - Loaded configuration from /var/folders/3f/2n5sjdw50vj9gfnrxjbptj4c0000gn/T/tmp166vuwxp/test_config.json
2025-06-06 17:00:07,646 - INFO - Cluster init script uploaded successfully to /Volumes/main/default/chuck/cluster_init-2025-06-02_14-30.sh
2025-06-06 17:00:07,654 - DEBUG - Volume 'chuck' not found in main.default. Attempting to create.
2025-06-06 17:00:07,654 - DEBUG - Volume 'chuck' created successfully.
2025-06-06 17:00:07,654 - INFO - Cluster init script uploaded successfully to /Volumes/main/default/chuck/cluster_init-2025-06-02_14-30.sh
2025-06-06 17:00:07,657 - DEBUG - Volume 'chuck' not found in main.default. Attempting to create.
2025-06-06 17:00:07,657 - DEBUG - Volume 'chuck' created successfully.
2025-06-06 17:00:07,657 - INFO - Cluster init script uploaded successfully to /Volumes/main/default/chuck/cluster_init-2025-06-02_14-30.sh
2025-06-06 17:00:07,660 - DEBUG - Volume 'chuck' not found in main.default. Attempting to create.
2025-06-06 17:00:07,662 - DEBUG - Volume 'chuck' not found in main.default. Attempting to create.
2025-06-06 17:00:07,668 - INFO - Cluster init script uploaded successfully to /Volumes/test_catalog/test_schema/chuck/cluster_init-2025-12-31_23-59.sh
2025-06-06 17:00:07,670 - ERROR - Error generating help: Test error
Traceback (most recent call last):
  File "/Users/johnrush/repos/chuck-data/chuck_data/commands/help.py", line 31, in handle_command
    user_commands = get_user_commands()
                    ^^^^^^^^^^^^^^^^^^^
  File "/usr/local/Cellar/python@3.11/3.11.4_1/Frameworks/Python.framework/Versions/3.11/lib/python3.11/unittest/mock.py", line 1124, in __call__
    return self._mock_call(*args, **kwargs)
           ^^^^^^^^^^^^^^^^^^^^^^^^^^^^^^^^
  File "/usr/local/Cellar/python@3.11/3.11.4_1/Frameworks/Python.framework/Versions/3.11/lib/python3.11/unittest/mock.py", line 1128, in _mock_call
    return self._execute_mock_call(*args, **kwargs)
           ^^^^^^^^^^^^^^^^^^^^^^^^^^^^^^^^^^^^^^^^
  File "/usr/local/Cellar/python@3.11/3.11.4_1/Frameworks/Python.framework/Versions/3.11/lib/python3.11/unittest/mock.py", line 1183, in _execute_mock_call
    raise effect
Exception: Test error
2025-06-06 17:00:07,676 - ERROR - Failed to get job status for run '999999': Not Found
Traceback (most recent call last):
  File "/Users/johnrush/repos/chuck-data/chuck_data/commands/jobs.py", line 67, in handle_job_status
    data = client.get_job_run_status(run_id_str)
           ^^^^^^^^^^^^^^^^^^^^^^^^^^^^^^^^^^^^^
  File "/Users/johnrush/repos/chuck-data/tests/commands/test_jobs.py", line 119, in get_job_run_status
    raise Exception("Not Found")
Exception: Not Found
2025-06-06 17:00:07,682 - ERROR - Failed to submit job: Bad Request
Traceback (most recent call last):
  File "/Users/johnrush/repos/chuck-data/chuck_data/commands/jobs.py", line 32, in handle_launch_job
    run_data = client.submit_job_run(
               ^^^^^^^^^^^^^^^^^^^^^^
  File "/Users/johnrush/repos/chuck-data/tests/commands/test_jobs.py", line 70, in submit_job_run
    raise Exception("Bad Request")
Exception: Bad Request
2025-06-06 17:00:07,688 - ERROR - Failed to launch job, no run_id: {}
2025-06-06 17:00:07,693 - ERROR - Error listing catalogs: API error
2025-06-06 17:00:07,705 - DEBUG - Saved configuration to /var/folders/3f/2n5sjdw50vj9gfnrxjbptj4c0000gn/T/tmp9npl3g4m/test_config.json
2025-06-06 17:00:07,706 - DEBUG - Loaded configuration from /var/folders/3f/2n5sjdw50vj9gfnrxjbptj4c0000gn/T/tmp9npl3g4m/test_config.json
2025-06-06 17:00:07,708 - DEBUG - Saved configuration to /var/folders/3f/2n5sjdw50vj9gfnrxjbptj4c0000gn/T/tmpq6zkbr00/test_config.json
2025-06-06 17:00:07,708 - DEBUG - Loaded configuration from /var/folders/3f/2n5sjdw50vj9gfnrxjbptj4c0000gn/T/tmpq6zkbr00/test_config.json
2025-06-06 17:00:07,712 - DEBUG - Saved configuration to /var/folders/3f/2n5sjdw50vj9gfnrxjbptj4c0000gn/T/tmp8l2eaayh/test_config.json
2025-06-06 17:00:07,712 - DEBUG - Loaded configuration from /var/folders/3f/2n5sjdw50vj9gfnrxjbptj4c0000gn/T/tmp8l2eaayh/test_config.json
2025-06-06 17:00:07,713 - ERROR - Failed to list models: API error
Traceback (most recent call last):
  File "/Users/johnrush/repos/chuck-data/chuck_data/commands/list_models.py", line 31, in handle_command
    models_list = list_models_api(client)
                  ^^^^^^^^^^^^^^^^^^^^^^^
  File "/Users/johnrush/repos/chuck-data/chuck_data/models.py", line 19, in list_models
    return client.list_models()
           ^^^^^^^^^^^^^^^^^^^^
  File "/Users/johnrush/repos/chuck-data/tests/commands/test_list_models.py", line 112, in list_models
    raise Exception("API error")
Exception: API error
2025-06-06 17:00:07,717 - DEBUG - Saved configuration to /var/folders/3f/2n5sjdw50vj9gfnrxjbptj4c0000gn/T/tmpb096i2cm/test_config.json
2025-06-06 17:00:07,717 - DEBUG - Loaded configuration from /var/folders/3f/2n5sjdw50vj9gfnrxjbptj4c0000gn/T/tmpb096i2cm/test_config.json
2025-06-06 17:00:07,717 - DEBUG - Loaded configuration from /var/folders/3f/2n5sjdw50vj9gfnrxjbptj4c0000gn/T/tmpb096i2cm/test_config.json
2025-06-06 17:00:07,721 - DEBUG - Saved configuration to /var/folders/3f/2n5sjdw50vj9gfnrxjbptj4c0000gn/T/tmp7bmopss5/test_config.json
2025-06-06 17:00:07,721 - DEBUG - Loaded configuration from /var/folders/3f/2n5sjdw50vj9gfnrxjbptj4c0000gn/T/tmp7bmopss5/test_config.json
2025-06-06 17:00:07,721 - DEBUG - Loaded configuration from /var/folders/3f/2n5sjdw50vj9gfnrxjbptj4c0000gn/T/tmp7bmopss5/test_config.json
2025-06-06 17:00:07,723 - DEBUG - Saved configuration to /var/folders/3f/2n5sjdw50vj9gfnrxjbptj4c0000gn/T/tmps25z0in6/test_config.json
2025-06-06 17:00:07,723 - DEBUG - Loaded configuration from /var/folders/3f/2n5sjdw50vj9gfnrxjbptj4c0000gn/T/tmps25z0in6/test_config.json
2025-06-06 17:00:07,724 - DEBUG - Loaded configuration from /var/folders/3f/2n5sjdw50vj9gfnrxjbptj4c0000gn/T/tmps25z0in6/test_config.json
2025-06-06 17:00:07,726 - DEBUG - Saved configuration to /var/folders/3f/2n5sjdw50vj9gfnrxjbptj4c0000gn/T/tmp23lhnfjz/test_config.json
2025-06-06 17:00:07,726 - DEBUG - Loaded configuration from /var/folders/3f/2n5sjdw50vj9gfnrxjbptj4c0000gn/T/tmp23lhnfjz/test_config.json
2025-06-06 17:00:07,726 - DEBUG - Loaded configuration from /var/folders/3f/2n5sjdw50vj9gfnrxjbptj4c0000gn/T/tmp23lhnfjz/test_config.json
2025-06-06 17:00:07,726 - DEBUG - Saved configuration to /var/folders/3f/2n5sjdw50vj9gfnrxjbptj4c0000gn/T/tmp23lhnfjz/test_config.json
2025-06-06 17:00:07,727 - DEBUG - Loaded configuration from /var/folders/3f/2n5sjdw50vj9gfnrxjbptj4c0000gn/T/tmp23lhnfjz/test_config.json
2025-06-06 17:00:07,729 - DEBUG - Saved configuration to /var/folders/3f/2n5sjdw50vj9gfnrxjbptj4c0000gn/T/tmp8z1bicas/test_config.json
2025-06-06 17:00:07,729 - DEBUG - Loaded configuration from /var/folders/3f/2n5sjdw50vj9gfnrxjbptj4c0000gn/T/tmp8z1bicas/test_config.json
2025-06-06 17:00:07,729 - DEBUG - Loaded configuration from /var/folders/3f/2n5sjdw50vj9gfnrxjbptj4c0000gn/T/tmp8z1bicas/test_config.json
2025-06-06 17:00:07,729 - DEBUG - Saved configuration to /var/folders/3f/2n5sjdw50vj9gfnrxjbptj4c0000gn/T/tmp8z1bicas/test_config.json
2025-06-06 17:00:07,730 - DEBUG - Loaded configuration from /var/folders/3f/2n5sjdw50vj9gfnrxjbptj4c0000gn/T/tmp8z1bicas/test_config.json
2025-06-06 17:00:07,734 - DEBUG - Saved configuration to /var/folders/3f/2n5sjdw50vj9gfnrxjbptj4c0000gn/T/tmp6fyu410e/test_config.json
2025-06-06 17:00:07,735 - DEBUG - Loaded configuration from /var/folders/3f/2n5sjdw50vj9gfnrxjbptj4c0000gn/T/tmp6fyu410e/test_config.json
2025-06-06 17:00:07,737 - DEBUG - Saved configuration to /var/folders/3f/2n5sjdw50vj9gfnrxjbptj4c0000gn/T/tmp0thlgb0t/test_config.json
2025-06-06 17:00:07,737 - DEBUG - Loaded configuration from /var/folders/3f/2n5sjdw50vj9gfnrxjbptj4c0000gn/T/tmp0thlgb0t/test_config.json
2025-06-06 17:00:07,737 - DEBUG - Loaded configuration from /var/folders/3f/2n5sjdw50vj9gfnrxjbptj4c0000gn/T/tmp0thlgb0t/test_config.json
2025-06-06 17:00:07,738 - DEBUG - Saved configuration to /var/folders/3f/2n5sjdw50vj9gfnrxjbptj4c0000gn/T/tmp0thlgb0t/test_config.json
2025-06-06 17:00:07,741 - ERROR - Error listing tables: API error
2025-06-06 17:00:07,747 - DEBUG - Saved configuration to /var/folders/3f/2n5sjdw50vj9gfnrxjbptj4c0000gn/T/tmpgf4epnz2/test_config.json
2025-06-06 17:00:07,747 - DEBUG - Loaded configuration from /var/folders/3f/2n5sjdw50vj9gfnrxjbptj4c0000gn/T/tmpgf4epnz2/test_config.json
2025-06-06 17:00:07,748 - DEBUG - Loaded configuration from /var/folders/3f/2n5sjdw50vj9gfnrxjbptj4c0000gn/T/tmpgf4epnz2/test_config.json
2025-06-06 17:00:07,751 - DEBUG - Saved configuration to /var/folders/3f/2n5sjdw50vj9gfnrxjbptj4c0000gn/T/tmphu7nsxy8/test_config.json
2025-06-06 17:00:07,751 - DEBUG - Loaded configuration from /var/folders/3f/2n5sjdw50vj9gfnrxjbptj4c0000gn/T/tmphu7nsxy8/test_config.json
2025-06-06 17:00:07,752 - DEBUG - Saved configuration to /var/folders/3f/2n5sjdw50vj9gfnrxjbptj4c0000gn/T/tmphu7nsxy8/test_config.json
2025-06-06 17:00:07,752 - DEBUG - Loaded configuration from /var/folders/3f/2n5sjdw50vj9gfnrxjbptj4c0000gn/T/tmphu7nsxy8/test_config.json
2025-06-06 17:00:07,752 - DEBUG - Loaded configuration from /var/folders/3f/2n5sjdw50vj9gfnrxjbptj4c0000gn/T/tmphu7nsxy8/test_config.json
2025-06-06 17:00:07,758 - ERROR - Error fetching warehouses: API connection error
2025-06-06 17:00:07,769 - ERROR - Failed to set model 'claude-v1': API error
Traceback (most recent call last):
  File "/Users/johnrush/repos/chuck-data/chuck_data/commands/model_selection.py", line 28, in handle_command
    models_list = list_models_api(client)
                  ^^^^^^^^^^^^^^^^^^^^^^^
  File "/Users/johnrush/repos/chuck-data/chuck_data/models.py", line 19, in list_models
    return client.list_models()
           ^^^^^^^^^^^^^^^^^^^^
  File "/Users/johnrush/repos/chuck-data/tests/commands/test_model_selection.py", line 79, in list_models
    raise Exception("API error")
Exception: API error
2025-06-06 17:00:07,771 - DEBUG - Saved configuration to /var/folders/3f/2n5sjdw50vj9gfnrxjbptj4c0000gn/T/tmpfh19goqz/test_config.json
2025-06-06 17:00:07,772 - DEBUG - Loaded configuration from /var/folders/3f/2n5sjdw50vj9gfnrxjbptj4c0000gn/T/tmpfh19goqz/test_config.json
2025-06-06 17:00:07,774 - DEBUG - Saved configuration to /var/folders/3f/2n5sjdw50vj9gfnrxjbptj4c0000gn/T/tmp5g6ntd2q/test_config.json
2025-06-06 17:00:07,774 - DEBUG - Loaded configuration from /var/folders/3f/2n5sjdw50vj9gfnrxjbptj4c0000gn/T/tmp5g6ntd2q/test_config.json
2025-06-06 17:00:07,776 - DEBUG - Saved configuration to /var/folders/3f/2n5sjdw50vj9gfnrxjbptj4c0000gn/T/tmpqjoeqw_h/test_config.json
2025-06-06 17:00:07,776 - DEBUG - Loaded configuration from /var/folders/3f/2n5sjdw50vj9gfnrxjbptj4c0000gn/T/tmpqjoeqw_h/test_config.json
2025-06-06 17:00:07,781 - DEBUG - Saved configuration to /var/folders/3f/2n5sjdw50vj9gfnrxjbptj4c0000gn/T/tmpi30c24hh/test_config.json
2025-06-06 17:00:07,781 - DEBUG - Loaded configuration from /var/folders/3f/2n5sjdw50vj9gfnrxjbptj4c0000gn/T/tmpi30c24hh/test_config.json
2025-06-06 17:00:07,789 - INFO - Starting PII Scan for 2 tables in test_cat.test_schema.
2025-06-06 17:00:07,799 - ERROR - Bulk PII scan error: LLM client error
Traceback (most recent call last):
  File "/Users/johnrush/repos/chuck-data/chuck_data/commands/scan_pii.py", line 46, in handle_command
    llm_client = LLMClient()
                 ^^^^^^^^^^^
  File "/usr/local/Cellar/python@3.11/3.11.4_1/Frameworks/Python.framework/Versions/3.11/lib/python3.11/unittest/mock.py", line 1124, in __call__
    return self._mock_call(*args, **kwargs)
           ^^^^^^^^^^^^^^^^^^^^^^^^^^^^^^^^
  File "/usr/local/Cellar/python@3.11/3.11.4_1/Frameworks/Python.framework/Versions/3.11/lib/python3.11/unittest/mock.py", line 1128, in _mock_call
    return self._execute_mock_call(*args, **kwargs)
           ^^^^^^^^^^^^^^^^^^^^^^^^^^^^^^^^^^^^^^^^
  File "/usr/local/Cellar/python@3.11/3.11.4_1/Frameworks/Python.framework/Versions/3.11/lib/python3.11/unittest/mock.py", line 1183, in _execute_mock_call
    raise effect
Exception: LLM client error
2025-06-06 17:00:07,808 - DEBUG - Saved configuration to /var/folders/3f/2n5sjdw50vj9gfnrxjbptj4c0000gn/T/tmpsxje4fek/test_config.json
2025-06-06 17:00:07,808 - DEBUG - Loaded configuration from /var/folders/3f/2n5sjdw50vj9gfnrxjbptj4c0000gn/T/tmpsxje4fek/test_config.json
2025-06-06 17:00:07,808 - ERROR - Failed to set schema: Failed to list schemas
Traceback (most recent call last):
  File "/Users/johnrush/repos/chuck-data/chuck_data/commands/schema_selection.py", line 110, in handle_command
    result = get_schemas_list(client=client, catalog_name=catalog_name)
             ^^^^^^^^^^^^^^^^^^^^^^^^^^^^^^^^^^^^^^^^^^^^^^^^^^^^^^^^^^
  File "/Users/johnrush/repos/chuck-data/chuck_data/catalogs.py", line 56, in list_schemas
    return client.list_schemas(catalog_name, include_browse, max_results, page_token)
           ^^^^^^^^^^^^^^^^^^^^^^^^^^^^^^^^^^^^^^^^^^^^^^^^^^^^^^^^^^^^^^^^^^^^^^^^^^
  File "/Users/johnrush/repos/chuck-data/tests/commands/test_schema_selection.py", line 102, in list_schemas
    raise Exception("Failed to list schemas")
Exception: Failed to list schemas
2025-06-06 17:00:07,811 - DEBUG - Saved configuration to /var/folders/3f/2n5sjdw50vj9gfnrxjbptj4c0000gn/T/tmps81a6p36/test_config.json
2025-06-06 17:00:07,812 - DEBUG - Loaded configuration from /var/folders/3f/2n5sjdw50vj9gfnrxjbptj4c0000gn/T/tmps81a6p36/test_config.json
2025-06-06 17:00:07,814 - DEBUG - Saved configuration to /var/folders/3f/2n5sjdw50vj9gfnrxjbptj4c0000gn/T/tmpnya8_l5j/test_config.json
2025-06-06 17:00:07,814 - DEBUG - Loaded configuration from /var/folders/3f/2n5sjdw50vj9gfnrxjbptj4c0000gn/T/tmpnya8_l5j/test_config.json
2025-06-06 17:00:07,814 - DEBUG - Loaded configuration from /var/folders/3f/2n5sjdw50vj9gfnrxjbptj4c0000gn/T/tmpnya8_l5j/test_config.json
2025-06-06 17:00:07,815 - DEBUG - Saved configuration to /var/folders/3f/2n5sjdw50vj9gfnrxjbptj4c0000gn/T/tmpnya8_l5j/test_config.json
2025-06-06 17:00:07,815 - DEBUG - Loaded configuration from /var/folders/3f/2n5sjdw50vj9gfnrxjbptj4c0000gn/T/tmpnya8_l5j/test_config.json
2025-06-06 17:00:07,821 - DEBUG - Sending metric: {"event": "USAGE", "configuration": {"workspace_url": "https://dbc-df998298-4c7e.cloud.databricks.co...
2025-06-06 17:00:07,824 - DEBUG - Starting new HTTPS connection (1): chuck.amperity.com:443
2025-06-06 17:00:07,943 - DEBUG - https://chuck.amperity.com:443 "POST /api/usage HTTP/1.1" 204 0
2025-06-06 17:00:07,944 - DEBUG - Failed to send metrics: 204 - 
2025-06-06 17:00:07,947 - ERROR - Stitch setup error: LLM client error
Traceback (most recent call last):
  File "/Users/johnrush/repos/chuck-data/chuck_data/commands/setup_stitch.py", line 111, in handle_command
    return _phase_1_prepare_config(
           ^^^^^^^^^^^^^^^^^^^^^^^^
  File "/Users/johnrush/repos/chuck-data/chuck_data/commands/setup_stitch.py", line 273, in _phase_1_prepare_config
    llm_client = LLMClient()
                 ^^^^^^^^^^^
  File "/usr/local/Cellar/python@3.11/3.11.4_1/Frameworks/Python.framework/Versions/3.11/lib/python3.11/unittest/mock.py", line 1124, in __call__
    return self._mock_call(*args, **kwargs)
           ^^^^^^^^^^^^^^^^^^^^^^^^^^^^^^^^
  File "/usr/local/Cellar/python@3.11/3.11.4_1/Frameworks/Python.framework/Versions/3.11/lib/python3.11/unittest/mock.py", line 1128, in _mock_call
    return self._execute_mock_call(*args, **kwargs)
           ^^^^^^^^^^^^^^^^^^^^^^^^^^^^^^^^^^^^^^^^
  File "/usr/local/Cellar/python@3.11/3.11.4_1/Frameworks/Python.framework/Versions/3.11/lib/python3.11/unittest/mock.py", line 1183, in _execute_mock_call
    raise effect
Exception: LLM client error
2025-06-06 17:00:07,962 - DEBUG - GET request to: https://.cloud.databricks.com/api/2.0/preview/scim/v2/Me
2025-06-06 17:00:07,962 - DEBUG - Connection error: URL has an invalid label.
2025-06-06 17:00:07,962 - DEBUG - Token validation failed: Connection error occurred: URL has an invalid label.
2025-06-06 17:00:07,966 - ERROR - Error validating token: Connection failed
2025-06-06 17:00:07,973 - DEBUG - GET request to: https://invalid-workspace.nonexistent.com.cloud.databricks.com/api/2.0/preview/scim/v2/Me
2025-06-06 17:00:07,976 - DEBUG - Starting new HTTPS connection (1): invalid-workspace.nonexistent.com.cloud.databricks.com:443
2025-06-06 17:00:07,978 - DEBUG - Connection error: HTTPSConnectionPool(host='invalid-workspace.nonexistent.com.cloud.databricks.com', port=443): Max retries exceeded with url: /api/2.0/preview/scim/v2/Me (Caused by NameResolutionError("<urllib3.connection.HTTPSConnection object at 0x112b9a650>: Failed to resolve 'invalid-workspace.nonexistent.com.cloud.databricks.com' ([Errno 8] nodename nor servname provided, or not known)"))
2025-06-06 17:00:07,978 - DEBUG - Token validation failed: Connection error occurred: HTTPSConnectionPool(host='invalid-workspace.nonexistent.com.cloud.databricks.com', port=443): Max retries exceeded with url: /api/2.0/preview/scim/v2/Me (Caused by NameResolutionError("<urllib3.connection.HTTPSConnection object at 0x112b9a650>: Failed to resolve 'invalid-workspace.nonexistent.com.cloud.databricks.com' ([Errno 8] nodename nor servname provided, or not known)"))
2025-06-06 17:00:08,084 - DEBUG - GET request to: https://invalid.nonexistent.com.cloud.databricks.com/api/2.0/preview/scim/v2/Me
2025-06-06 17:00:08,087 - DEBUG - Starting new HTTPS connection (1): invalid.nonexistent.com.cloud.databricks.com:443
2025-06-06 17:00:08,088 - DEBUG - Connection error: HTTPSConnectionPool(host='invalid.nonexistent.com.cloud.databricks.com', port=443): Max retries exceeded with url: /api/2.0/preview/scim/v2/Me (Caused by NameResolutionError("<urllib3.connection.HTTPSConnection object at 0x112a15150>: Failed to resolve 'invalid.nonexistent.com.cloud.databricks.com' ([Errno 8] nodename nor servname provided, or not known)"))
2025-06-06 17:00:08,088 - DEBUG - Token validation failed: Connection error occurred: HTTPSConnectionPool(host='invalid.nonexistent.com.cloud.databricks.com', port=443): Max retries exceeded with url: /api/2.0/preview/scim/v2/Me (Caused by NameResolutionError("<urllib3.connection.HTTPSConnection object at 0x112a15150>: Failed to resolve 'invalid.nonexistent.com.cloud.databricks.com' ([Errno 8] nodename nor servname provided, or not known)"))
2025-06-06 17:00:08,090 - ERROR - Error validating token: Validation failed
2025-06-06 17:00:08,206 - ERROR - Error validating token: Connection failed
2025-06-06 17:00:08,239 - ERROR - Error validating token: Network error with secret details
2025-06-06 17:00:08,275 - ERROR - Error validating token: Connection error: Failed to resolve 'workspace123.cloud.databricks.com'
2025-06-06 17:00:08,290 - ERROR - Error fetching Amperity init script: API Error
Traceback (most recent call last):
  File "/Users/johnrush/repos/chuck-data/chuck_data/commands/stitch_tools.py", line 179, in _helper_prepare_stitch_config
    init_script_data = client.fetch_amperity_job_init(amperity_token)
                       ^^^^^^^^^^^^^^^^^^^^^^^^^^^^^^^^^^^^^^^^^^^^^^
  File "/usr/local/Cellar/python@3.11/3.11.4_1/Frameworks/Python.framework/Versions/3.11/lib/python3.11/unittest/mock.py", line 1124, in __call__
    return self._mock_call(*args, **kwargs)
           ^^^^^^^^^^^^^^^^^^^^^^^^^^^^^^^^
  File "/usr/local/Cellar/python@3.11/3.11.4_1/Frameworks/Python.framework/Versions/3.11/lib/python3.11/unittest/mock.py", line 1128, in _mock_call
    return self._execute_mock_call(*args, **kwargs)
           ^^^^^^^^^^^^^^^^^^^^^^^^^^^^^^^^^^^^^^^^
  File "/usr/local/Cellar/python@3.11/3.11.4_1/Frameworks/Python.framework/Versions/3.11/lib/python3.11/unittest/mock.py", line 1183, in _execute_mock_call
    raise effect
Exception: API Error
2025-06-06 17:00:08,302 - DEBUG - Versioned cluster init script uploaded to /Volumes/test_catalog/test_schema/chuck/cluster_init-2025-06-02_14-30.sh
2025-06-06 17:00:08,305 - DEBUG - Versioned cluster init script uploaded to /Volumes/test_catalog/test_schema/chuck/cluster_init-2025-06-02_14-30.sh
2025-06-06 17:00:08,309 - DEBUG - Volume 'chuck' not found in test_catalog.test_schema. Attempting to create.
2025-06-06 17:00:08,322 - DEBUG - Saved configuration to /var/folders/3f/2n5sjdw50vj9gfnrxjbptj4c0000gn/T/tmp2ei27snl/test_config.json
2025-06-06 17:00:08,322 - DEBUG - Loaded configuration from /var/folders/3f/2n5sjdw50vj9gfnrxjbptj4c0000gn/T/tmp2ei27snl/test_config.json
2025-06-06 17:00:08,322 - DEBUG - Loaded configuration from /var/folders/3f/2n5sjdw50vj9gfnrxjbptj4c0000gn/T/tmp2ei27snl/test_config.json
2025-06-06 17:00:08,322 - DEBUG - Loaded configuration from /var/folders/3f/2n5sjdw50vj9gfnrxjbptj4c0000gn/T/tmp2ei27snl/test_config.json
2025-06-06 17:00:08,324 - DEBUG - Saved configuration to /var/folders/3f/2n5sjdw50vj9gfnrxjbptj4c0000gn/T/tmpryaboy0x/test_config.json
2025-06-06 17:00:08,325 - DEBUG - Loaded configuration from /var/folders/3f/2n5sjdw50vj9gfnrxjbptj4c0000gn/T/tmpryaboy0x/test_config.json
2025-06-06 17:00:08,325 - DEBUG - Saved configuration to /var/folders/3f/2n5sjdw50vj9gfnrxjbptj4c0000gn/T/tmpryaboy0x/test_config.json
2025-06-06 17:00:08,325 - DEBUG - Loaded configuration from /var/folders/3f/2n5sjdw50vj9gfnrxjbptj4c0000gn/T/tmpryaboy0x/test_config.json
2025-06-06 17:00:08,325 - DEBUG - Saved configuration to /var/folders/3f/2n5sjdw50vj9gfnrxjbptj4c0000gn/T/tmpryaboy0x/test_config.json
2025-06-06 17:00:08,326 - DEBUG - Loaded configuration from /var/folders/3f/2n5sjdw50vj9gfnrxjbptj4c0000gn/T/tmpryaboy0x/test_config.json
2025-06-06 17:00:08,326 - DEBUG - Loaded configuration from /var/folders/3f/2n5sjdw50vj9gfnrxjbptj4c0000gn/T/tmpryaboy0x/test_config.json
2025-06-06 17:00:08,326 - DEBUG - Loaded configuration from /var/folders/3f/2n5sjdw50vj9gfnrxjbptj4c0000gn/T/tmpryaboy0x/test_config.json
2025-06-06 17:00:08,328 - INFO - Applying tag 'email' to column 'email_col'
2025-06-06 17:00:08,328 - INFO - Applying tag 'given-name' to column 'name_col'
2025-06-06 17:00:08,329 - INFO - Applying tag 'phone' to column 'good_col'
2025-06-06 17:00:08,331 - INFO - Applying tag 'email' to column 'email_col'
2025-06-06 17:00:08,333 - INFO - Applying tag 'email' to column 'email_col'
2025-06-06 17:00:08,333 - ERROR - Error applying tag to email_col: Connection error
2025-06-06 17:00:08,337 - DEBUG - Saved configuration to /var/folders/3f/2n5sjdw50vj9gfnrxjbptj4c0000gn/T/tmph20jgs5a/test_config.json
2025-06-06 17:00:08,337 - DEBUG - Loaded configuration from /var/folders/3f/2n5sjdw50vj9gfnrxjbptj4c0000gn/T/tmph20jgs5a/test_config.json
2025-06-06 17:00:08,339 - DEBUG - Saved configuration to /var/folders/3f/2n5sjdw50vj9gfnrxjbptj4c0000gn/T/tmpb9890eo3/test_config.json
2025-06-06 17:00:08,341 - ERROR - Failed to set warehouse: Failed to list warehouses
Traceback (most recent call last):
  File "/Users/johnrush/repos/chuck-data/chuck_data/commands/warehouse_selection.py", line 106, in handle_command
    warehouses = client.list_warehouses()
                 ^^^^^^^^^^^^^^^^^^^^^^^^
  File "/Users/johnrush/repos/chuck-data/tests/commands/test_warehouse_selection.py", line 110, in list_warehouses
    raise Exception("Failed to list warehouses")
Exception: Failed to list warehouses
2025-06-06 17:00:08,344 - DEBUG - Saved configuration to /var/folders/3f/2n5sjdw50vj9gfnrxjbptj4c0000gn/T/tmpf0wd3713/test_config.json
2025-06-06 17:00:08,353 - ERROR - Failed to set workspace URL: Validation error
Traceback (most recent call last):
  File "/Users/johnrush/repos/chuck-data/chuck_data/commands/workspace_selection.py", line 37, in handle_command
    is_valid, error_message = validate_workspace_url(workspace_url)
                              ^^^^^^^^^^^^^^^^^^^^^^^^^^^^^^^^^^^^^
  File "/usr/local/Cellar/python@3.11/3.11.4_1/Frameworks/Python.framework/Versions/3.11/lib/python3.11/unittest/mock.py", line 1124, in __call__
    return self._mock_call(*args, **kwargs)
           ^^^^^^^^^^^^^^^^^^^^^^^^^^^^^^^^
  File "/usr/local/Cellar/python@3.11/3.11.4_1/Frameworks/Python.framework/Versions/3.11/lib/python3.11/unittest/mock.py", line 1128, in _mock_call
    return self._execute_mock_call(*args, **kwargs)
           ^^^^^^^^^^^^^^^^^^^^^^^^^^^^^^^^^^^^^^^^
  File "/usr/local/Cellar/python@3.11/3.11.4_1/Frameworks/Python.framework/Versions/3.11/lib/python3.11/unittest/mock.py", line 1183, in _execute_mock_call
    raise effect
Exception: Validation error
